Workbook

Sheet ReadMe-Forest construction
B2: Random Forest Implementation: Pima Indians Diabetes Classification
B3: Executive Summary
B4: This document explains a machine learning implementation that predicts diabetes risk using medical data from the Pima Indians population. The system uses a Random Forest algorithm with 12 decision trees, each limited to depth 3 for interpretability. The model achieves 75.8% accuracy on test data and is implemented in Excel for transparency and educational purposes.
B6: 1. Fundamental Machine Learning Concepts
B7: 1.1 What is Classification?
B8: Classification is a type of machine learning where we predict categorical outcomes. In this case:
B9: Class 0: No diabetes (tested_negative)
B10: Class 1: Diabetes (tested_positive)
B11: Think of it as a medical screening tool that learns patterns from historical data to assess new patients' diabetes risk.
B12: 1.2 Decision Trees: The Building Blocks
B13: A decision tree makes predictions by asking a series of yes/no questions about the input features. It's like a medical flowchart:
B14: Example Structure:
... B35: 2.1 Medical Context & Feature Definitions
B36: Feature | C36: Medical Meaning | D36: Normal Range | E36: Importance
B37: preg | C37: Number of pregnancies | D37: 0-5 | E37: Hormonal changes affect glucose
B38: plas | C38: Plasma glucose concentration | D38: 70-100 mg/dL | E38: Primary diabetes indicator
B39: pres | C39: Diastolic blood pressure (mm Hg) | D39: <80 mm Hg | E39: Cardiovascular health link
B40: skin | C40: Triceps skin fold thickness (mm) | D40: 10-40 mm | E40: Obesity indicator
B41: insu | C41: 2-Hour serum insulin (mu U/ml) | D41: 16-166 μU/mL | E41: Insulin resistance measure
B42: mass | C42: Body mass index (weight in kg/(height in m)²) | D42: 18.5-24.9 | E42: Obesity metric
B43: pedi | C43: Diabetes pedigree function | D43: 0-2.4 | E43: Genetic predisposition score
B44: age | C44: Age in years | D44: - | E44: Risk increases with age
B45: 2.2 Data Statistics
B46: 768 patients in original dataset
B47: 537 patients used for training (70%)
B48: 231 patients used for testing (30%)
B49: Class distribution: Approximately 65% non-diabetic, 35% diabetic
B51: 3. Technical Implementation Details
B52: 3.1 Bootstrap Sampling (Data Randomization)
B53: Each tree sees a different random sample of patients:
B54: Sample size: 537 patients (same as original training set)
B55: Sampling method: With replacement (some patients appear multiple times)
B56: Unique patients per tree: ~330-343 (about 61-64% of training data)
B57: Why bootstrap? Creates diversity among trees and enables "out-of-bag" error estimation.
... B91: 4.2 Excel Formula Breakdown
B93: =IF(D2>133.5,) -> FALSE
B94: IF(D2<=161.5,
B95: IF(I2<=0.31,0,0),
B96: IF(I2>0.31,1,1)
B97: ),
...

Sheet Random Forest Analysis
A2: Random Forest Analysis, Interpretation, and Discussion
A4: 1. Overview of the Learned Structure
A6: This Random Forest consists of 12 trees, each built on different bootstrap samples and random feature subsets. Although each individual tree has a slightly different structure, collectively they reveal strong and consistent patterns.
A8: Across the forest, plasma glucose (plas) appears as the dominant variable, used in 8 of the 12 trees, and almost always near the top of the tree. This is consistent with both clinical intuition and the impurity reduction pattern: splits on glucose tend to produce the largest immediate drops in Gini impurity.
A10: In contrast, variables such as pregnancies, mass (BMI), and insulin typically appear in deeper nodes, contributing smaller but still meaningful purity improvements in specific subpopulations.
A12: The forest therefore learns a hierarchical risk structure:
A14: Primary signals: glucose, pedigree
A15: Secondary refiners: BMI, age, skinfold
A16: Contextual variables: pres, insu, preg
A18: This mirrors established medical knowledge and therefore passes the test of conceptual soundness.
A20: 2. Feature Usage Insights
A22: Instead of looking only at numerical importances, this sheet also evaluates how many trees used each feature and how many total nodes used it.
... A102: This three-stage flow (macro → meso → micro splitting) is exactly what we expect from a well-structured Random Forest.

Sheet TestRowIDs
A1: RowID
A2: 731
A3: 199
A4: 25
A5: 418
A6: 388
A7: 157
A8: 661
A9: 206
A10: 4
A11: 532
A12: 159
A13: 348
... A232: 20

Sheet RandomForest Final
B1: RowID | C1: preg | D1: plas | E1: pres | F1: skin | G1: insu | H1: mass | I1: pedi | J1: age | K1: class | L1: Tree 1 | M1: Tree 2 | N1: Tree 3 | O1: Tree 4 | P1: Tree 5 | Q1: Tree 6 | R1: Tree 7 | S1: Tree 8 | T1: Tree 9 | U1: Tree 10 | V1: Tree 11 | W1: Tree 12 | X1: Count_0 | Y1: Count_1 | Z1: 0_or_1 | AA1: if_correct | AC1: Test RowID | AE1: Count_0 | AF1: Count_1
B2: 1 | C2: 6 | D2: 148 | E2: 72 | F2: 35 | G2: 0 | H2: 33.6 | I2: 0.627 | J2: 50 | K2: 1 | L2: =IF(J2<=42.5,IF(G2<=119.5,IF(C2<=2.5,0,0),IF(C2<=0.5,1,0)),IF(G2<=139.5,IF(J2<=55.5,1,0),1)) -> 1 | M2: =IF(J2<=30.5,IF(H2<=36.25,IF(J2<=26.5,0,0),IF(H2<=42.75,0,1)),IF(H2<=27.45,IF(H2<=24.8,0,0),IF(J2<=42.5,1,1))) -> 1 | N2: =IF(D2<=137.5,IF(J2<=27.5,IF(I2<=0.4945,0,0),IF(D2<=107.5,0,0)),IF(D2<=155.5,IF(D2<=146.5,1,0),IF(J2<=44.5,1,1))) -> 0 | O2: =IF(D2<=133.5,IF(I2<=0.5095,IF(D2<=94.5,0,0),IF(F2<=28.5,0,1)),IF(D2<=161.5,IF(I2<=0.315,0,1),IF(C2<=6.5,1,1))) -> 1 | P2: =IF(D2<=124.5,IF(J2<=27.5,IF(F2<=30.5,0,0),IF(D2<=94.5,0,0)),IF(D2<=166.5,IF(J2<=24.5,0,1),IF(J2<=37.5,1,1))) -> 1 | Q2: =IF(H2<=28.849999,IF(C2<=5.5,IF(E2<=69,0,0),IF(H2<=24.7,0,0)),IF(C2<=4.5,IF(G2<=107.5,0,0),IF(G2<=122.5,0,1))) -> 0 | R2: =IF(D2<=154.5,IF(H2<=27.849999,IF(D2<=107.5,0,0),IF(I2<=1.105,0,1)),IF(I2<=0.2745,1,IF(G2<=171.5,1,1))) -> 0 | S2: =IF(D2<=133.5,IF(J2<=27.5,IF(H2<=31.3,0,0),IF(H2<=28.65,0,0)),IF(H2<=29.4,0,IF(D2<=155.5,1,1))) -> 1 | T2: =IF(D2<=151.5,IF(D2<=99.5,IF(J2<=36.5,0,0),IF(I2<=0.317,0,0)),IF(F2<=38.5,IF(J2<=44.5,1,1),1)) -> 0 | U2: =IF(H2<=29.650001,IF(C2<=8.5,IF(H2<=26.5,0,0),0),IF(C2<=6.5,IF(H2<=43,0,1),IF(I2<=0.208,0,1))) -> 0 | V2: =IF(H2<=29.849999,IF(C2<=4.5,IF(H2<=25.45,0,0),IF(I2<=0.261,0,0)),IF(G2<=179,IF(C2<=4.5,0,1),IF(H2<=35.049999,1,1))) -> 1 | W2: =IF(D2<=127.5,IF(C2<=5.5,IF(E2<=79,0,0),IF(I2<=0.2205,0,0)),IF(I2<=0.3165,IF(I2<=0.242,1,0),IF(D2<=143.5,1,1))) -> 1 | X2: =COUNTIF(L2:W2,0) -> 5 | Y2: =COUNTIF(L2:W2,1) -> 7 | Z2: =IF(X2>Y2,0,1) -> 1 | AA2: =IF(Z2=K2,1,0) -> 1 | AB2: =SUM(AA2:AA769)/COUNT(AA2:AA769) -> 0.78385417 | AC2: 731 | AD2: =VLOOKUP(AC2,B:AA,26,FALSE) -> 0 | AE2: =VLOOKUP(AC2,B:AA,23,FALSE) -> 9 | AF2: =VLOOKUP(AC2,B:AA,24,FALSE) -> 3 | AG2: =AE2&"_"&AF2 -> 9_3 | AJ2: =SUM(AD:AD) -> 175
B3: 2 | C3: 1 | D3: 85 | E3: 66 | F3: 29 | G3: 0 | H3: 26.6 | I3: 0.351 | J3: 31 | K3: 0 | L3: =IF(J3<=42.5,IF(G3<=119.5,IF(C3<=2.5,0,0),IF(C3<=0.5,1,0)),IF(G3<=139.5,IF(J3<=55.5,1,0),1)) -> 0 | M3: =IF(J3<=30.5,IF(H3<=36.25,IF(J3<=26.5,0,0),IF(H3<=42.75,0,1)),IF(H3<=27.45,IF(H3<=24.8,0,0),IF(J3<=42.5,1,1))) -> 0 | N3: =IF(D3<=137.5,IF(J3<=27.5,IF(I3<=0.4945,0,0),IF(D3<=107.5,0,0)),IF(D3<=155.5,IF(D3<=146.5,1,0),IF(J3<=44.5,1,1))) -> 0 | O3: =IF(D3<=133.5,IF(I3<=0.5095,IF(D3<=94.5,0,0),IF(F3<=28.5,0,1)),IF(D3<=161.5,IF(I3<=0.315,0,1),IF(C3<=6.5,1,1))) -> 0 | P3: =IF(D3<=124.5,IF(J3<=27.5,IF(F3<=30.5,0,0),IF(D3<=94.5,0,0)),IF(D3<=166.5,IF(J3<=24.5,0,1),IF(J3<=37.5,1,1))) -> 0 | Q3: =IF(H3<=28.849999,IF(C3<=5.5,IF(E3<=69,0,0),IF(H3<=24.7,0,0)),IF(C3<=4.5,IF(G3<=107.5,0,0),IF(G3<=122.5,0,1))) -> 0 | R3: =IF(D3<=154.5,IF(H3<=27.849999,IF(D3<=107.5,0,0),IF(I3<=1.105,0,1)),IF(I3<=0.2745,1,IF(G3<=171.5,1,1))) -> 0 | S3: =IF(D3<=133.5,IF(J3<=27.5,IF(H3<=31.3,0,0),IF(H3<=28.65,0,0)),IF(H3<=29.4,0,IF(D3<=155.5,1,1))) -> 0 | T3: =IF(D3<=151.5,IF(D3<=99.5,IF(J3<=36.5,0,0),IF(I3<=0.317,0,0)),IF(F3<=38.5,IF(J3<=44.5,1,1),1)) -> 0 | U3: =IF(H3<=29.650001,IF(C3<=8.5,IF(H3<=26.5,0,0),0),IF(C3<=6.5,IF(H3<=43,0,1),IF(I3<=0.208,0,1))) -> 0 | V3: =IF(H3<=29.849999,IF(C3<=4.5,IF(H3<=25.45,0,0),IF(I3<=0.261,0,0)),IF(G3<=179,IF(C3<=4.5,0,1),IF(H3<=35.049999,1,1))) -> 0 | W3: =IF(D3<=127.5,IF(C3<=5.5,IF(E3<=79,0,0),IF(I3<=0.2205,0,0)),IF(I3<=0.3165,IF(I3<=0.242,1,0),IF(D3<=143.5,1,1))) -> 0 | X3: =COUNTIF(L3:W3,0) -> 12 | Y3: =COUNTIF(L3:W3,1) -> 0 | Z3: =IF(X3>Y3,0,1) -> 0 | AA3: =IF(Z3=K3,1,0) -> 1 | AC3: 199 | AD3: =VLOOKUP(AC3,B:AA,26,FALSE) -> 0 | AE3: =VLOOKUP(AC3,B:AA,23,FALSE) -> 11 | AF3: =VLOOKUP(AC3,B:AA,24,FALSE) -> 1 | AG3: =AE3&"_"&AF3 -> 11_1 | AJ3: =AJ2/231 -> 0.75757576
B4: 3 | C4: 8 | D4: 183 | E4: 64 | F4: 0 | G4: 0 | H4: 23.3 | I4: 0.672 | J4: 32 | K4: 1 | L4: =IF(J4<=42.5,IF(G4<=119.5,IF(C4<=2.5,0,0),IF(C4<=0.5,1,0)),IF(G4<=139.5,IF(J4<=55.5,1,0),1)) -> 0 | M4: =IF(J4<=30.5,IF(H4<=36.25,IF(J4<=26.5,0,0),IF(H4<=42.75,0,1)),IF(H4<=27.45,IF(H4<=24.8,0,0),IF(J4<=42.5,1,1))) -> 0 | N4: =IF(D4<=137.5,IF(J4<=27.5,IF(I4<=0.4945,0,0),IF(D4<=107.5,0,0)),IF(D4<=155.5,IF(D4<=146.5,1,0),IF(J4<=44.5,1,1))) -> 1 | O4: =IF(D4<=133.5,IF(I4<=0.5095,IF(D4<=94.5,0,0),IF(F4<=28.5,0,1)),IF(D4<=161.5,IF(I4<=0.315,0,1),IF(C4<=6.5,1,1))) -> 1 | P4: =IF(D4<=124.5,IF(J4<=27.5,IF(F4<=30.5,0,0),IF(D4<=94.5,0,0)),IF(D4<=166.5,IF(J4<=24.5,0,1),IF(J4<=37.5,1,1))) -> 1 | Q4: =IF(H4<=28.849999,IF(C4<=5.5,IF(E4<=69,0,0),IF(H4<=24.7,0,0)),IF(C4<=4.5,IF(G4<=107.5,0,0),IF(G4<=122.5,0,1))) -> 0 | R4: =IF(D4<=154.5,IF(H4<=27.849999,IF(D4<=107.5,0,0),IF(I4<=1.105,0,1)),IF(I4<=0.2745,1,IF(G4<=171.5,1,1))) -> 1 | S4: =IF(D4<=133.5,IF(J4<=27.5,IF(H4<=31.3,0,0),IF(H4<=28.65,0,0)),IF(H4<=29.4,0,IF(D4<=155.5,1,1))) -> 0 | T4: =IF(D4<=151.5,IF(D4<=99.5,IF(J4<=36.5,0,0),IF(I4<=0.317,0,0)),IF(F4<=38.5,IF(J4<=44.5,1,1),1)) -> 1 | U4: =IF(H4<=29.650001,IF(C4<=8.5,IF(H4<=26.5,0,0),0),IF(C4<=6.5,IF(H4<=43,0,1),IF(I4<=0.208,0,1))) -> 0 | V4: =IF(H4<=29.849999,IF(C4<=4.5,IF(H4<=25.45,0,0),IF(I4<=0.261,0,0)),IF(G4<=179,IF(C4<=4.5,0,1),IF(H4<=35.049999,1,1))) -> 0 | W4: =IF(D4<=127.5,IF(C4<=5.5,IF(E4<=79,0,0),IF(I4<=0.2205,0,0)),IF(I4<=0.3165,IF(I4<=0.242,1,0),IF(D4<=143.5,1,1))) -> 1 | X4: =COUNTIF(L4:W4,0) -> 6 | Y4: =COUNTIF(L4:W4,1) -> 6 | Z4: =IF(X4>Y4,0,1) -> 1 | AA4: =IF(Z4=K4,1,0) -> 1 | AC4: 25 | AD4: =VLOOKUP(AC4,B:AA,26,FALSE) -> 1 | AE4: =VLOOKUP(AC4,B:AA,23,FALSE) -> 4 | AF4: =VLOOKUP(AC4,B:AA,24,FALSE) -> 8 | AG4: =AE4&"_"&AF4 -> 4_8
B5: 4 | C5: 1 | D5: 89 | E5: 66 | F5: 23 | G5: 94 | H5: 28.1 | I5: 0.167 | J5: 21 | K5: 0 | L5: =IF(J5<=42.5,IF(G5<=119.5,IF(C5<=2.5,0,0),IF(C5<=0.5,1,0)),IF(G5<=139.5,IF(J5<=55.5,1,0),1)) -> 0 | M5: =IF(J5<=30.5,IF(H5<=36.25,IF(J5<=26.5,0,0),IF(H5<=42.75,0,1)),IF(H5<=27.45,IF(H5<=24.8,0,0),IF(J5<=42.5,1,1))) -> 0 | N5: =IF(D5<=137.5,IF(J5<=27.5,IF(I5<=0.4945,0,0),IF(D5<=107.5,0,0)),IF(D5<=155.5,IF(D5<=146.5,1,0),IF(J5<=44.5,1,1))) -> 0 | O5: =IF(D5<=133.5,IF(I5<=0.5095,IF(D5<=94.5,0,0),IF(F5<=28.5,0,1)),IF(D5<=161.5,IF(I5<=0.315,0,1),IF(C5<=6.5,1,1))) -> 0 | P5: =IF(D5<=124.5,IF(J5<=27.5,IF(F5<=30.5,0,0),IF(D5<=94.5,0,0)),IF(D5<=166.5,IF(J5<=24.5,0,1),IF(J5<=37.5,1,1))) -> 0 | Q5: =IF(H5<=28.849999,IF(C5<=5.5,IF(E5<=69,0,0),IF(H5<=24.7,0,0)),IF(C5<=4.5,IF(G5<=107.5,0,0),IF(G5<=122.5,0,1))) -> 0 | R5: =IF(D5<=154.5,IF(H5<=27.849999,IF(D5<=107.5,0,0),IF(I5<=1.105,0,1)),IF(I5<=0.2745,1,IF(G5<=171.5,1,1))) -> 0 | S5: =IF(D5<=133.5,IF(J5<=27.5,IF(H5<=31.3,0,0),IF(H5<=28.65,0,0)),IF(H5<=29.4,0,IF(D5<=155.5,1,1))) -> 0 | T5: =IF(D5<=151.5,IF(D5<=99.5,IF(J5<=36.5,0,0),IF(I5<=0.317,0,0)),IF(F5<=38.5,IF(J5<=44.5,1,1),1)) -> 0 | U5: =IF(H5<=29.650001,IF(C5<=8.5,IF(H5<=26.5,0,0),0),IF(C5<=6.5,IF(H5<=43,0,1),IF(I5<=0.208,0,1))) -> 0 | V5: =IF(H5<=29.849999,IF(C5<=4.5,IF(H5<=25.45,0,0),IF(I5<=0.261,0,0)),IF(G5<=179,IF(C5<=4.5,0,1),IF(H5<=35.049999,1,1))) -> 0 | W5: =IF(D5<=127.5,IF(C5<=5.5,IF(E5<=79,0,0),IF(I5<=0.2205,0,0)),IF(I5<=0.3165,IF(I5<=0.242,1,0),IF(D5<=143.5,1,1))) -> 0 | X5: =COUNTIF(L5:W5,0) -> 12 | Y5: =COUNTIF(L5:W5,1) -> 0 | Z5: =IF(X5>Y5,0,1) -> 0 | AA5: =IF(Z5=K5,1,0) -> 1 | AC5: 418 | AD5: =VLOOKUP(AC5,B:AA,26,FALSE) -> 1 | AE5: =VLOOKUP(AC5,B:AA,23,FALSE) -> 6 | AF5: =VLOOKUP(AC5,B:AA,24,FALSE) -> 6 | AG5: =AE5&"_"&AF5 -> 6_6
B6: 5 | C6: 0 | D6: 137 | E6: 40 | F6: 35 | G6: 168 | H6: 43.1 | I6: 2.288 | J6: 33 | K6: 1 | L6: =IF(J6<=42.5,IF(G6<=119.5,IF(C6<=2.5,0,0),IF(C6<=0.5,1,0)),IF(G6<=139.5,IF(J6<=55.5,1,0),1)) -> 1 | M6: =IF(J6<=30.5,IF(H6<=36.25,IF(J6<=26.5,0,0),IF(H6<=42.75,0,1)),IF(H6<=27.45,IF(H6<=24.8,0,0),IF(J6<=42.5,1,1))) -> 1 | N6: =IF(D6<=137.5,IF(J6<=27.5,IF(I6<=0.4945,0,0),IF(D6<=107.5,0,0)),IF(D6<=155.5,IF(D6<=146.5,1,0),IF(J6<=44.5,1,1))) -> 0 | O6: =IF(D6<=133.5,IF(I6<=0.5095,IF(D6<=94.5,0,0),IF(F6<=28.5,0,1)),IF(D6<=161.5,IF(I6<=0.315,0,1),IF(C6<=6.5,1,1))) -> 1 | P6: =IF(D6<=124.5,IF(J6<=27.5,IF(F6<=30.5,0,0),IF(D6<=94.5,0,0)),IF(D6<=166.5,IF(J6<=24.5,0,1),IF(J6<=37.5,1,1))) -> 1 | Q6: =IF(H6<=28.849999,IF(C6<=5.5,IF(E6<=69,0,0),IF(H6<=24.7,0,0)),IF(C6<=4.5,IF(G6<=107.5,0,0),IF(G6<=122.5,0,1))) -> 0 | R6: =IF(D6<=154.5,IF(H6<=27.849999,IF(D6<=107.5,0,0),IF(I6<=1.105,0,1)),IF(I6<=0.2745,1,IF(G6<=171.5,1,1))) -> 1 | S6: =IF(D6<=133.5,IF(J6<=27.5,IF(H6<=31.3,0,0),IF(H6<=28.65,0,0)),IF(H6<=29.4,0,IF(D6<=155.5,1,1))) -> 1 | T6: =IF(D6<=151.5,IF(D6<=99.5,IF(J6<=36.5,0,0),IF(I6<=0.317,0,0)),IF(F6<=38.5,IF(J6<=44.5,1,1),1)) -> 0 | U6: =IF(H6<=29.650001,IF(C6<=8.5,IF(H6<=26.5,0,0),0),IF(C6<=6.5,IF(H6<=43,0,1),IF(I6<=0.208,0,1))) -> 1 | V6: =IF(H6<=29.849999,IF(C6<=4.5,IF(H6<=25.45,0,0),IF(I6<=0.261,0,0)),IF(G6<=179,IF(C6<=4.5,0,1),IF(H6<=35.049999,1,1))) -> 0 | W6: =IF(D6<=127.5,IF(C6<=5.5,IF(E6<=79,0,0),IF(I6<=0.2205,0,0)),IF(I6<=0.3165,IF(I6<=0.242,1,0),IF(D6<=143.5,1,1))) -> 1 | X6: =COUNTIF(L6:W6,0) -> 4 | Y6: =COUNTIF(L6:W6,1) -> 8 | Z6: =IF(X6>Y6,0,1) -> 1 | AA6: =IF(Z6=K6,1,0) -> 1 | AC6: 388 | AD6: =VLOOKUP(AC6,B:AA,26,FALSE) -> 0 | AE6: =VLOOKUP(AC6,B:AA,23,FALSE) -> 8 | AF6: =VLOOKUP(AC6,B:AA,24,FALSE) -> 4 | AG6: =AE6&"_"&AF6 -> 8_4
B7: 6 | C7: 5 | D7: 116 | E7: 74 | F7: 0 | G7: 0 | H7: 25.6 | I7: 0.201 | J7: 30 | K7: 0 | L7: =IF(J7<=42.5,IF(G7<=119.5,IF(C7<=2.5,0,0),IF(C7<=0.5,1,0)),IF(G7<=139.5,IF(J7<=55.5,1,0),1)) -> 0 | M7: =IF(J7<=30.5,IF(H7<=36.25,IF(J7<=26.5,0,0),IF(H7<=42.75,0,1)),IF(H7<=27.45,IF(H7<=24.8,0,0),IF(J7<=42.5,1,1))) -> 0 | N7: =IF(D7<=137.5,IF(J7<=27.5,IF(I7<=0.4945,0,0),IF(D7<=107.5,0,0)),IF(D7<=155.5,IF(D7<=146.5,1,0),IF(J7<=44.5,1,1))) -> 0 | O7: =IF(D7<=133.5,IF(I7<=0.5095,IF(D7<=94.5,0,0),IF(F7<=28.5,0,1)),IF(D7<=161.5,IF(I7<=0.315,0,1),IF(C7<=6.5,1,1))) -> 0 | P7: =IF(D7<=124.5,IF(J7<=27.5,IF(F7<=30.5,0,0),IF(D7<=94.5,0,0)),IF(D7<=166.5,IF(J7<=24.5,0,1),IF(J7<=37.5,1,1))) -> 0 | Q7: =IF(H7<=28.849999,IF(C7<=5.5,IF(E7<=69,0,0),IF(H7<=24.7,0,0)),IF(C7<=4.5,IF(G7<=107.5,0,0),IF(G7<=122.5,0,1))) -> 0 | R7: =IF(D7<=154.5,IF(H7<=27.849999,IF(D7<=107.5,0,0),IF(I7<=1.105,0,1)),IF(I7<=0.2745,1,IF(G7<=171.5,1,1))) -> 0 | S7: =IF(D7<=133.5,IF(J7<=27.5,IF(H7<=31.3,0,0),IF(H7<=28.65,0,0)),IF(H7<=29.4,0,IF(D7<=155.5,1,1))) -> 0 | T7: =IF(D7<=151.5,IF(D7<=99.5,IF(J7<=36.5,0,0),IF(I7<=0.317,0,0)),IF(F7<=38.5,IF(J7<=44.5,1,1),1)) -> 0 | U7: =IF(H7<=29.650001,IF(C7<=8.5,IF(H7<=26.5,0,0),0),IF(C7<=6.5,IF(H7<=43,0,1),IF(I7<=0.208,0,1))) -> 0 | V7: =IF(H7<=29.849999,IF(C7<=4.5,IF(H7<=25.45,0,0),IF(I7<=0.261,0,0)),IF(G7<=179,IF(C7<=4.5,0,1),IF(H7<=35.049999,1,1))) -> 0 | W7: =IF(D7<=127.5,IF(C7<=5.5,IF(E7<=79,0,0),IF(I7<=0.2205,0,0)),IF(I7<=0.3165,IF(I7<=0.242,1,0),IF(D7<=143.5,1,1))) -> 0 | X7: =COUNTIF(L7:W7,0) -> 12 | Y7: =COUNTIF(L7:W7,1) -> 0 | Z7: =IF(X7>Y7,0,1) -> 0 | AA7: =IF(Z7=K7,1,0) -> 1 | AC7: 157 | AD7: =VLOOKUP(AC7,B:AA,26,FALSE) -> 1 | AE7: =VLOOKUP(AC7,B:AA,23,FALSE) -> 12 | AF7: =VLOOKUP(AC7,B:AA,24,FALSE) -> 0 | AG7: =AE7&"_"&AF7 -> 12_0
B8: 7 | C8: 3 | D8: 78 | E8: 50 | F8: 32 | G8: 88 | H8: 31 | I8: 0.248 | J8: 26 | K8: 1 | L8: =IF(J8<=42.5,IF(G8<=119.5,IF(C8<=2.5,0,0),IF(C8<=0.5,1,0)),IF(G8<=139.5,IF(J8<=55.5,1,0),1)) -> 0 | M8: =IF(J8<=30.5,IF(H8<=36.25,IF(J8<=26.5,0,0),IF(H8<=42.75,0,1)),IF(H8<=27.45,IF(H8<=24.8,0,0),IF(J8<=42.5,1,1))) -> 0 | N8: =IF(D8<=137.5,IF(J8<=27.5,IF(I8<=0.4945,0,0),IF(D8<=107.5,0,0)),IF(D8<=155.5,IF(D8<=146.5,1,0),IF(J8<=44.5,1,1))) -> 0 | O8: =IF(D8<=133.5,IF(I8<=0.5095,IF(D8<=94.5,0,0),IF(F8<=28.5,0,1)),IF(D8<=161.5,IF(I8<=0.315,0,1),IF(C8<=6.5,1,1))) -> 0 | P8: =IF(D8<=124.5,IF(J8<=27.5,IF(F8<=30.5,0,0),IF(D8<=94.5,0,0)),IF(D8<=166.5,IF(J8<=24.5,0,1),IF(J8<=37.5,1,1))) -> 0 | Q8: =IF(H8<=28.849999,IF(C8<=5.5,IF(E8<=69,0,0),IF(H8<=24.7,0,0)),IF(C8<=4.5,IF(G8<=107.5,0,0),IF(G8<=122.5,0,1))) -> 0 | R8: =IF(D8<=154.5,IF(H8<=27.849999,IF(D8<=107.5,0,0),IF(I8<=1.105,0,1)),IF(I8<=0.2745,1,IF(G8<=171.5,1,1))) -> 0 | S8: =IF(D8<=133.5,IF(J8<=27.5,IF(H8<=31.3,0,0),IF(H8<=28.65,0,0)),IF(H8<=29.4,0,IF(D8<=155.5,1,1))) -> 0 | T8: =IF(D8<=151.5,IF(D8<=99.5,IF(J8<=36.5,0,0),IF(I8<=0.317,0,0)),IF(F8<=38.5,IF(J8<=44.5,1,1),1)) -> 0 | U8: =IF(H8<=29.650001,IF(C8<=8.5,IF(H8<=26.5,0,0),0),IF(C8<=6.5,IF(H8<=43,0,1),IF(I8<=0.208,0,1))) -> 0 | V8: =IF(H8<=29.849999,IF(C8<=4.5,IF(H8<=25.45,0,0),IF(I8<=0.261,0,0)),IF(G8<=179,IF(C8<=4.5,0,1),IF(H8<=35.049999,1,1))) -> 0 | W8: =IF(D8<=127.5,IF(C8<=5.5,IF(E8<=79,0,0),IF(I8<=0.2205,0,0)),IF(I8<=0.3165,IF(I8<=0.242,1,0),IF(D8<=143.5,1,1))) -> 0 | X8: =COUNTIF(L8:W8,0) -> 12 | Y8: =COUNTIF(L8:W8,1) -> 0 | Z8: =IF(X8>Y8,0,1) -> 0 | AA8: =IF(Z8=K8,1,0) -> 0 | AC8: 661 | AD8: =VLOOKUP(AC8,B:AA,26,FALSE) -> 0 | AE8: =VLOOKUP(AC8,B:AA,23,FALSE) -> 4 | AF8: =VLOOKUP(AC8,B:AA,24,FALSE) -> 8 | AG8: =AE8&"_"&AF8 -> 4_8
B9: 8 | C9: 10 | D9: 115 | E9: 0 | F9: 0 | G9: 0 | H9: 35.3 | I9: 0.134 | J9: 29 | K9: 0 | L9: =IF(J9<=42.5,IF(G9<=119.5,IF(C9<=2.5,0,0),IF(C9<=0.5,1,0)),IF(G9<=139.5,IF(J9<=55.5,1,0),1)) -> 0 | M9: =IF(J9<=30.5,IF(H9<=36.25,IF(J9<=26.5,0,0),IF(H9<=42.75,0,1)),IF(H9<=27.45,IF(H9<=24.8,0,0),IF(J9<=42.5,1,1))) -> 0 | N9: =IF(D9<=137.5,IF(J9<=27.5,IF(I9<=0.4945,0,0),IF(D9<=107.5,0,0)),IF(D9<=155.5,IF(D9<=146.5,1,0),IF(J9<=44.5,1,1))) -> 0 | O9: =IF(D9<=133.5,IF(I9<=0.5095,IF(D9<=94.5,0,0),IF(F9<=28.5,0,1)),IF(D9<=161.5,IF(I9<=0.315,0,1),IF(C9<=6.5,1,1))) -> 0 | P9: =IF(D9<=124.5,IF(J9<=27.5,IF(F9<=30.5,0,0),IF(D9<=94.5,0,0)),IF(D9<=166.5,IF(J9<=24.5,0,1),IF(J9<=37.5,1,1))) -> 0 | Q9: =IF(H9<=28.849999,IF(C9<=5.5,IF(E9<=69,0,0),IF(H9<=24.7,0,0)),IF(C9<=4.5,IF(G9<=107.5,0,0),IF(G9<=122.5,0,1))) -> 0 | R9: =IF(D9<=154.5,IF(H9<=27.849999,IF(D9<=107.5,0,0),IF(I9<=1.105,0,1)),IF(I9<=0.2745,1,IF(G9<=171.5,1,1))) -> 0 | S9: =IF(D9<=133.5,IF(J9<=27.5,IF(H9<=31.3,0,0),IF(H9<=28.65,0,0)),IF(H9<=29.4,0,IF(D9<=155.5,1,1))) -> 0 | T9: =IF(D9<=151.5,IF(D9<=99.5,IF(J9<=36.5,0,0),IF(I9<=0.317,0,0)),IF(F9<=38.5,IF(J9<=44.5,1,1),1)) -> 0 | U9: =IF(H9<=29.650001,IF(C9<=8.5,IF(H9<=26.5,0,0),0),IF(C9<=6.5,IF(H9<=43,0,1),IF(I9<=0.208,0,1))) -> 0 | V9: =IF(H9<=29.849999,IF(C9<=4.5,IF(H9<=25.45,0,0),IF(I9<=0.261,0,0)),IF(G9<=179,IF(C9<=4.5,0,1),IF(H9<=35.049999,1,1))) -> 1 | W9: =IF(D9<=127.5,IF(C9<=5.5,IF(E9<=79,0,0),IF(I9<=0.2205,0,0)),IF(I9<=0.3165,IF(I9<=0.242,1,0),IF(D9<=143.5,1,1))) -> 0 | X9: =COUNTIF(L9:W9,0) -> 11 | Y9: =COUNTIF(L9:W9,1) -> 1 | Z9: =IF(X9>Y9,0,1) -> 0 | AA9: =IF(Z9=K9,1,0) -> 1 | AC9: 206 | AD9: =VLOOKUP(AC9,B:AA,26,FALSE) -> 1 | AE9: =VLOOKUP(AC9,B:AA,23,FALSE) -> 12 | AF9: =VLOOKUP(AC9,B:AA,24,FALSE) -> 0 | AG9: =AE9&"_"&AF9 -> 12_0
B10: 9 | C10: 2 | D10: 197 | E10: 70 | F10: 45 | G10: 543 | H10: 30.5 | I10: 0.158 | J10: 53 | K10: 1 | L10: =IF(J10<=42.5,IF(G10<=119.5,IF(C10<=2.5,0,0),IF(C10<=0.5,1,0)),IF(G10<=139.5,IF(J10<=55.5,1,0),1)) -> 1 | M10: =IF(J10<=30.5,IF(H10<=36.25,IF(J10<=26.5,0,0),IF(H10<=42.75,0,1)),IF(H10<=27.45,IF(H10<=24.8,0,0),IF(J10<=42.5,1,1))) -> 1 | N10: =IF(D10<=137.5,IF(J10<=27.5,IF(I10<=0.4945,0,0),IF(D10<=107.5,0,0)),IF(D10<=155.5,IF(D10<=146.5,1,0),IF(J10<=44.5,1,1))) -> 1 | O10: =IF(D10<=133.5,IF(I10<=0.5095,IF(D10<=94.5,0,0),IF(F10<=28.5,0,1)),IF(D10<=161.5,IF(I10<=0.315,0,1),IF(C10<=6.5,1,1))) -> 1 | P10: =IF(D10<=124.5,IF(J10<=27.5,IF(F10<=30.5,0,0),IF(D10<=94.5,0,0)),IF(D10<=166.5,IF(J10<=24.5,0,1),IF(J10<=37.5,1,1))) -> 1 | Q10: =IF(H10<=28.849999,IF(C10<=5.5,IF(E10<=69,0,0),IF(H10<=24.7,0,0)),IF(C10<=4.5,IF(G10<=107.5,0,0),IF(G10<=122.5,0,1))) -> 0 | R10: =IF(D10<=154.5,IF(H10<=27.849999,IF(D10<=107.5,0,0),IF(I10<=1.105,0,1)),IF(I10<=0.2745,1,IF(G10<=171.5,1,1))) -> 1 | S10: =IF(D10<=133.5,IF(J10<=27.5,IF(H10<=31.3,0,0),IF(H10<=28.65,0,0)),IF(H10<=29.4,0,IF(D10<=155.5,1,1))) -> 1 | T10: =IF(D10<=151.5,IF(D10<=99.5,IF(J10<=36.5,0,0),IF(I10<=0.317,0,0)),IF(F10<=38.5,IF(J10<=44.5,1,1),1)) -> 1 | U10: =IF(H10<=29.650001,IF(C10<=8.5,IF(H10<=26.5,0,0),0),IF(C10<=6.5,IF(H10<=43,0,1),IF(I10<=0.208,0,1))) -> 0 | V10: =IF(H10<=29.849999,IF(C10<=4.5,IF(H10<=25.45,0,0),IF(I10<=0.261,0,0)),IF(G10<=179,IF(C10<=4.5,0,1),IF(H10<=35.049999,1,1))) -> 1 | W10: =IF(D10<=127.5,IF(C10<=5.5,IF(E10<=79,0,0),IF(I10<=0.2205,0,0)),IF(I10<=0.3165,IF(I10<=0.242,1,0),IF(D10<=143.5,1,1))) -> 1 | X10: =COUNTIF(L10:W10,0) -> 2 | Y10: =COUNTIF(L10:W10,1) -> 10 | Z10: =IF(X10>Y10,0,1) -> 1 | AA10: =IF(Z10=K10,1,0) -> 1 | AC10: 4 | AD10: =VLOOKUP(AC10,B:AA,26,FALSE) -> 1 | AE10: =VLOOKUP(AC10,B:AA,23,FALSE) -> 12 | AF10: =VLOOKUP(AC10,B:AA,24,FALSE) -> 0 | AG10: =AE10&"_"&AF10 -> 12_0
B11: 10 | C11: 8 | D11: 125 | E11: 96 | F11: 0 | G11: 0 | H11: 0 | I11: 0.232 | J11: 54 | K11: 1 | L11: =IF(J11<=42.5,IF(G11<=119.5,IF(C11<=2.5,0,0),IF(C11<=0.5,1,0)),IF(G11<=139.5,IF(J11<=55.5,1,0),1)) -> 1 | M11: =IF(J11<=30.5,IF(H11<=36.25,IF(J11<=26.5,0,0),IF(H11<=42.75,0,1)),IF(H11<=27.45,IF(H11<=24.8,0,0),IF(J11<=42.5,1,1))) -> 0 | N11: =IF(D11<=137.5,IF(J11<=27.5,IF(I11<=0.4945,0,0),IF(D11<=107.5,0,0)),IF(D11<=155.5,IF(D11<=146.5,1,0),IF(J11<=44.5,1,1))) -> 0 | O11: =IF(D11<=133.5,IF(I11<=0.5095,IF(D11<=94.5,0,0),IF(F11<=28.5,0,1)),IF(D11<=161.5,IF(I11<=0.315,0,1),IF(C11<=6.5,1,1))) -> 0 | P11: =IF(D11<=124.5,IF(J11<=27.5,IF(F11<=30.5,0,0),IF(D11<=94.5,0,0)),IF(D11<=166.5,IF(J11<=24.5,0,1),IF(J11<=37.5,1,1))) -> 1 | Q11: =IF(H11<=28.849999,IF(C11<=5.5,IF(E11<=69,0,0),IF(H11<=24.7,0,0)),IF(C11<=4.5,IF(G11<=107.5,0,0),IF(G11<=122.5,0,1))) -> 0 | R11: =IF(D11<=154.5,IF(H11<=27.849999,IF(D11<=107.5,0,0),IF(I11<=1.105,0,1)),IF(I11<=0.2745,1,IF(G11<=171.5,1,1))) -> 0 | S11: =IF(D11<=133.5,IF(J11<=27.5,IF(H11<=31.3,0,0),IF(H11<=28.65,0,0)),IF(H11<=29.4,0,IF(D11<=155.5,1,1))) -> 0 | T11: =IF(D11<=151.5,IF(D11<=99.5,IF(J11<=36.5,0,0),IF(I11<=0.317,0,0)),IF(F11<=38.5,IF(J11<=44.5,1,1),1)) -> 0 | U11: =IF(H11<=29.650001,IF(C11<=8.5,IF(H11<=26.5,0,0),0),IF(C11<=6.5,IF(H11<=43,0,1),IF(I11<=0.208,0,1))) -> 0 | V11: =IF(H11<=29.849999,IF(C11<=4.5,IF(H11<=25.45,0,0),IF(I11<=0.261,0,0)),IF(G11<=179,IF(C11<=4.5,0,1),IF(H11<=35.049999,1,1))) -> 0 | W11: =IF(D11<=127.5,IF(C11<=5.5,IF(E11<=79,0,0),IF(I11<=0.2205,0,0)),IF(I11<=0.3165,IF(I11<=0.242,1,0),IF(D11<=143.5,1,1))) -> 0 | X11: =COUNTIF(L11:W11,0) -> 10 | Y11: =COUNTIF(L11:W11,1) -> 2 | Z11: =IF(X11>Y11,0,1) -> 0 | AA11: =IF(Z11=K11,1,0) -> 0 | AC11: 532 | AD11: =VLOOKUP(AC11,B:AA,26,FALSE) -> 1 | AE11: =VLOOKUP(AC11,B:AA,23,FALSE) -> 10 | AF11: =VLOOKUP(AC11,B:AA,24,FALSE) -> 2 | AG11: =AE11&"_"&AF11 -> 10_2
B12: 11 | C12: 4 | D12: 110 | E12: 92 | F12: 0 | G12: 0 | H12: 37.6 | I12: 0.191 | J12: 30 | K12: 0 | L12: =IF(J12<=42.5,IF(G12<=119.5,IF(C12<=2.5,0,0),IF(C12<=0.5,1,0)),IF(G12<=139.5,IF(J12<=55.5,1,0),1)) -> 0 | M12: =IF(J12<=30.5,IF(H12<=36.25,IF(J12<=26.5,0,0),IF(H12<=42.75,0,1)),IF(H12<=27.45,IF(H12<=24.8,0,0),IF(J12<=42.5,1,1))) -> 0 | N12: =IF(D12<=137.5,IF(J12<=27.5,IF(I12<=0.4945,0,0),IF(D12<=107.5,0,0)),IF(D12<=155.5,IF(D12<=146.5,1,0),IF(J12<=44.5,1,1))) -> 0 | O12: =IF(D12<=133.5,IF(I12<=0.5095,IF(D12<=94.5,0,0),IF(F12<=28.5,0,1)),IF(D12<=161.5,IF(I12<=0.315,0,1),IF(C12<=6.5,1,1))) -> 0 | P12: =IF(D12<=124.5,IF(J12<=27.5,IF(F12<=30.5,0,0),IF(D12<=94.5,0,0)),IF(D12<=166.5,IF(J12<=24.5,0,1),IF(J12<=37.5,1,1))) -> 0 | Q12: =IF(H12<=28.849999,IF(C12<=5.5,IF(E12<=69,0,0),IF(H12<=24.7,0,0)),IF(C12<=4.5,IF(G12<=107.5,0,0),IF(G12<=122.5,0,1))) -> 0 | R12: =IF(D12<=154.5,IF(H12<=27.849999,IF(D12<=107.5,0,0),IF(I12<=1.105,0,1)),IF(I12<=0.2745,1,IF(G12<=171.5,1,1))) -> 0 | S12: =IF(D12<=133.5,IF(J12<=27.5,IF(H12<=31.3,0,0),IF(H12<=28.65,0,0)),IF(H12<=29.4,0,IF(D12<=155.5,1,1))) -> 0 | T12: =IF(D12<=151.5,IF(D12<=99.5,IF(J12<=36.5,0,0),IF(I12<=0.317,0,0)),IF(F12<=38.5,IF(J12<=44.5,1,1),1)) -> 0 | U12: =IF(H12<=29.650001,IF(C12<=8.5,IF(H12<=26.5,0,0),0),IF(C12<=6.5,IF(H12<=43,0,1),IF(I12<=0.208,0,1))) -> 0 | V12: =IF(H12<=29.849999,IF(C12<=4.5,IF(H12<=25.45,0,0),IF(I12<=0.261,0,0)),IF(G12<=179,IF(C12<=4.5,0,1),IF(H12<=35.049999,1,1))) -> 0 | W12: =IF(D12<=127.5,IF(C12<=5.5,IF(E12<=79,0,0),IF(I12<=0.2205,0,0)),IF(I12<=0.3165,IF(I12<=0.242,1,0),IF(D12<=143.5,1,1))) -> 0 | X12: =COUNTIF(L12:W12,0) -> 12 | Y12: =COUNTIF(L12:W12,1) -> 0 | Z12: =IF(X12>Y12,0,1) -> 0 | AA12: =IF(Z12=K12,1,0) -> 1 | AC12: 159 | AD12: =VLOOKUP(AC12,B:AA,26,FALSE) -> 1 | AE12: =VLOOKUP(AC12,B:AA,23,FALSE) -> 12 | AF12: =VLOOKUP(AC12,B:AA,24,FALSE) -> 0 | AG12: =AE12&"_"&AF12 -> 12_0
B13: 12 | C13: 10 | D13: 168 | E13: 74 | F13: 0 | G13: 0 | H13: 38 | I13: 0.537 | J13: 34 | K13: 1 | L13: =IF(J13<=42.5,IF(G13<=119.5,IF(C13<=2.5,0,0),IF(C13<=0.5,1,0)),IF(G13<=139.5,IF(J13<=55.5,1,0),1)) -> 0 | M13: =IF(J13<=30.5,IF(H13<=36.25,IF(J13<=26.5,0,0),IF(H13<=42.75,0,1)),IF(H13<=27.45,IF(H13<=24.8,0,0),IF(J13<=42.5,1,1))) -> 1 | N13: =IF(D13<=137.5,IF(J13<=27.5,IF(I13<=0.4945,0,0),IF(D13<=107.5,0,0)),IF(D13<=155.5,IF(D13<=146.5,1,0),IF(J13<=44.5,1,1))) -> 1 | O13: =IF(D13<=133.5,IF(I13<=0.5095,IF(D13<=94.5,0,0),IF(F13<=28.5,0,1)),IF(D13<=161.5,IF(I13<=0.315,0,1),IF(C13<=6.5,1,1))) -> 1 | P13: =IF(D13<=124.5,IF(J13<=27.5,IF(F13<=30.5,0,0),IF(D13<=94.5,0,0)),IF(D13<=166.5,IF(J13<=24.5,0,1),IF(J13<=37.5,1,1))) -> 1 | Q13: =IF(H13<=28.849999,IF(C13<=5.5,IF(E13<=69,0,0),IF(H13<=24.7,0,0)),IF(C13<=4.5,IF(G13<=107.5,0,0),IF(G13<=122.5,0,1))) -> 0 | R13: =IF(D13<=154.5,IF(H13<=27.849999,IF(D13<=107.5,0,0),IF(I13<=1.105,0,1)),IF(I13<=0.2745,1,IF(G13<=171.5,1,1))) -> 1 | S13: =IF(D13<=133.5,IF(J13<=27.5,IF(H13<=31.3,0,0),IF(H13<=28.65,0,0)),IF(H13<=29.4,0,IF(D13<=155.5,1,1))) -> 1 | T13: =IF(D13<=151.5,IF(D13<=99.5,IF(J13<=36.5,0,0),IF(I13<=0.317,0,0)),IF(F13<=38.5,IF(J13<=44.5,1,1),1)) -> 1 | U13: =IF(H13<=29.650001,IF(C13<=8.5,IF(H13<=26.5,0,0),0),IF(C13<=6.5,IF(H13<=43,0,1),IF(I13<=0.208,0,1))) -> 1 | V13: =IF(H13<=29.849999,IF(C13<=4.5,IF(H13<=25.45,0,0),IF(I13<=0.261,0,0)),IF(G13<=179,IF(C13<=4.5,0,1),IF(H13<=35.049999,1,1))) -> 1 | W13: =IF(D13<=127.5,IF(C13<=5.5,IF(E13<=79,0,0),IF(I13<=0.2205,0,0)),IF(I13<=0.3165,IF(I13<=0.242,1,0),IF(D13<=143.5,1,1))) -> 1 | X13: =COUNTIF(L13:W13,0) -> 2 | Y13: =COUNTIF(L13:W13,1) -> 10 | Z13: =IF(X13>Y13,0,1) -> 1 | AA13: =IF(Z13=K13,1,0) -> 1 | AC13: 348 | AD13: =VLOOKUP(AC13,B:AA,26,FALSE) -> 1 | AE13: =VLOOKUP(AC13,B:AA,23,FALSE) -> 12 | AF13: =VLOOKUP(AC13,B:AA,24,FALSE) -> 0 | AG13: =AE13&"_"&AF13 -> 12_0
B14: 13 | C14: 10 | D14: 139 | E14: 80 | F14: 0 | G14: 0 | H14: 27.1 | I14: 1.441 | J14: 57 | K14: 0 | L14: =IF(J14<=42.5,IF(G14<=119.5,IF(C14<=2.5,0,0),IF(C14<=0.5,1,0)),IF(G14<=139.5,IF(J14<=55.5,1,0),1)) -> 0 | M14: =IF(J14<=30.5,IF(H14<=36.25,IF(J14<=26.5,0,0),IF(H14<=42.75,0,1)),IF(H14<=27.45,IF(H14<=24.8,0,0),IF(J14<=42.5,1,1))) -> 0 | N14: =IF(D14<=137.5,IF(J14<=27.5,IF(I14<=0.4945,0,0),IF(D14<=107.5,0,0)),IF(D14<=155.5,IF(D14<=146.5,1,0),IF(J14<=44.5,1,1))) -> 1 | O14: =IF(D14<=133.5,IF(I14<=0.5095,IF(D14<=94.5,0,0),IF(F14<=28.5,0,1)),IF(D14<=161.5,IF(I14<=0.315,0,1),IF(C14<=6.5,1,1))) -> 1 | P14: =IF(D14<=124.5,IF(J14<=27.5,IF(F14<=30.5,0,0),IF(D14<=94.5,0,0)),IF(D14<=166.5,IF(J14<=24.5,0,1),IF(J14<=37.5,1,1))) -> 1 | Q14: =IF(H14<=28.849999,IF(C14<=5.5,IF(E14<=69,0,0),IF(H14<=24.7,0,0)),IF(C14<=4.5,IF(G14<=107.5,0,0),IF(G14<=122.5,0,1))) -> 0 | R14: =IF(D14<=154.5,IF(H14<=27.849999,IF(D14<=107.5,0,0),IF(I14<=1.105,0,1)),IF(I14<=0.2745,1,IF(G14<=171.5,1,1))) -> 0 | S14: =IF(D14<=133.5,IF(J14<=27.5,IF(H14<=31.3,0,0),IF(H14<=28.65,0,0)),IF(H14<=29.4,0,IF(D14<=155.5,1,1))) -> 0 | T14: =IF(D14<=151.5,IF(D14<=99.5,IF(J14<=36.5,0,0),IF(I14<=0.317,0,0)),IF(F14<=38.5,IF(J14<=44.5,1,1),1)) -> 0 | U14: =IF(H14<=29.650001,IF(C14<=8.5,IF(H14<=26.5,0,0),0),IF(C14<=6.5,IF(H14<=43,0,1),IF(I14<=0.208,0,1))) -> 0 | V14: =IF(H14<=29.849999,IF(C14<=4.5,IF(H14<=25.45,0,0),IF(I14<=0.261,0,0)),IF(G14<=179,IF(C14<=4.5,0,1),IF(H14<=35.049999,1,1))) -> 0 | W14: =IF(D14<=127.5,IF(C14<=5.5,IF(E14<=79,0,0),IF(I14<=0.2205,0,0)),IF(I14<=0.3165,IF(I14<=0.242,1,0),IF(D14<=143.5,1,1))) -> 1 | X14: =COUNTIF(L14:W14,0) -> 8 | Y14: =COUNTIF(L14:W14,1) -> 4 | Z14: =IF(X14>Y14,0,1) -> 0 | AA14: =IF(Z14=K14,1,0) -> 1 | AC14: 225 | AD14: =VLOOKUP(AC14,B:AA,26,FALSE) -> 1 | AE14: =VLOOKUP(AC14,B:AA,23,FALSE) -> 12 | AF14: =VLOOKUP(AC14,B:AA,24,FALSE) -> 0 | AG14: =AE14&"_"&AF14 -> 12_0
B15: 14 | C15: 1 | D15: 189 | E15: 60 | F15: 23 | G15: 846 | H15: 30.1 | I15: 0.398 | J15: 59 | K15: 1 | L15: =IF(J15<=42.5,IF(G15<=119.5,IF(C15<=2.5,0,0),IF(C15<=0.5,1,0)),IF(G15<=139.5,IF(J15<=55.5,1,0),1)) -> 1 | M15: =IF(J15<=30.5,IF(H15<=36.25,IF(J15<=26.5,0,0),IF(H15<=42.75,0,1)),IF(H15<=27.45,IF(H15<=24.8,0,0),IF(J15<=42.5,1,1))) -> 1 | N15: =IF(D15<=137.5,IF(J15<=27.5,IF(I15<=0.4945,0,0),IF(D15<=107.5,0,0)),IF(D15<=155.5,IF(D15<=146.5,1,0),IF(J15<=44.5,1,1))) -> 1 | O15: =IF(D15<=133.5,IF(I15<=0.5095,IF(D15<=94.5,0,0),IF(F15<=28.5,0,1)),IF(D15<=161.5,IF(I15<=0.315,0,1),IF(C15<=6.5,1,1))) -> 1 | P15: =IF(D15<=124.5,IF(J15<=27.5,IF(F15<=30.5,0,0),IF(D15<=94.5,0,0)),IF(D15<=166.5,IF(J15<=24.5,0,1),IF(J15<=37.5,1,1))) -> 1 | Q15: =IF(H15<=28.849999,IF(C15<=5.5,IF(E15<=69,0,0),IF(H15<=24.7,0,0)),IF(C15<=4.5,IF(G15<=107.5,0,0),IF(G15<=122.5,0,1))) -> 0 | R15: =IF(D15<=154.5,IF(H15<=27.849999,IF(D15<=107.5,0,0),IF(I15<=1.105,0,1)),IF(I15<=0.2745,1,IF(G15<=171.5,1,1))) -> 1 | S15: =IF(D15<=133.5,IF(J15<=27.5,IF(H15<=31.3,0,0),IF(H15<=28.65,0,0)),IF(H15<=29.4,0,IF(D15<=155.5,1,1))) -> 1 | T15: =IF(D15<=151.5,IF(D15<=99.5,IF(J15<=36.5,0,0),IF(I15<=0.317,0,0)),IF(F15<=38.5,IF(J15<=44.5,1,1),1)) -> 1 | U15: =IF(H15<=29.650001,IF(C15<=8.5,IF(H15<=26.5,0,0),0),IF(C15<=6.5,IF(H15<=43,0,1),IF(I15<=0.208,0,1))) -> 0 | V15: =IF(H15<=29.849999,IF(C15<=4.5,IF(H15<=25.45,0,0),IF(I15<=0.261,0,0)),IF(G15<=179,IF(C15<=4.5,0,1),IF(H15<=35.049999,1,1))) -> 1 | W15: =IF(D15<=127.5,IF(C15<=5.5,IF(E15<=79,0,0),IF(I15<=0.2205,0,0)),IF(I15<=0.3165,IF(I15<=0.242,1,0),IF(D15<=143.5,1,1))) -> 1 | X15: =COUNTIF(L15:W15,0) -> 2 | Y15: =COUNTIF(L15:W15,1) -> 10 | Z15: =IF(X15>Y15,0,1) -> 1 | AA15: =IF(Z15=K15,1,0) -> 1 | AC15: 757 | AD15: =VLOOKUP(AC15,B:AA,26,FALSE) -> 0 | AE15: =VLOOKUP(AC15,B:AA,23,FALSE) -> 5 | AF15: =VLOOKUP(AC15,B:AA,24,FALSE) -> 7 | AG15: =AE15&"_"&AF15 -> 5_7
... B232: 231 | C232: 4 | D232: 142 | E232: 86 | F232: 0 | G232: 0 | H232: 44 | I232: 0.645 | J232: 22 | K232: 1 | L232: =IF(J232<=42.5,IF(G232<=119.5,IF(C232<=2.5,0,0),IF(C232<=0.5,1,0)),IF(G232<=139.5,IF(J232<=55.5,1,0),1)) -> 0 | M232: =IF(J232<=30.5,IF(H232<=36.25,IF(J232<=26.5,0,0),IF(H232<=42.75,0,1)),IF(H232<=27.45,IF(H232<=24.8,0,0),IF(J232<=42.5,1,1))) -> 1 | N232: =IF(D232<=137.5,IF(J232<=27.5,IF(I232<=0.4945,0,0),IF(D232<=107.5,0,0)),IF(D232<=155.5,IF(D232<=146.5,1,0),IF(J232<=44.5,1,1))) -> 1 | O232: =IF(D232<=133.5,IF(I232<=0.5095,IF(D232<=94.5,0,0),IF(F232<=28.5,0,1)),IF(D232<=161.5,IF(I232<=0.315,0,1),IF(C232<=6.5,1,1))) -> 1 | P232: =IF(D232<=124.5,IF(J232<=27.5,IF(F232<=30.5,0,0),IF(D232<=94.5,0,0)),IF(D232<=166.5,IF(J232<=24.5,0,1),IF(J232<=37.5,1,1))) -> 0 | Q232: =IF(H232<=28.849999,IF(C232<=5.5,IF(E232<=69,0,0),IF(H232<=24.7,0,0)),IF(C232<=4.5,IF(G232<=107.5,0,0),IF(G232<=122.5,0,1))) -> 0 | R232: =IF(D232<=154.5,IF(H232<=27.849999,IF(D232<=107.5,0,0),IF(I232<=1.105,0,1)),IF(I232<=0.2745,1,IF(G232<=171.5,1,1))) -> 0 | S232: =IF(D232<=133.5,IF(J232<=27.5,IF(H232<=31.3,0,0),IF(H232<=28.65,0,0)),IF(H232<=29.4,0,IF(D232<=155.5,1,1))) -> 1 | T232: =IF(D232<=151.5,IF(D232<=99.5,IF(J232<=36.5,0,0),IF(I232<=0.317,0,0)),IF(F232<=38.5,IF(J232<=44.5,1,1),1)) -> 0 | U232: =IF(H232<=29.650001,IF(C232<=8.5,IF(H232<=26.5,0,0),0),IF(C232<=6.5,IF(H232<=43,0,1),IF(I232<=0.208,0,1))) -> 1 | V232: =IF(H232<=29.849999,IF(C232<=4.5,IF(H232<=25.45,0,0),IF(I232<=0.261,0,0)),IF(G232<=179,IF(C232<=4.5,0,1),IF(H232<=35.049999,1,1))) -> 0 | W232: =IF(D232<=127.5,IF(C232<=5.5,IF(E232<=79,0,0),IF(I232<=0.2205,0,0)),IF(I232<=0.3165,IF(I232<=0.242,1,0),IF(D232<=143.5,1,1))) -> 1 | X232: =COUNTIF(L232:W232,0) -> 6 | Y232: =COUNTIF(L232:W232,1) -> 6 | Z232: =IF(X232>Y232,0,1) -> 1 | AA232: =IF(Z232=K232,1,0) -> 1 | AC232: 20 | AD232: =VLOOKUP(AC232,B:AA,26,FALSE) -> 0 | AE232: =VLOOKUP(AC232,B:AA,23,FALSE) -> 10 | AF232: =VLOOKUP(AC232,B:AA,24,FALSE) -> 2 | AG232: =AE232&"_"&AF232 -> 10_2
B233: 232 | C233: 6 | D233: 134 | E233: 80 | F233: 37 | G233: 370 | H233: 46.2 | I233: 0.238 | J233: 46 | K233: 1 | L233: =IF(J233<=42.5,IF(G233<=119.5,IF(C233<=2.5,0,0),IF(C233<=0.5,1,0)),IF(G233<=139.5,IF(J233<=55.5,1,0),1)) -> 1 | M233: =IF(J233<=30.5,IF(H233<=36.25,IF(J233<=26.5,0,0),IF(H233<=42.75,0,1)),IF(H233<=27.45,IF(H233<=24.8,0,0),IF(J233<=42.5,1,1))) -> 1 | N233: =IF(D233<=137.5,IF(J233<=27.5,IF(I233<=0.4945,0,0),IF(D233<=107.5,0,0)),IF(D233<=155.5,IF(D233<=146.5,1,0),IF(J233<=44.5,1,1))) -> 0 | O233: =IF(D233<=133.5,IF(I233<=0.5095,IF(D233<=94.5,0,0),IF(F233<=28.5,0,1)),IF(D233<=161.5,IF(I233<=0.315,0,1),IF(C233<=6.5,1,1))) -> 0 | P233: =IF(D233<=124.5,IF(J233<=27.5,IF(F233<=30.5,0,0),IF(D233<=94.5,0,0)),IF(D233<=166.5,IF(J233<=24.5,0,1),IF(J233<=37.5,1,1))) -> 1 | Q233: =IF(H233<=28.849999,IF(C233<=5.5,IF(E233<=69,0,0),IF(H233<=24.7,0,0)),IF(C233<=4.5,IF(G233<=107.5,0,0),IF(G233<=122.5,0,1))) -> 1 | R233: =IF(D233<=154.5,IF(H233<=27.849999,IF(D233<=107.5,0,0),IF(I233<=1.105,0,1)),IF(I233<=0.2745,1,IF(G233<=171.5,1,1))) -> 0 | S233: =IF(D233<=133.5,IF(J233<=27.5,IF(H233<=31.3,0,0),IF(H233<=28.65,0,0)),IF(H233<=29.4,0,IF(D233<=155.5,1,1))) -> 1 | T233: =IF(D233<=151.5,IF(D233<=99.5,IF(J233<=36.5,0,0),IF(I233<=0.317,0,0)),IF(F233<=38.5,IF(J233<=44.5,1,1),1)) -> 0 | U233: =IF(H233<=29.650001,IF(C233<=8.5,IF(H233<=26.5,0,0),0),IF(C233<=6.5,IF(H233<=43,0,1),IF(I233<=0.208,0,1))) -> 1 | V233: =IF(H233<=29.849999,IF(C233<=4.5,IF(H233<=25.45,0,0),IF(I233<=0.261,0,0)),IF(G233<=179,IF(C233<=4.5,0,1),IF(H233<=35.049999,1,1))) -> 1 | W233: =IF(D233<=127.5,IF(C233<=5.5,IF(E233<=79,0,0),IF(I233<=0.2205,0,0)),IF(I233<=0.3165,IF(I233<=0.242,1,0),IF(D233<=143.5,1,1))) -> 1 | X233: =COUNTIF(L233:W233,0) -> 4 | Y233: =COUNTIF(L233:W233,1) -> 8 | Z233: =IF(X233>Y233,0,1) -> 1 | AA233: =IF(Z233=K233,1,0) -> 1
B234: 233 | C234: 1 | D234: 79 | E234: 80 | F234: 25 | G234: 37 | H234: 25.4 | I234: 0.583 | J234: 22 | K234: 0 | L234: =IF(J234<=42.5,IF(G234<=119.5,IF(C234<=2.5,0,0),IF(C234<=0.5,1,0)),IF(G234<=139.5,IF(J234<=55.5,1,0),1)) -> 0 | M234: =IF(J234<=30.5,IF(H234<=36.25,IF(J234<=26.5,0,0),IF(H234<=42.75,0,1)),IF(H234<=27.45,IF(H234<=24.8,0,0),IF(J234<=42.5,1,1))) -> 0 | N234: =IF(D234<=137.5,IF(J234<=27.5,IF(I234<=0.4945,0,0),IF(D234<=107.5,0,0)),IF(D234<=155.5,IF(D234<=146.5,1,0),IF(J234<=44.5,1,1))) -> 0 | O234: =IF(D234<=133.5,IF(I234<=0.5095,IF(D234<=94.5,0,0),IF(F234<=28.5,0,1)),IF(D234<=161.5,IF(I234<=0.315,0,1),IF(C234<=6.5,1,1))) -> 0 | P234: =IF(D234<=124.5,IF(J234<=27.5,IF(F234<=30.5,0,0),IF(D234<=94.5,0,0)),IF(D234<=166.5,IF(J234<=24.5,0,1),IF(J234<=37.5,1,1))) -> 0 | Q234: =IF(H234<=28.849999,IF(C234<=5.5,IF(E234<=69,0,0),IF(H234<=24.7,0,0)),IF(C234<=4.5,IF(G234<=107.5,0,0),IF(G234<=122.5,0,1))) -> 0 | R234: =IF(D234<=154.5,IF(H234<=27.849999,IF(D234<=107.5,0,0),IF(I234<=1.105,0,1)),IF(I234<=0.2745,1,IF(G234<=171.5,1,1))) -> 0 | S234: =IF(D234<=133.5,IF(J234<=27.5,IF(H234<=31.3,0,0),IF(H234<=28.65,0,0)),IF(H234<=29.4,0,IF(D234<=155.5,1,1))) -> 0 | T234: =IF(D234<=151.5,IF(D234<=99.5,IF(J234<=36.5,0,0),IF(I234<=0.317,0,0)),IF(F234<=38.5,IF(J234<=44.5,1,1),1)) -> 0 | U234: =IF(H234<=29.650001,IF(C234<=8.5,IF(H234<=26.5,0,0),0),IF(C234<=6.5,IF(H234<=43,0,1),IF(I234<=0.208,0,1))) -> 0 | V234: =IF(H234<=29.849999,IF(C234<=4.5,IF(H234<=25.45,0,0),IF(I234<=0.261,0,0)),IF(G234<=179,IF(C234<=4.5,0,1),IF(H234<=35.049999,1,1))) -> 0 | W234: =IF(D234<=127.5,IF(C234<=5.5,IF(E234<=79,0,0),IF(I234<=0.2205,0,0)),IF(I234<=0.3165,IF(I234<=0.242,1,0),IF(D234<=143.5,1,1))) -> 0 | X234: =COUNTIF(L234:W234,0) -> 12 | Y234: =COUNTIF(L234:W234,1) -> 0 | Z234: =IF(X234>Y234,0,1) -> 0 | AA234: =IF(Z234=K234,1,0) -> 1
B235: 234 | C235: 4 | D235: 122 | E235: 68 | F235: 0 | G235: 0 | H235: 35 | I235: 0.394 | J235: 29 | K235: 0 | L235: =IF(J235<=42.5,IF(G235<=119.5,IF(C235<=2.5,0,0),IF(C235<=0.5,1,0)),IF(G235<=139.5,IF(J235<=55.5,1,0),1)) -> 0 | M235: =IF(J235<=30.5,IF(H235<=36.25,IF(J235<=26.5,0,0),IF(H235<=42.75,0,1)),IF(H235<=27.45,IF(H235<=24.8,0,0),IF(J235<=42.5,1,1))) -> 0 | N235: =IF(D235<=137.5,IF(J235<=27.5,IF(I235<=0.4945,0,0),IF(D235<=107.5,0,0)),IF(D235<=155.5,IF(D235<=146.5,1,0),IF(J235<=44.5,1,1))) -> 0 | O235: =IF(D235<=133.5,IF(I235<=0.5095,IF(D235<=94.5,0,0),IF(F235<=28.5,0,1)),IF(D235<=161.5,IF(I235<=0.315,0,1),IF(C235<=6.5,1,1))) -> 0 | P235: =IF(D235<=124.5,IF(J235<=27.5,IF(F235<=30.5,0,0),IF(D235<=94.5,0,0)),IF(D235<=166.5,IF(J235<=24.5,0,1),IF(J235<=37.5,1,1))) -> 0 | Q235: =IF(H235<=28.849999,IF(C235<=5.5,IF(E235<=69,0,0),IF(H235<=24.7,0,0)),IF(C235<=4.5,IF(G235<=107.5,0,0),IF(G235<=122.5,0,1))) -> 0 | R235: =IF(D235<=154.5,IF(H235<=27.849999,IF(D235<=107.5,0,0),IF(I235<=1.105,0,1)),IF(I235<=0.2745,1,IF(G235<=171.5,1,1))) -> 0 | S235: =IF(D235<=133.5,IF(J235<=27.5,IF(H235<=31.3,0,0),IF(H235<=28.65,0,0)),IF(H235<=29.4,0,IF(D235<=155.5,1,1))) -> 0 | T235: =IF(D235<=151.5,IF(D235<=99.5,IF(J235<=36.5,0,0),IF(I235<=0.317,0,0)),IF(F235<=38.5,IF(J235<=44.5,1,1),1)) -> 0 | U235: =IF(H235<=29.650001,IF(C235<=8.5,IF(H235<=26.5,0,0),0),IF(C235<=6.5,IF(H235<=43,0,1),IF(I235<=0.208,0,1))) -> 0 | V235: =IF(H235<=29.849999,IF(C235<=4.5,IF(H235<=25.45,0,0),IF(I235<=0.261,0,0)),IF(G235<=179,IF(C235<=4.5,0,1),IF(H235<=35.049999,1,1))) -> 0 | W235: =IF(D235<=127.5,IF(C235<=5.5,IF(E235<=79,0,0),IF(I235<=0.2205,0,0)),IF(I235<=0.3165,IF(I235<=0.242,1,0),IF(D235<=143.5,1,1))) -> 0 | X235: =COUNTIF(L235:W235,0) -> 12 | Y235: =COUNTIF(L235:W235,1) -> 0 | Z235: =IF(X235>Y235,0,1) -> 0 | AA235: =IF(Z235=K235,1,0) -> 1
B236: 235 | C236: 3 | D236: 74 | E236: 68 | F236: 28 | G236: 45 | H236: 29.7 | I236: 0.293 | J236: 23 | K236: 0 | L236: =IF(J236<=42.5,IF(G236<=119.5,IF(C236<=2.5,0,0),IF(C236<=0.5,1,0)),IF(G236<=139.5,IF(J236<=55.5,1,0),1)) -> 0 | M236: =IF(J236<=30.5,IF(H236<=36.25,IF(J236<=26.5,0,0),IF(H236<=42.75,0,1)),IF(H236<=27.45,IF(H236<=24.8,0,0),IF(J236<=42.5,1,1))) -> 0 | N236: =IF(D236<=137.5,IF(J236<=27.5,IF(I236<=0.4945,0,0),IF(D236<=107.5,0,0)),IF(D236<=155.5,IF(D236<=146.5,1,0),IF(J236<=44.5,1,1))) -> 0 | O236: =IF(D236<=133.5,IF(I236<=0.5095,IF(D236<=94.5,0,0),IF(F236<=28.5,0,1)),IF(D236<=161.5,IF(I236<=0.315,0,1),IF(C236<=6.5,1,1))) -> 0 | P236: =IF(D236<=124.5,IF(J236<=27.5,IF(F236<=30.5,0,0),IF(D236<=94.5,0,0)),IF(D236<=166.5,IF(J236<=24.5,0,1),IF(J236<=37.5,1,1))) -> 0 | Q236: =IF(H236<=28.849999,IF(C236<=5.5,IF(E236<=69,0,0),IF(H236<=24.7,0,0)),IF(C236<=4.5,IF(G236<=107.5,0,0),IF(G236<=122.5,0,1))) -> 0 | R236: =IF(D236<=154.5,IF(H236<=27.849999,IF(D236<=107.5,0,0),IF(I236<=1.105,0,1)),IF(I236<=0.2745,1,IF(G236<=171.5,1,1))) -> 0 | S236: =IF(D236<=133.5,IF(J236<=27.5,IF(H236<=31.3,0,0),IF(H236<=28.65,0,0)),IF(H236<=29.4,0,IF(D236<=155.5,1,1))) -> 0 | T236: =IF(D236<=151.5,IF(D236<=99.5,IF(J236<=36.5,0,0),IF(I236<=0.317,0,0)),IF(F236<=38.5,IF(J236<=44.5,1,1),1)) -> 0 | U236: =IF(H236<=29.650001,IF(C236<=8.5,IF(H236<=26.5,0,0),0),IF(C236<=6.5,IF(H236<=43,0,1),IF(I236<=0.208,0,1))) -> 0 | V236: =IF(H236<=29.849999,IF(C236<=4.5,IF(H236<=25.45,0,0),IF(I236<=0.261,0,0)),IF(G236<=179,IF(C236<=4.5,0,1),IF(H236<=35.049999,1,1))) -> 0 | W236: =IF(D236<=127.5,IF(C236<=5.5,IF(E236<=79,0,0),IF(I236<=0.2205,0,0)),IF(I236<=0.3165,IF(I236<=0.242,1,0),IF(D236<=143.5,1,1))) -> 0 | X236: =COUNTIF(L236:W236,0) -> 12 | Y236: =COUNTIF(L236:W236,1) -> 0 | Z236: =IF(X236>Y236,0,1) -> 0 | AA236: =IF(Z236=K236,1,0) -> 1
B237: 236 | C237: 4 | D237: 171 | E237: 72 | F237: 0 | G237: 0 | H237: 43.6 | I237: 0.479 | J237: 26 | K237: 1 | L237: =IF(J237<=42.5,IF(G237<=119.5,IF(C237<=2.5,0,0),IF(C237<=0.5,1,0)),IF(G237<=139.5,IF(J237<=55.5,1,0),1)) -> 0 | M237: =IF(J237<=30.5,IF(H237<=36.25,IF(J237<=26.5,0,0),IF(H237<=42.75,0,1)),IF(H237<=27.45,IF(H237<=24.8,0,0),IF(J237<=42.5,1,1))) -> 1 | N237: =IF(D237<=137.5,IF(J237<=27.5,IF(I237<=0.4945,0,0),IF(D237<=107.5,0,0)),IF(D237<=155.5,IF(D237<=146.5,1,0),IF(J237<=44.5,1,1))) -> 1 | O237: =IF(D237<=133.5,IF(I237<=0.5095,IF(D237<=94.5,0,0),IF(F237<=28.5,0,1)),IF(D237<=161.5,IF(I237<=0.315,0,1),IF(C237<=6.5,1,1))) -> 1 | P237: =IF(D237<=124.5,IF(J237<=27.5,IF(F237<=30.5,0,0),IF(D237<=94.5,0,0)),IF(D237<=166.5,IF(J237<=24.5,0,1),IF(J237<=37.5,1,1))) -> 1 | Q237: =IF(H237<=28.849999,IF(C237<=5.5,IF(E237<=69,0,0),IF(H237<=24.7,0,0)),IF(C237<=4.5,IF(G237<=107.5,0,0),IF(G237<=122.5,0,1))) -> 0 | R237: =IF(D237<=154.5,IF(H237<=27.849999,IF(D237<=107.5,0,0),IF(I237<=1.105,0,1)),IF(I237<=0.2745,1,IF(G237<=171.5,1,1))) -> 1 | S237: =IF(D237<=133.5,IF(J237<=27.5,IF(H237<=31.3,0,0),IF(H237<=28.65,0,0)),IF(H237<=29.4,0,IF(D237<=155.5,1,1))) -> 1 | T237: =IF(D237<=151.5,IF(D237<=99.5,IF(J237<=36.5,0,0),IF(I237<=0.317,0,0)),IF(F237<=38.5,IF(J237<=44.5,1,1),1)) -> 1 | U237: =IF(H237<=29.650001,IF(C237<=8.5,IF(H237<=26.5,0,0),0),IF(C237<=6.5,IF(H237<=43,0,1),IF(I237<=0.208,0,1))) -> 1 | V237: =IF(H237<=29.849999,IF(C237<=4.5,IF(H237<=25.45,0,0),IF(I237<=0.261,0,0)),IF(G237<=179,IF(C237<=4.5,0,1),IF(H237<=35.049999,1,1))) -> 0 | W237: =IF(D237<=127.5,IF(C237<=5.5,IF(E237<=79,0,0),IF(I237<=0.2205,0,0)),IF(I237<=0.3165,IF(I237<=0.242,1,0),IF(D237<=143.5,1,1))) -> 1 | X237: =COUNTIF(L237:W237,0) -> 3 | Y237: =COUNTIF(L237:W237,1) -> 9 | Z237: =IF(X237>Y237,0,1) -> 1 | AA237: =IF(Z237=K237,1,0) -> 1
B238: 237 | C238: 7 | D238: 181 | E238: 84 | F238: 21 | G238: 192 | H238: 35.9 | I238: 0.586 | J238: 51 | K238: 1 | L238: =IF(J238<=42.5,IF(G238<=119.5,IF(C238<=2.5,0,0),IF(C238<=0.5,1,0)),IF(G238<=139.5,IF(J238<=55.5,1,0),1)) -> 1 | M238: =IF(J238<=30.5,IF(H238<=36.25,IF(J238<=26.5,0,0),IF(H238<=42.75,0,1)),IF(H238<=27.45,IF(H238<=24.8,0,0),IF(J238<=42.5,1,1))) -> 1 | N238: =IF(D238<=137.5,IF(J238<=27.5,IF(I238<=0.4945,0,0),IF(D238<=107.5,0,0)),IF(D238<=155.5,IF(D238<=146.5,1,0),IF(J238<=44.5,1,1))) -> 1 | O238: =IF(D238<=133.5,IF(I238<=0.5095,IF(D238<=94.5,0,0),IF(F238<=28.5,0,1)),IF(D238<=161.5,IF(I238<=0.315,0,1),IF(C238<=6.5,1,1))) -> 1 | P238: =IF(D238<=124.5,IF(J238<=27.5,IF(F238<=30.5,0,0),IF(D238<=94.5,0,0)),IF(D238<=166.5,IF(J238<=24.5,0,1),IF(J238<=37.5,1,1))) -> 1 | Q238: =IF(H238<=28.849999,IF(C238<=5.5,IF(E238<=69,0,0),IF(H238<=24.7,0,0)),IF(C238<=4.5,IF(G238<=107.5,0,0),IF(G238<=122.5,0,1))) -> 1 | R238: =IF(D238<=154.5,IF(H238<=27.849999,IF(D238<=107.5,0,0),IF(I238<=1.105,0,1)),IF(I238<=0.2745,1,IF(G238<=171.5,1,1))) -> 1 | S238: =IF(D238<=133.5,IF(J238<=27.5,IF(H238<=31.3,0,0),IF(H238<=28.65,0,0)),IF(H238<=29.4,0,IF(D238<=155.5,1,1))) -> 1 | T238: =IF(D238<=151.5,IF(D238<=99.5,IF(J238<=36.5,0,0),IF(I238<=0.317,0,0)),IF(F238<=38.5,IF(J238<=44.5,1,1),1)) -> 1 | U238: =IF(H238<=29.650001,IF(C238<=8.5,IF(H238<=26.5,0,0),0),IF(C238<=6.5,IF(H238<=43,0,1),IF(I238<=0.208,0,1))) -> 1 | V238: =IF(H238<=29.849999,IF(C238<=4.5,IF(H238<=25.45,0,0),IF(I238<=0.261,0,0)),IF(G238<=179,IF(C238<=4.5,0,1),IF(H238<=35.049999,1,1))) -> 1 | W238: =IF(D238<=127.5,IF(C238<=5.5,IF(E238<=79,0,0),IF(I238<=0.2205,0,0)),IF(I238<=0.3165,IF(I238<=0.242,1,0),IF(D238<=143.5,1,1))) -> 1 | X238: =COUNTIF(L238:W238,0) -> 0 | Y238: =COUNTIF(L238:W238,1) -> 12 | Z238: =IF(X238>Y238,0,1) -> 1 | AA238: =IF(Z238=K238,1,0) -> 1
B239: 238 | C239: 0 | D239: 179 | E239: 90 | F239: 27 | G239: 0 | H239: 44.1 | I239: 0.686 | J239: 23 | K239: 1 | L239: =IF(J239<=42.5,IF(G239<=119.5,IF(C239<=2.5,0,0),IF(C239<=0.5,1,0)),IF(G239<=139.5,IF(J239<=55.5,1,0),1)) -> 0 | M239: =IF(J239<=30.5,IF(H239<=36.25,IF(J239<=26.5,0,0),IF(H239<=42.75,0,1)),IF(H239<=27.45,IF(H239<=24.8,0,0),IF(J239<=42.5,1,1))) -> 1 | N239: =IF(D239<=137.5,IF(J239<=27.5,IF(I239<=0.4945,0,0),IF(D239<=107.5,0,0)),IF(D239<=155.5,IF(D239<=146.5,1,0),IF(J239<=44.5,1,1))) -> 1 | O239: =IF(D239<=133.5,IF(I239<=0.5095,IF(D239<=94.5,0,0),IF(F239<=28.5,0,1)),IF(D239<=161.5,IF(I239<=0.315,0,1),IF(C239<=6.5,1,1))) -> 1 | P239: =IF(D239<=124.5,IF(J239<=27.5,IF(F239<=30.5,0,0),IF(D239<=94.5,0,0)),IF(D239<=166.5,IF(J239<=24.5,0,1),IF(J239<=37.5,1,1))) -> 1 | Q239: =IF(H239<=28.849999,IF(C239<=5.5,IF(E239<=69,0,0),IF(H239<=24.7,0,0)),IF(C239<=4.5,IF(G239<=107.5,0,0),IF(G239<=122.5,0,1))) -> 0 | R239: =IF(D239<=154.5,IF(H239<=27.849999,IF(D239<=107.5,0,0),IF(I239<=1.105,0,1)),IF(I239<=0.2745,1,IF(G239<=171.5,1,1))) -> 1 | S239: =IF(D239<=133.5,IF(J239<=27.5,IF(H239<=31.3,0,0),IF(H239<=28.65,0,0)),IF(H239<=29.4,0,IF(D239<=155.5,1,1))) -> 1 | T239: =IF(D239<=151.5,IF(D239<=99.5,IF(J239<=36.5,0,0),IF(I239<=0.317,0,0)),IF(F239<=38.5,IF(J239<=44.5,1,1),1)) -> 1 | U239: =IF(H239<=29.650001,IF(C239<=8.5,IF(H239<=26.5,0,0),0),IF(C239<=6.5,IF(H239<=43,0,1),IF(I239<=0.208,0,1))) -> 1 | V239: =IF(H239<=29.849999,IF(C239<=4.5,IF(H239<=25.45,0,0),IF(I239<=0.261,0,0)),IF(G239<=179,IF(C239<=4.5,0,1),IF(H239<=35.049999,1,1))) -> 0 | W239: =IF(D239<=127.5,IF(C239<=5.5,IF(E239<=79,0,0),IF(I239<=0.2205,0,0)),IF(I239<=0.3165,IF(I239<=0.242,1,0),IF(D239<=143.5,1,1))) -> 1 | X239: =COUNTIF(L239:W239,0) -> 3 | Y239: =COUNTIF(L239:W239,1) -> 9 | Z239: =IF(X239>Y239,0,1) -> 1 | AA239: =IF(Z239=K239,1,0) -> 1
B240: 239 | C240: 9 | D240: 164 | E240: 84 | F240: 21 | G240: 0 | H240: 30.8 | I240: 0.831 | J240: 32 | K240: 1 | L240: =IF(J240<=42.5,IF(G240<=119.5,IF(C240<=2.5,0,0),IF(C240<=0.5,1,0)),IF(G240<=139.5,IF(J240<=55.5,1,0),1)) -> 0 | M240: =IF(J240<=30.5,IF(H240<=36.25,IF(J240<=26.5,0,0),IF(H240<=42.75,0,1)),IF(H240<=27.45,IF(H240<=24.8,0,0),IF(J240<=42.5,1,1))) -> 1 | N240: =IF(D240<=137.5,IF(J240<=27.5,IF(I240<=0.4945,0,0),IF(D240<=107.5,0,0)),IF(D240<=155.5,IF(D240<=146.5,1,0),IF(J240<=44.5,1,1))) -> 1 | O240: =IF(D240<=133.5,IF(I240<=0.5095,IF(D240<=94.5,0,0),IF(F240<=28.5,0,1)),IF(D240<=161.5,IF(I240<=0.315,0,1),IF(C240<=6.5,1,1))) -> 1 | P240: =IF(D240<=124.5,IF(J240<=27.5,IF(F240<=30.5,0,0),IF(D240<=94.5,0,0)),IF(D240<=166.5,IF(J240<=24.5,0,1),IF(J240<=37.5,1,1))) -> 1 | Q240: =IF(H240<=28.849999,IF(C240<=5.5,IF(E240<=69,0,0),IF(H240<=24.7,0,0)),IF(C240<=4.5,IF(G240<=107.5,0,0),IF(G240<=122.5,0,1))) -> 0 | R240: =IF(D240<=154.5,IF(H240<=27.849999,IF(D240<=107.5,0,0),IF(I240<=1.105,0,1)),IF(I240<=0.2745,1,IF(G240<=171.5,1,1))) -> 1 | S240: =IF(D240<=133.5,IF(J240<=27.5,IF(H240<=31.3,0,0),IF(H240<=28.65,0,0)),IF(H240<=29.4,0,IF(D240<=155.5,1,1))) -> 1 | T240: =IF(D240<=151.5,IF(D240<=99.5,IF(J240<=36.5,0,0),IF(I240<=0.317,0,0)),IF(F240<=38.5,IF(J240<=44.5,1,1),1)) -> 1 | U240: =IF(H240<=29.650001,IF(C240<=8.5,IF(H240<=26.5,0,0),0),IF(C240<=6.5,IF(H240<=43,0,1),IF(I240<=0.208,0,1))) -> 1 | V240: =IF(H240<=29.849999,IF(C240<=4.5,IF(H240<=25.45,0,0),IF(I240<=0.261,0,0)),IF(G240<=179,IF(C240<=4.5,0,1),IF(H240<=35.049999,1,1))) -> 1 | W240: =IF(D240<=127.5,IF(C240<=5.5,IF(E240<=79,0,0),IF(I240<=0.2205,0,0)),IF(I240<=0.3165,IF(I240<=0.242,1,0),IF(D240<=143.5,1,1))) -> 1 | X240: =COUNTIF(L240:W240,0) -> 2 | Y240: =COUNTIF(L240:W240,1) -> 10 | Z240: =IF(X240>Y240,0,1) -> 1 | AA240: =IF(Z240=K240,1,0) -> 1
B241: 240 | C241: 0 | D241: 104 | E241: 76 | F241: 0 | G241: 0 | H241: 18.4 | I241: 0.582 | J241: 27 | K241: 0 | L241: =IF(J241<=42.5,IF(G241<=119.5,IF(C241<=2.5,0,0),IF(C241<=0.5,1,0)),IF(G241<=139.5,IF(J241<=55.5,1,0),1)) -> 0 | M241: =IF(J241<=30.5,IF(H241<=36.25,IF(J241<=26.5,0,0),IF(H241<=42.75,0,1)),IF(H241<=27.45,IF(H241<=24.8,0,0),IF(J241<=42.5,1,1))) -> 0 | N241: =IF(D241<=137.5,IF(J241<=27.5,IF(I241<=0.4945,0,0),IF(D241<=107.5,0,0)),IF(D241<=155.5,IF(D241<=146.5,1,0),IF(J241<=44.5,1,1))) -> 0 | O241: =IF(D241<=133.5,IF(I241<=0.5095,IF(D241<=94.5,0,0),IF(F241<=28.5,0,1)),IF(D241<=161.5,IF(I241<=0.315,0,1),IF(C241<=6.5,1,1))) -> 0 | P241: =IF(D241<=124.5,IF(J241<=27.5,IF(F241<=30.5,0,0),IF(D241<=94.5,0,0)),IF(D241<=166.5,IF(J241<=24.5,0,1),IF(J241<=37.5,1,1))) -> 0 | Q241: =IF(H241<=28.849999,IF(C241<=5.5,IF(E241<=69,0,0),IF(H241<=24.7,0,0)),IF(C241<=4.5,IF(G241<=107.5,0,0),IF(G241<=122.5,0,1))) -> 0 | R241: =IF(D241<=154.5,IF(H241<=27.849999,IF(D241<=107.5,0,0),IF(I241<=1.105,0,1)),IF(I241<=0.2745,1,IF(G241<=171.5,1,1))) -> 0 | S241: =IF(D241<=133.5,IF(J241<=27.5,IF(H241<=31.3,0,0),IF(H241<=28.65,0,0)),IF(H241<=29.4,0,IF(D241<=155.5,1,1))) -> 0 | T241: =IF(D241<=151.5,IF(D241<=99.5,IF(J241<=36.5,0,0),IF(I241<=0.317,0,0)),IF(F241<=38.5,IF(J241<=44.5,1,1),1)) -> 0 | U241: =IF(H241<=29.650001,IF(C241<=8.5,IF(H241<=26.5,0,0),0),IF(C241<=6.5,IF(H241<=43,0,1),IF(I241<=0.208,0,1))) -> 0 | V241: =IF(H241<=29.849999,IF(C241<=4.5,IF(H241<=25.45,0,0),IF(I241<=0.261,0,0)),IF(G241<=179,IF(C241<=4.5,0,1),IF(H241<=35.049999,1,1))) -> 0 | W241: =IF(D241<=127.5,IF(C241<=5.5,IF(E241<=79,0,0),IF(I241<=0.2205,0,0)),IF(I241<=0.3165,IF(I241<=0.242,1,0),IF(D241<=143.5,1,1))) -> 0 | X241: =COUNTIF(L241:W241,0) -> 12 | Y241: =COUNTIF(L241:W241,1) -> 0 | Z241: =IF(X241>Y241,0,1) -> 0 | AA241: =IF(Z241=K241,1,0) -> 1
B242: 241 | C242: 1 | D242: 91 | E242: 64 | F242: 24 | G242: 0 | H242: 29.2 | I242: 0.192 | J242: 21 | K242: 0 | L242: =IF(J242<=42.5,IF(G242<=119.5,IF(C242<=2.5,0,0),IF(C242<=0.5,1,0)),IF(G242<=139.5,IF(J242<=55.5,1,0),1)) -> 0 | M242: =IF(J242<=30.5,IF(H242<=36.25,IF(J242<=26.5,0,0),IF(H242<=42.75,0,1)),IF(H242<=27.45,IF(H242<=24.8,0,0),IF(J242<=42.5,1,1))) -> 0 | N242: =IF(D242<=137.5,IF(J242<=27.5,IF(I242<=0.4945,0,0),IF(D242<=107.5,0,0)),IF(D242<=155.5,IF(D242<=146.5,1,0),IF(J242<=44.5,1,1))) -> 0 | O242: =IF(D242<=133.5,IF(I242<=0.5095,IF(D242<=94.5,0,0),IF(F242<=28.5,0,1)),IF(D242<=161.5,IF(I242<=0.315,0,1),IF(C242<=6.5,1,1))) -> 0 | P242: =IF(D242<=124.5,IF(J242<=27.5,IF(F242<=30.5,0,0),IF(D242<=94.5,0,0)),IF(D242<=166.5,IF(J242<=24.5,0,1),IF(J242<=37.5,1,1))) -> 0 | Q242: =IF(H242<=28.849999,IF(C242<=5.5,IF(E242<=69,0,0),IF(H242<=24.7,0,0)),IF(C242<=4.5,IF(G242<=107.5,0,0),IF(G242<=122.5,0,1))) -> 0 | R242: =IF(D242<=154.5,IF(H242<=27.849999,IF(D242<=107.5,0,0),IF(I242<=1.105,0,1)),IF(I242<=0.2745,1,IF(G242<=171.5,1,1))) -> 0 | S242: =IF(D242<=133.5,IF(J242<=27.5,IF(H242<=31.3,0,0),IF(H242<=28.65,0,0)),IF(H242<=29.4,0,IF(D242<=155.5,1,1))) -> 0 | T242: =IF(D242<=151.5,IF(D242<=99.5,IF(J242<=36.5,0,0),IF(I242<=0.317,0,0)),IF(F242<=38.5,IF(J242<=44.5,1,1),1)) -> 0 | U242: =IF(H242<=29.650001,IF(C242<=8.5,IF(H242<=26.5,0,0),0),IF(C242<=6.5,IF(H242<=43,0,1),IF(I242<=0.208,0,1))) -> 0 | V242: =IF(H242<=29.849999,IF(C242<=4.5,IF(H242<=25.45,0,0),IF(I242<=0.261,0,0)),IF(G242<=179,IF(C242<=4.5,0,1),IF(H242<=35.049999,1,1))) -> 0 | W242: =IF(D242<=127.5,IF(C242<=5.5,IF(E242<=79,0,0),IF(I242<=0.2205,0,0)),IF(I242<=0.3165,IF(I242<=0.242,1,0),IF(D242<=143.5,1,1))) -> 0 | X242: =COUNTIF(L242:W242,0) -> 12 | Y242: =COUNTIF(L242:W242,1) -> 0 | Z242: =IF(X242>Y242,0,1) -> 0 | AA242: =IF(Z242=K242,1,0) -> 1
B243: 242 | C243: 4 | D243: 91 | E243: 70 | F243: 32 | G243: 88 | H243: 33.1 | I243: 0.446 | J243: 22 | K243: 0 | L243: =IF(J243<=42.5,IF(G243<=119.5,IF(C243<=2.5,0,0),IF(C243<=0.5,1,0)),IF(G243<=139.5,IF(J243<=55.5,1,0),1)) -> 0 | M243: =IF(J243<=30.5,IF(H243<=36.25,IF(J243<=26.5,0,0),IF(H243<=42.75,0,1)),IF(H243<=27.45,IF(H243<=24.8,0,0),IF(J243<=42.5,1,1))) -> 0 | N243: =IF(D243<=137.5,IF(J243<=27.5,IF(I243<=0.4945,0,0),IF(D243<=107.5,0,0)),IF(D243<=155.5,IF(D243<=146.5,1,0),IF(J243<=44.5,1,1))) -> 0 | O243: =IF(D243<=133.5,IF(I243<=0.5095,IF(D243<=94.5,0,0),IF(F243<=28.5,0,1)),IF(D243<=161.5,IF(I243<=0.315,0,1),IF(C243<=6.5,1,1))) -> 0 | P243: =IF(D243<=124.5,IF(J243<=27.5,IF(F243<=30.5,0,0),IF(D243<=94.5,0,0)),IF(D243<=166.5,IF(J243<=24.5,0,1),IF(J243<=37.5,1,1))) -> 0 | Q243: =IF(H243<=28.849999,IF(C243<=5.5,IF(E243<=69,0,0),IF(H243<=24.7,0,0)),IF(C243<=4.5,IF(G243<=107.5,0,0),IF(G243<=122.5,0,1))) -> 0 | R243: =IF(D243<=154.5,IF(H243<=27.849999,IF(D243<=107.5,0,0),IF(I243<=1.105,0,1)),IF(I243<=0.2745,1,IF(G243<=171.5,1,1))) -> 0 | S243: =IF(D243<=133.5,IF(J243<=27.5,IF(H243<=31.3,0,0),IF(H243<=28.65,0,0)),IF(H243<=29.4,0,IF(D243<=155.5,1,1))) -> 0 | T243: =IF(D243<=151.5,IF(D243<=99.5,IF(J243<=36.5,0,0),IF(I243<=0.317,0,0)),IF(F243<=38.5,IF(J243<=44.5,1,1),1)) -> 0 | U243: =IF(H243<=29.650001,IF(C243<=8.5,IF(H243<=26.5,0,0),0),IF(C243<=6.5,IF(H243<=43,0,1),IF(I243<=0.208,0,1))) -> 0 | V243: =IF(H243<=29.849999,IF(C243<=4.5,IF(H243<=25.45,0,0),IF(I243<=0.261,0,0)),IF(G243<=179,IF(C243<=4.5,0,1),IF(H243<=35.049999,1,1))) -> 0 | W243: =IF(D243<=127.5,IF(C243<=5.5,IF(E243<=79,0,0),IF(I243<=0.2205,0,0)),IF(I243<=0.3165,IF(I243<=0.242,1,0),IF(D243<=143.5,1,1))) -> 0 | X243: =COUNTIF(L243:W243,0) -> 12 | Y243: =COUNTIF(L243:W243,1) -> 0 | Z243: =IF(X243>Y243,0,1) -> 0 | AA243: =IF(Z243=K243,1,0) -> 1
B244: 243 | C244: 3 | D244: 139 | E244: 54 | F244: 0 | G244: 0 | H244: 25.6 | I244: 0.402 | J244: 22 | K244: 1 | L244: =IF(J244<=42.5,IF(G244<=119.5,IF(C244<=2.5,0,0),IF(C244<=0.5,1,0)),IF(G244<=139.5,IF(J244<=55.5,1,0),1)) -> 0 | M244: =IF(J244<=30.5,IF(H244<=36.25,IF(J244<=26.5,0,0),IF(H244<=42.75,0,1)),IF(H244<=27.45,IF(H244<=24.8,0,0),IF(J244<=42.5,1,1))) -> 0 | N244: =IF(D244<=137.5,IF(J244<=27.5,IF(I244<=0.4945,0,0),IF(D244<=107.5,0,0)),IF(D244<=155.5,IF(D244<=146.5,1,0),IF(J244<=44.5,1,1))) -> 1 | O244: =IF(D244<=133.5,IF(I244<=0.5095,IF(D244<=94.5,0,0),IF(F244<=28.5,0,1)),IF(D244<=161.5,IF(I244<=0.315,0,1),IF(C244<=6.5,1,1))) -> 1 | P244: =IF(D244<=124.5,IF(J244<=27.5,IF(F244<=30.5,0,0),IF(D244<=94.5,0,0)),IF(D244<=166.5,IF(J244<=24.5,0,1),IF(J244<=37.5,1,1))) -> 0 | Q244: =IF(H244<=28.849999,IF(C244<=5.5,IF(E244<=69,0,0),IF(H244<=24.7,0,0)),IF(C244<=4.5,IF(G244<=107.5,0,0),IF(G244<=122.5,0,1))) -> 0 | R244: =IF(D244<=154.5,IF(H244<=27.849999,IF(D244<=107.5,0,0),IF(I244<=1.105,0,1)),IF(I244<=0.2745,1,IF(G244<=171.5,1,1))) -> 0 | S244: =IF(D244<=133.5,IF(J244<=27.5,IF(H244<=31.3,0,0),IF(H244<=28.65,0,0)),IF(H244<=29.4,0,IF(D244<=155.5,1,1))) -> 0 | T244: =IF(D244<=151.5,IF(D244<=99.5,IF(J244<=36.5,0,0),IF(I244<=0.317,0,0)),IF(F244<=38.5,IF(J244<=44.5,1,1),1)) -> 0 | U244: =IF(H244<=29.650001,IF(C244<=8.5,IF(H244<=26.5,0,0),0),IF(C244<=6.5,IF(H244<=43,0,1),IF(I244<=0.208,0,1))) -> 0 | V244: =IF(H244<=29.849999,IF(C244<=4.5,IF(H244<=25.45,0,0),IF(I244<=0.261,0,0)),IF(G244<=179,IF(C244<=4.5,0,1),IF(H244<=35.049999,1,1))) -> 0 | W244: =IF(D244<=127.5,IF(C244<=5.5,IF(E244<=79,0,0),IF(I244<=0.2205,0,0)),IF(I244<=0.3165,IF(I244<=0.242,1,0),IF(D244<=143.5,1,1))) -> 1 | X244: =COUNTIF(L244:W244,0) -> 9 | Y244: =COUNTIF(L244:W244,1) -> 3 | Z244: =IF(X244>Y244,0,1) -> 0 | AA244: =IF(Z244=K244,1,0) -> 0
... B769: 768 | C769: 1 | D769: 93 | E769: 70 | F769: 31 | G769: 0 | H769: 30.4 | I769: 0.315 | J769: 23 | K769: 0 | L769: =IF(J769<=42.5,IF(G769<=119.5,IF(C769<=2.5,0,0),IF(C769<=0.5,1,0)),IF(G769<=139.5,IF(J769<=55.5,1,0),1)) -> 0 | M769: =IF(J769<=30.5,IF(H769<=36.25,IF(J769<=26.5,0,0),IF(H769<=42.75,0,1)),IF(H769<=27.45,IF(H769<=24.8,0,0),IF(J769<=42.5,1,1))) -> 0 | N769: =IF(D769<=137.5,IF(J769<=27.5,IF(I769<=0.4945,0,0),IF(D769<=107.5,0,0)),IF(D769<=155.5,IF(D769<=146.5,1,0),IF(J769<=44.5,1,1))) -> 0 | O769: =IF(D769<=133.5,IF(I769<=0.5095,IF(D769<=94.5,0,0),IF(F769<=28.5,0,1)),IF(D769<=161.5,IF(I769<=0.315,0,1),IF(C769<=6.5,1,1))) -> 0 | P769: =IF(D769<=124.5,IF(J769<=27.5,IF(F769<=30.5,0,0),IF(D769<=94.5,0,0)),IF(D769<=166.5,IF(J769<=24.5,0,1),IF(J769<=37.5,1,1))) -> 0 | Q769: =IF(H769<=28.849999,IF(C769<=5.5,IF(E769<=69,0,0),IF(H769<=24.7,0,0)),IF(C769<=4.5,IF(G769<=107.5,0,0),IF(G769<=122.5,0,1))) -> 0 | R769: =IF(D769<=154.5,IF(H769<=27.849999,IF(D769<=107.5,0,0),IF(I769<=1.105,0,1)),IF(I769<=0.2745,1,IF(G769<=171.5,1,1))) -> 0 | S769: =IF(D769<=133.5,IF(J769<=27.5,IF(H769<=31.3,0,0),IF(H769<=28.65,0,0)),IF(H769<=29.4,0,IF(D769<=155.5,1,1))) -> 0 | T769: =IF(D769<=151.5,IF(D769<=99.5,IF(J769<=36.5,0,0),IF(I769<=0.317,0,0)),IF(F769<=38.5,IF(J769<=44.5,1,1),1)) -> 0 | U769: =IF(H769<=29.650001,IF(C769<=8.5,IF(H769<=26.5,0,0),0),IF(C769<=6.5,IF(H769<=43,0,1),IF(I769<=0.208,0,1))) -> 0 | V769: =IF(H769<=29.849999,IF(C769<=4.5,IF(H769<=25.45,0,0),IF(I769<=0.261,0,0)),IF(G769<=179,IF(C769<=4.5,0,1),IF(H769<=35.049999,1,1))) -> 0 | W769: =IF(D769<=127.5,IF(C769<=5.5,IF(E769<=79,0,0),IF(I769<=0.2205,0,0)),IF(I769<=0.3165,IF(I769<=0.242,1,0),IF(D769<=143.5,1,1))) -> 0 | X769: =COUNTIF(L769:W769,0) -> 12 | Y769: =COUNTIF(L769:W769,1) -> 0 | Z769: =IF(X769>Y769,0,1) -> 0 | AA769: =IF(Z769=K769,1,0) -> 1

Sheet RandomForest_Validation
J1: Random Forest Feature Importance (Gini-based)
A2: Random Forest Validation – Test Set Only | C2: Source: 'RandomForest Final' (test rows identified by Test RowID in column AC) | J2: Tree | K2: Count how many " AND " appear in the Split text | L2: Replace the last " AND " with a marker | M2: Extract only the last condition (tail) | N2: Get the split variable name for this node | O2: Gain | Q2: Feature | R2: Total Gain | S2: Normalized Importance | T2: #Nodes Used
A3: Core test-set counts and accuracy | J3: =RIGHT(LEFT(_xlfn.FORMULATEXT(K3),8),7) -> Tree_01 | K3: =Tree_01!AK9 -> 0 | L3: =Tree_01!AL9 -> age ≤ 42.5 | M3: =Tree_01!AM9 -> age ≤ 42.5 | N3: =Tree_01!AN9 -> age | O3: =Tree_01!AO9 -> 0.03329035 | Q3: preg | R3: =SUMIF($N:$N, Q3, $O:$O) -> 0.77089779 | S3: =R3 / SUM($R$3:$R$10) -> 0.083347479 | T3: =COUNTIF($N:$N, Q3) -> 2 | W3: Variable Usage Across 12 Decision Trees | AS3: Voting Stability | BA3: Tree_01 | BB3: =BA3&"!"&"L2" -> Tree_01!L2 | BC3: {=_xlfn.FORMULATEXT(INDIRECT(BB3))} -> =IF(J2<=42.5,IF(G2<=119.5,IF(C2<=2.5,0,0),IF(C2<=0.5,1,0)),IF(G2<=139.5,IF(J2<=55.5,1,0),1))
A4: Total test observations | B4: =COUNTA('RandomForest Final'!$AC$2:$AC$769) -> 231 | J4: =RIGHT(LEFT(_xlfn.FORMULATEXT(K4),8),7) -> Tree_01 | K4: =Tree_01!AK10 -> 1 | L4: =Tree_01!AL10 -> age ≤ 42.5|insu ≤ 119.5 | M4: =Tree_01!AM10 -> insu ≤ 119.5 | N4: =Tree_01!AN10 -> insu | O4: =Tree_01!AO10 -> 0.13523956 | Q4: plas | R4: =SUMIF($N:$N, Q4, $O:$O) -> 2.6903427 | S4: =R4 / SUM($R$3:$R$10) -> 0.2908729 | T4: =COUNTIF($N:$N, Q4) -> 18 | W4: Tree | X4: Feature 1 | Y4: Feature 2 | Z4: Feature 3 | AA4: Feature 4 | AB4: Total Features | AC4: Accuracry | BA4: Tree_02 | BB4: =BA4&"!"&"L2" -> Tree_02!L2 | BC4: {=_xlfn.FORMULATEXT(INDIRECT(BB4))} -> =IF(J2<=30.5,IF(H2<=36.25,IF(J2<=26.5,0,0),IF(H2<=42.75,0,1)),IF(H2<=27.45,IF(H2<=24.8,0,0),IF(J2<=42.5,1,1)))
A5: Correct predictions (test only) | B5: {=SUMPRODUCT( 'RandomForest Final'!$AA$2:$AA$769, --(COUNTIF('RandomForest Final'!$AC$2:$AC$769,'RandomForest Final'!$B$2:$B$769)>0))} -> 175 | J5: =RIGHT(LEFT(_xlfn.FORMULATEXT(K5),8),7) -> Tree_01 | K5: =Tree_01!AK11 -> 2 | L5: =Tree_01!AL11 -> age ≤ 42.5 AND insu > 119.5|preg ≤ 0.5 | M5: =Tree_01!AM11 -> preg ≤ 0.5 | N5: =Tree_01!AN11 -> preg | O5: =Tree_01!AO11 -> 0.33822043 | Q5: pres | R5: =SUMIF($N:$N, Q5, $O:$O) -> 0.39869777 | S5: =R5 / SUM($R$3:$R$10) -> 0.043106173 | T5: =COUNTIF($N:$N, Q5) -> 7 | W5: 1 | X5: age (J) | Y5: mass (H) | Z5: preg (C) | AA5: - | AB5: 3 | AC5: =SUM(Tree_01!M2:M538)/COUNT(Tree_01!M2:M538) -> 0.75418994 | AS5: 0_12 | AT5: =COUNTIF('RandomForest Final'!AG:AG,AS5) -> 1 | BA5: Tree_03 | BB5: =BA5&"!"&"L2" -> Tree_03!L2 | BC5: {=_xlfn.FORMULATEXT(INDIRECT(BB5))} -> =IF(D2<=137.5,IF(J2<=27.5,IF(I2<=0.4945,0,0),IF(D2<=107.5,0,0)),IF(D2<=155.5,IF(D2<=146.5,1,0),IF(J2<=44.5,1,1)))
A6: Accuracy (test set) | B6: =IF(B4=0,"", B5/B4) -> 0.75757576 | J6: =RIGHT(LEFT(_xlfn.FORMULATEXT(K6),8),7) -> Tree_01 | K6: =Tree_01!AK12 -> 1 | L6: =Tree_01!AL12 -> age > 42.5|insu ≤ 139.5 | M6: =Tree_01!AM12 -> insu ≤ 139.5 | N6: =Tree_01!AN12 -> insu | O6: =Tree_01!AO12 -> 0.35526566 | Q6: skin | R6: =SUMIF($N:$N, Q6, $O:$O) -> 0.75705052 | S6: =R6 / SUM($R$3:$R$10) -> 0.081850347 | T6: =COUNTIF($N:$N, Q6) -> 5 | W6: 2 | X6: age (J) | Y6: mass (H) | Z6: - | AA6: - | AB6: 2 | AC6: =SUM(Tree_02!M2:M538)/COUNT(Tree_01!M2:M538) -> 0.73184358 | AS6: 1_11 | AT6: =COUNTIF('RandomForest Final'!AG:AG,AS6) -> 4 | BA6: Tree_04 | BB6: =BA6&"!"&"L2" -> Tree_04!L2 | BC6: {=_xlfn.FORMULATEXT(INDIRECT(BB6))} -> =IF(D2<=133.5,IF(I2<=0.5095,IF(D2<=94.5,0,0),IF(F2<=28.5,0,1)),IF(D2<=161.5,IF(I2<=0.315,0,1),IF(C2<=6.5,1,1)))
