Workbook

Sheet Readme
B4: ENCODER-ONLY TRANSFORMER FOR FRAUD DETECTION
B5: Excel Implementation - Educational Resource
B7: WHAT IS THIS?
B8: This workbook contains a complete, transparent implementation of an Encoder-Only Transformer neural network for credit card fraud detection. Every calculation is visible, making this ideal for learning how transformers work without programming.
B10: ARCHITECTURE TYPE: ENCODER-ONLY
B11: This implementation uses an Encoder-Only Transformer architecture, similar to BERT (Bidirectional Encoder Representations from Transformers).
B12: What's Included (Encoder Components):
B13: Self-Attention Mechanism with Query (Q), Key (K), Value (V) matrices
B14: Attention Score Calculation: Q × K^T
B15: Softmax Normalization for attention weights
B16: Attention Output: Z = Softmax(A) × V
B17: Binary Cross-Entropy Loss Function
... B129: Distinguish encoder vs decoder architectures

Sheet Data (2)
B2: Data
B3: Transaction | C3: 1 | D3: 2 | E3: 3 | F3: 4 | G3: 5 | H3: 6 | L3: Feature | M3: Encoding
B4: Amount (USD) | C4: 8000 | D4: 100 | E4: 9500 | F4: 200 | G4: 9000 | H4: 50 | L4: Time | M4: 1 = Late Night (12 AM - 6 AM), 2 = Morning (6 AM - 12 PM), 3 = Afternoon (12 PM - 6 PM), 4 = Evening (6 PM - 12 AM)
B5: Time | C5: Late Night (1 AM) | D5: Afternoon (3 PM) | E5: Late Night (1 AM) | F5: Morning (10 AM) | G5: Late Night (1 AM) | H5: Evening (9 PM) | L5: Merchant Type | M5: 3 = High-Risk (Luxury, Jewelry), 2 = Medium-Risk (Electronics, Pharmacy), 1 = Low-Risk (Grocery, Fast Food)
B6: Merchant Type | C6: Luxury | D6: Grocery | E6: Luxury | F6: Grocery | G6: Luxury | H6: Grocery | L6: Frequency | M6: High (Many txns in short time) = 1, Low (few txns over days) = 0.2, Medium = 0.6
B7: Frequency | C7: Frequent | D7: Rare | E7: Very Frequent | F7: Rare | G7: Frequent | H7: Occasional | L7: Location | M7: USA = 0, Foreign (Russia, UK) = 1
B8: Location | C8: Foreign | D8: Domestic | E8: Foreign | F8: Domestic | G8: Foreign | H8: Domestic | L8: Device Used | M8: New Device = 1, Same Device = 0
B9: Device Used | C9: New Device | D9: Same Device | E9: New Device | F9: Same Device | G9: New Device | H9: Same Device
B10: Fraud Label | C10: 1 | D10: 0 | E10: 1 | F10: 0 | G10: 1 | H10: 0
B12: Embedding
B13: Transaction | C13: 1 | D13: 2 | E13: 3 | F13: 4 | G13: 5 | H13: 6
B14: Normalized Amount | C14: 0.84127 | D14: 0.005291 | E14: 1 | F14: 0.015873 | G14: 0.94709 | H14: 0
B15: Time Encoding | C15: 1 | D15: 3 | E15: 1 | F15: 2 | G15: 1 | H15: 4
B16: Merchant Encoding | C16: 3 | D16: 1 | E16: 3 | F16: 1 | G16: 3 | H16: 1
B17: Frequency Encoding | C17: 1 | D17: 0.1 | E17: 1 | F17: 0.2 | G17: 0.9 | H17: 0.3
B18: Location Encoding | C18: 1 | D18: 0 | E18: 1 | F18: 0 | G18: 1 | H18: 0
B19: Device Encoding | C19: 1 | D19: 0 | E19: 1 | F19: 0 | G19: 1 | H19: 0
B20: Fraud Label | C20: 1 | D20: 0 | E20: 1 | F20: 0 | G20: 1 | H20: 0
B23: Query (Q) Matrix (6×4)
B25: Feature | C25: Q1 | D25: Q2 | E25: Q3 | F25: Q4
B26: Amount | C26: 0.24835708 | D26: -0.06913215 | E26: 0.32384427 | F26: 0.76151493
B27: Time | C27: -0.11707669 | D27: -0.11706848 | E27: 0.78960641 | F27: 0.38371736
B28: Merchant | C28: -0.23473719 | D28: 0.27128002 | E28: -0.23170885 | F28: -0.23286488
B29: Frequency | C29: 0.12098114 | D29: -0.95664012 | E29: -0.86245892 | F29: -0.28114376
B30: Location | C30: -0.50641556 | D30: 0.15712367 | E30: -0.45401204 | F30: -0.70615185
B31: Device Used | C31: 0.73282438 | D31: -0.11288815 | E31: 0.0337641 | F31: -0.71237409
B33: Key (K) Matrix (6×4)
B35: Feature | C35: K1 | D35: K2 | E35: K3 | F35: K4
B36: Amount | C36: -0.27219136 | D36: 0.05546129 | E36: -0.57549679 | F36: 0.18784901
B37: Time | C37: -0.30031934 | D37: -0.14584687 | E37: -0.30085331 | F37: 0.92613909
B38: Merchant | C38: -0.00674861 | D38: -0.52885546 | E38: 0.41127246 | F38: -0.61042182
B39: Frequency | C39: 0.1044318 | D39: -0.97983506 | E39: -0.66409302 | F39: 0.09843062
B40: Location | C40: 0.36923329 | D40: 0.08568414 | E40: -0.05782414 | F40: -0.15055185
B41: Device Used | C41: -0.739261 | D41: -0.3599221 | E41: -0.23031939 | F41: 0.52856111
B43: Value (V) Matrix (6×4)
B45: Feature | C45: V1 | D45: V2 | E45: V3 | F45: V4
B46: Amount | C46: 0.17180914 | D46: -0.88152008 | E46: 0.16204198 | F46: -0.19254114
B47: Time | C47: -0.338461 | D47: 0.30583814 | E47: 0.51549976 | F47: 0.46564006
B48: Merchant | C48: -0.41960876 | D48: -0.15460619 | E48: 0.16563172 | F48: 0.48777256
B49: Frequency | C49: -0.23958712 | D49: -0.09282949 | E49: -0.55316749 | F49: -0.59810331
...

Sheet Data
B2: Data
B3: Transaction | C3: 1 | D3: 2 | E3: 3 | F3: 4 | G3: 5 | H3: 6 | L3: Feature | M3: Encoding
B4: Amount (USD) | C4: 8000 | D4: 100 | E4: 9500 | F4: 200 | G4: 9000 | H4: 50 | L4: Time | M4: 1 = Late Night (12 AM - 6 AM), 2 = Morning (6 AM - 12 PM), 3 = Afternoon (12 PM - 6 PM), 4 = Evening (6 PM - 12 AM)
B5: Time | C5: Late Night (1 AM) | D5: Afternoon (3 PM) | E5: Late Night (1 AM) | F5: Morning (10 AM) | G5: Late Night (1 AM) | H5: Evening (9 PM) | L5: Merchant Type | M5: 3 = High-Risk (Luxury, Jewelry), 2 = Medium-Risk (Electronics, Pharmacy), 1 = Low-Risk (Grocery, Fast Food)
B6: Merchant Type | C6: Luxury | D6: Grocery | E6: Luxury | F6: Grocery | G6: Luxury | H6: Grocery | L6: Frequency | M6: High (Many txns in short time) = 1, Low (few txns over days) = 0.2, Medium = 0.6
B7: Frequency | C7: Rare | D7: Frequent | E7: Rare | F7: Frequent | G7: Rare | H7: Occasional | L7: Location | M7: USA = 0, Foreign (Russia, UK) = 1
B8: Location | C8: Foreign | D8: Domestic | E8: Foreign | F8: Domestic | G8: Foreign | H8: Domestic | L8: Device Used | M8: New Device = 1, Same Device = 0
B9: Device Used | C9: New Device | D9: Same Device | E9: New Device | F9: Same Device | G9: New Device | H9: Same Device
B10: Fraud Label | C10: 1 | D10: 0 | E10: 1 | F10: 0 | G10: 1 | H10: 0
B12: Embedding
B13: Transaction | C13: 1 | D13: 2 | E13: 3 | F13: 4 | G13: 5 | H13: 6
B14: Normalized Amount | C14: 0.84127 | D14: 0.005291 | E14: 1 | F14: 0.015873 | G14: 0.94709 | H14: 0
B15: Time Encoding | C15: 1 | D15: 3 | E15: 1 | F15: 2 | G15: 1 | H15: 4
B16: Merchant Encoding | C16: 3 | D16: 1 | E16: 3 | F16: 1 | G16: 3 | H16: 1
B17: Frequency Encoding | C17: 1 | D17: 0.1 | E17: 0.9 | F17: 0.2 | G17: 0.8 | H17: 0.3
B18: Location Encoding | C18: 1 | D18: 0 | E18: 1 | F18: 0 | G18: 1 | H18: 0
B19: Device Encoding | C19: 1 | D19: 0 | E19: 1 | F19: 0 | G19: 1 | H19: 0
B20: Fraud Label | C20: 1 | D20: 0 | E20: 1 | F20: 0 | G20: 1 | H20: 0
B23: Query (Q) Matrix (6×4)
B25: Feature | C25: Q1 | D25: Q2 | E25: Q3 | F25: Q4
B26: Amount | C26: 0.24835708 | D26: -0.06913215 | E26: 0.32384427 | F26: 0.76151493
B27: Time | C27: -0.11707669 | D27: -0.11706848 | E27: 0.78960641 | F27: 0.38371736
B28: Merchant | C28: -0.23473719 | D28: 0.27128002 | E28: -0.23170885 | F28: -0.23286488
B29: Frequency | C29: 0.12098114 | D29: -0.95664012 | E29: -0.86245892 | F29: -0.28114376
B30: Location | C30: -0.50641556 | D30: 0.15712367 | E30: -0.45401204 | F30: -0.70615185
B31: Device Used | C31: 0.73282438 | D31: -0.11288815 | E31: 0.0337641 | F31: -0.71237409
B33: Key (K) Matrix (6×4)
B35: Feature | C35: K1 | D35: K2 | E35: K3 | F35: K4
B36: Amount | C36: -0.27219136 | D36: 0.05546129 | E36: -0.57549679 | F36: 0.18784901
B37: Time | C37: -0.30031934 | D37: -0.14584687 | E37: -0.30085331 | F37: 0.92613909
B38: Merchant | C38: -0.00674861 | D38: -0.52885546 | E38: 0.41127246 | F38: -0.61042182
B39: Frequency | C39: 0.1044318 | D39: -0.97983506 | E39: -0.66409302 | F39: 0.09843062
B40: Location | C40: 0.36923329 | D40: 0.08568414 | E40: -0.05782414 | F40: -0.15055185
B41: Device Used | C41: -0.739261 | D41: -0.3599221 | E41: -0.23031939 | F41: 0.52856111
B43: Value (V) Matrix (6×4)
B45: Feature | C45: V1 | D45: V2 | E45: V3 | F45: V4
B46: Amount | C46: 0.17180914 | D46: -0.88152008 | E46: 0.16204198 | F46: -0.19254114
B47: Time | C47: -0.338461 | D47: 0.30583814 | E47: 0.51549976 | F47: 0.46564006
B48: Merchant | C48: -0.41960876 | D48: -0.15460619 | E48: 0.16563172 | F48: 0.48777256
B49: Frequency | C49: -0.23958712 | D49: -0.09282949 | E49: -0.55316749 | F49: -0.59810331
...

Sheet First Iteration
B3: Input | C3: X_train: | J3: Y_train
C4: {=TRANSPOSE(Data!C14:H20)} -> 0.84127 | D4: 1 | E4: 3 | F4: 1 | G4: 1 | H4: 1 | I4: 1 | J4: 1 | AG4: dL/dZ
C5: 0.005291 | D5: 3 | E5: 1 | F5: 0.1 | G5: 0 | H5: 0 | I5: 0 | J5: 0 | Z5: Z Matrix (Output of Attention): | AE5: Y_Pred | AI5: Binary Cross-Entropy Loss | AM5: #2. Compute gradient of loss w.r.t attention_weights (dL/dP)
C6: 1 | D6: 1 | E6: 3 | F6: 0.9 | G6: 1 | H6: 1 | I6: 1 | J6: 1 | R6: {=MMULT(M9:P14,TRANSPOSE(M18:P23))} -> 1.8537653 | S6: -1.9505328 | T6: 1.834139 | U6: -0.99832437 | V6: 1.7455433 | W6: -2.6869571 | Z6: {=MMULT(R29:W34,M27:P32)} -> -1.1123972 | AA6: -0.51005121 | AB6: 0.90301822 | AC6: 2.3605532 | AE6: =1/(1+EXP(-SUM(Z6:AC6))) -> 0.8376877 | AG6: =AE6-J4 -> -0.1623123 | AI6: =-J4*LN(AE6)-(1-J4)*LN(1-AE6) -> 0.17710993
C7: 0.015873 | D7: 2 | E7: 1 | F7: 0.2 | G7: 0 | H7: 0 | I7: 0 | J7: 0 | L7: Query | R7: -0.29133521 | S7: 1.499139 | T7: -0.3127373 | U7: 0.96547281 | V7: -0.15060704 | W7: 1.6794754 | Z7: -1.382781 | AA7: 0.32374324 | AB7: 1.4016338 | AC7: 2.0188206 | AE7: =1/(1+EXP(-SUM(Z7:AC7))) -> 0.91383742 | AG7: =AE7-J5 -> 0.91383742 | AI7: =-J5*LN(AE7)-(1-J5)*LN(1-AE7) -> 2.4515193 | AM7: {=MMULT(Z15:AC20,TRANSPOSE(M27:P32))} -> -0.23337255 | AN7: -0.45000356 | AO7: -0.23838397 | AP7: -0.27069414 | AQ7: -0.26882293 | AR7: -0.55643108
C8: 0.94709 | D8: 1 | E8: 3 | F8: 0.8 | G8: 1 | H8: 1 | I8: 1 | J8: 1 | M8: 0 | N8: 1 | O8: 2 | P8: 3 | R8: 1.472896 | S8: -1.8177693 | T8: 1.4603908 | U8: -0.95783467 | V8: 1.3903383 | W8: -2.5092682 | Z8: -1.1235838 | AA8: -0.46649484 | AB8: 0.92572263 | AC8: 2.3362031 | AE8: =1/(1+EXP(-SUM(Z8:AC8))) -> 0.84182193 | AG8: =AE8-J6 -> -0.15817807 | AI8: =-J6*LN(AE8)-(1-J6)*LN(1-AE8) -> 0.17218677 | AM8: 1.313915 | AN8: 2.5335731 | AO8: 1.3421299 | AP8: 1.5240399 | AQ8: 1.5135048 | AR8: 3.1327726
C9: 0 | D9: 4 | E9: 1 | F9: 0.3 | G9: 0 | H9: 0 | I9: 0 | J9: 0 | M9: {=MMULT(C4:H9,C13:F18)} -> -0.26496294 | N9: -0.27379182 | O9: -0.91578653 | P9: -1.3739073 | R9: 0.088931311 | S9: 0.96814029 | T9: 0.076358464 | U9: 0.64600685 | V9: 0.1644608 | W9: 1.0989562 | Z9: -1.3303777 | AA9: 0.17317287 | AB9: 1.3071173 | AC9: 2.0721263 | AE9: =1/(1+EXP(-SUM(Z9:AC9))) -> 0.90221122 | AG9: =AE9-J7 -> 0.90221122 | AI9: =-J7*LN(AE9)-(1-J7)*LN(1-AE9) -> 2.3249454 | AM9: -0.22742835 | AN9: -0.43854158 | AO9: -0.23231213 | AP9: -0.26379932 | AQ9: -0.26197578 | AR9: -0.54225829
M10: -0.57255509 | N10: -0.17595521 | O10: 2.0525779 | P10: 0.894202 | R10: 1.1699841 | S10: -1.9660602 | T10: 1.1674723 | U10: -1.0821682 | V10: 1.1136953 | W10: -2.7257884 | Z10: -1.1259485 | AA10: -0.45332789 | AB10: 0.9316074 | AC10: 2.3267375 | AE10: =1/(1+EXP(-SUM(Z10:AC10))) -> 0.84278114 | AG10: =AE10-J8 -> -0.15721886 | AI10: =-J8*LN(AE10)-(1-J8)*LN(1-AE10) -> 0.17104797 | AM10: 1.2971988 | AN10: 2.50134 | AO10: 1.3250548 | AP10: 1.5046505 | AQ10: 1.4942494 | AR10: 3.0929162
M11: -0.23763933 | N11: -0.18910116 | O11: -0.77813684 | P11: -1.2249177 | R11: 0.29365318 | S11: 2.271246 | T11: 0.23552398 | U11: 1.5384426 | V11: 0.42121166 | W11: 2.6237536 | Z11: -1.4080678 | AA11: 0.37061486 | AB11: 1.4412051 | AC11: 2.0215737 | AE11: =1/(1+EXP(-SUM(Z11:AC11))) -> 0.91873825 | AG11: =AE11-J9 -> 0.91873825 | AI11: =-J9*LN(AE11)-(1-J9)*LN(1-AE11) -> 2.5100799 | AM11: -0.2260492 | AN11: -0.43588221 | AO11: -0.23090336 | AP11: -0.26219961 | AQ11: -0.26038712 | AR11: -0.53896997
B12: Query | M12: -0.44075217 | N12: -0.1552823 | O12: 1.1801526 | P12: 0.49042861 | AI12: =AVERAGE(AI6:AI11) -> 1.3011482 | AM12: 1.3209614 | AN12: 2.5471605 | AO12: 1.3493276 | AP12: 1.5322132 | AQ12: 1.5216216 | AR12: 3.1495734
C13: =Data!C26 -> 0.24835708 | D13: =Data!D26 -> -0.06913215 | E13: =Data!E26 -> 0.32384427 | F13: =Data!F26 -> 0.76151493 | M13: -0.26287802 | N13: -0.089779364 | O13: -0.70902555 | P13: -1.2370951 | R13: Attention Scores:
C14: =Data!C27 -> -0.11707669 | D14: =Data!D27 -> -0.11706848 | E14: =Data!E27 -> 0.78960641 | F14: =Data!F27 -> 0.38371736 | M14: -0.66674961 | N14: -0.48398594 | O14: 2.6679791 | P14: 1.2176614 | R14: =R6/SQRT(4) -> 0.92688263 | S14: =S6/SQRT(4) -> -0.97526642 | T14: =T6/SQRT(4) -> 0.9170695 | U14: =U6/SQRT(4) -> -0.49916219 | V14: =V6/SQRT(4) -> 0.87277167 | W14: =W6/SQRT(4) -> -1.3434786 | Z14: # 1. Compute gradient of loss w.r.t attention_output (dL/dZ)
C15: =Data!C28 -> -0.23473719 | D15: =Data!D28 -> 0.27128002 | E15: =Data!E28 -> -0.23170885 | F15: =Data!F28 -> -0.23286488 | R15: =R7/SQRT(4) -> -0.1456676 | S15: =S7/SQRT(4) -> 0.74956952 | T15: =T7/SQRT(4) -> -0.15636865 | U15: =U7/SQRT(4) -> 0.4827364 | V15: =V7/SQRT(4) -> -0.075303521 | W15: =W7/SQRT(4) -> 0.83973772 | Z15: =AG6 -> -0.1623123 | AA15: =Z15 -> -0.1623123 | AB15: =AA15 -> -0.1623123 | AC15: =AB15 -> -0.1623123 | AF15: =R29*AM7 -> -0.06803187 | AG15: =S29*AN7 -> -0.019578786 | AH15: =T29*AO7 -> -0.068814175 | AI15: =U29*AP7 -> -0.018959116 | AJ15: =V29*AQ7 -> -0.074238443 | AK15: =W29*AR7 -> -0.016752078 | AM15: =SUM(AF15:AK15) -> -0.26637447 | AO15: =AM7-$AM15 -> 0.033001916 | AP15: =AN7-$AM15 -> -0.1836291 | AQ15: =AO7-$AM15 -> 0.027990492 | AR15: =AP7-$AM15 -> -0.004319673 | AS15: =AQ7-$AM15 -> -0.002448463 | AT15: =AR7-$AM15 -> -0.29005661
C16: =Data!C29 -> 0.12098114 | D16: =Data!D29 -> -0.95664012 | E16: =Data!E29 -> -0.86245892 | F16: =Data!F29 -> -0.28114376 | L16: Key | R16: =R8/SQRT(4) -> 0.73644801 | S16: =S8/SQRT(4) -> -0.90888465 | T16: =T8/SQRT(4) -> 0.73019541 | U16: =U8/SQRT(4) -> -0.47891734 | V16: =V8/SQRT(4) -> 0.69516916 | W16: =W8/SQRT(4) -> -1.2546341 | Z16: =AG7 -> 0.91383742 | AA16: =Z16 -> 0.91383742 | AB16: =AA16 -> 0.91383742 | AC16: =AB16 -> 0.91383742 | AF16: =R30*AM8 -> 0.13056003 | AG16: =S30*AN8 -> 0.61627275 | AH16: =T30*AO8 -> 0.13194415 | AI16: =U30*AP8 -> 0.28389106 | AJ16: =V30*AQ8 -> 0.16135615 | AK16: =W30*AR8 -> 0.83392683 | AM16: =SUM(AF16:AK16) -> 2.157951 | AO16: =AM8-$AM16 -> -0.84403597 | AP16: =AN8-$AM16 -> 0.37562217 | AQ16: =AO8-$AM16 -> -0.81582107 | AR16: =AP8-$AM16 -> -0.63391103 | AS16: =AQ8-$AM16 -> -0.64444616 | AT16: =AR8-$AM16 -> 0.97482165
C17: =Data!C30 -> -0.50641556 | D17: =Data!D30 -> 0.15712367 | E17: =Data!E30 -> -0.45401204 | F17: =Data!F30 -> -0.70615185 | M17: 0 | N17: 1 | O17: 2 | P17: 3 | R17: =R9/SQRT(4) -> 0.044465656 | S17: =S9/SQRT(4) -> 0.48407014 | T17: =T9/SQRT(4) -> 0.038179232 | U17: =U9/SQRT(4) -> 0.32300342 | V17: =V9/SQRT(4) -> 0.082230399 | W17: =W9/SQRT(4) -> 0.54947812 | Z17: =AG8 -> -0.15817807 | AA17: =Z17 -> -0.15817807 | AB17: =AA17 -> -0.15817807 | AC17: =AB17 -> -0.15817807 | AF17: =R31*AM9 -> -0.063537659 | AG17: =S31*AN9 -> -0.023639511 | AH17: =T31*AO9 -> -0.064497521 | AI17: =U31*AP9 -> -0.021859178 | AJ17: =V31*AQ9 -> -0.070229661 | AK17: =W31*AR9 -> -0.020686015 | AM17: =SUM(AF17:AK17) -> -0.26444954 | AO17: =AM9-$AM17 -> 0.037021195 | AP17: =AN9-$AM17 -> -0.17409203 | AQ17: =AO9-$AM17 -> 0.032137417 | AR17: =AP9-$AM17 -> 0.00065022023 | AS17: =AQ9-$AM17 -> 0.0024737689 | AT17: =AR9-$AM17 -> -0.27780875
C18: =Data!C31 -> 0.73282438 | D18: =Data!D31 -> -0.11288815 | E18: =Data!E31 -> 0.0337641 | F18: =Data!F31 -> -0.71237409 | M18: {=MMULT(C4:H9,C20:F25)} -> -0.81514751 | N18: -2.9398284 | O18: -0.50342066 | P18: -0.27065475 | R18: =R10/SQRT(4) -> 0.58499203 | S18: =S10/SQRT(4) -> -0.9830301 | T18: =T10/SQRT(4) -> 0.58373615 | U18: =U10/SQRT(4) -> -0.54108411 | V18: =V10/SQRT(4) -> 0.55684764 | W18: =W10/SQRT(4) -> -1.3628942 | Z18: =AG9 -> 0.90221122 | AA18: =Z18 -> 0.90221122 | AB18: =AA18 -> 0.90221122 | AC18: =AB18 -> 0.90221122 | AF18: =R32*AM10 -> 0.17153006 | AG18: =S32*AN10 -> 0.5133626 | AH18: =T32*AO10 -> 0.17411547 | AI18: =U32*AP10 -> 0.26286741 | AJ18: =V32*AQ10 -> 0.20519076 | AK18: =W32*AR10 -> 0.67768203 | AM18: =SUM(AF18:AK18) -> 2.0047483 | AO18: =AM10-$AM18 -> -0.70754948 | AP18: =AN10-$AM18 -> 0.49659169 | AQ18: =AO10-$AM18 -> -0.67969354 | AR18: =AP10-$AM18 -> -0.50009783 | AS18: =AQ10-$AM18 -> -0.51049893 | AT18: =AR10-$AM18 -> 1.0881679
B19: W_K | C19: Matrix: | M19: -0.89870361 | N19: -1.0640861 | O19: -0.56074173 | P19: 2.1788324 | R19: =R11/SQRT(4) -> 0.14682659 | S19: =S11/SQRT(4) -> 1.135623 | T19: =T11/SQRT(4) -> 0.11776199 | U19: =U11/SQRT(4) -> 0.76922128 | V19: =V11/SQRT(4) -> 0.21060583 | W19: =W11/SQRT(4) -> 1.3118768 | Z19: =AG10 -> -0.15721886 | AA19: =Z19 -> -0.15721886 | AB19: =AA19 -> -0.15721886 | AC19: =AB19 -> -0.15721886 | AF19: =R33*AM11 -> -0.061993647 | AG19: =S33*AN11 -> -0.024918966 | AH19: =T33*AO11 -> -0.063245416 | AI19: =U33*AP11 -> -0.02331995 | AJ19: =V33*AQ11 -> -0.069428978 | AK19: =W33*AR11 -> -0.02107427 | AM19: =SUM(AF19:AK19) -> -0.26398123 | AO19: =AM11-$AM19 -> 0.037932032 | AP19: =AN11-$AM19 -> -0.17190098 | AQ19: =AO11-$AM19 -> 0.033077869 | AR19: =AP11-$AM19 -> 0.0017816145 | AS19: =AQ11-$AM19 -> 0.003594105 | AT19: =AR11-$AM19 -> -0.27498875
C20: =Data!C36 -> -0.27219136 | D20: =Data!D36 -> 0.05546129 | E20: =Data!E36 -> -0.57549679 | F20: =Data!F36 -> 0.18784901 | M20: -0.86879562 | N20: -2.8330415 | O20: -0.52835997 | P20: -0.25068054 | Z20: =AG11 -> 0.91873825 | AA20: =Z20 -> 0.91873825 | AB20: =AA20 -> 0.91873825 | AC20: =AB20 -> 0.91873825 | AF20: =R34*AM12 -> 0.12237156 | AG20: =S34*AN12 -> 0.63427192 | AH20: =T34*AO12 -> 0.12141859 | AI20: =U34*AP12 -> 0.26449176 | AJ20: =V34*AQ12 -> 0.1502436 | AK20: =W34*AR12 -> 0.93544223 | AM20: =SUM(AF20:AK20) -> 2.2282396 | AO20: =AM12-$AM20 -> -0.90727824 | AP20: =AN12-$AM20 -> 0.31892083 | AQ20: =AO12-$AM20 -> -0.87891202 | AR20: =AP12-$AM20 -> -0.69602641 | AS20: =AQ12-$AM20 -> -0.70661804 | AT20: =AR12-$AM20 -> 0.92133376
C21: =Data!C37 -> -0.30031934 | D21: =Data!D37 -> -0.14584687 | E21: =Data!E37 -> -0.30085331 | F21: =Data!F37 -> 0.92613909 | M21: -0.59082142 | N21: -1.0156359 | O21: -0.33238762 | P21: 1.2645242 | R21: =EXP(R14) -> 2.5266205 | S21: =EXP(S14) -> 0.37709187 | T21: =EXP(T14) -> 2.5019477 | U21: =EXP(U14) -> 0.60703903 | V21: =EXP(V14) -> 2.3935358 | W21: =EXP(W14) -> 0.2609364 | Z21: # 3. Compute gradient of loss w.r.t attention scores (dL/dA) with softmax derivative
C22: =Data!C38 -> -0.00674861 | D22: =Data!D38 -> -0.52885546 | E22: =Data!E38 -> 0.41127246 | F22: =Data!F38 -> -0.61042182 | M22: -0.86483716 | N22: -2.7379924 | O22: -0.43150113 | P22: -0.2704627 | R22: =EXP(R15) -> 0.86444499 | S22: =EXP(S15) -> 2.1160889 | T22: =EXP(T15) -> 0.85524385 | U22: =EXP(U15) -> 1.6205027 | V22: =EXP(V15) -> 0.92746194 | W22: =EXP(W15) -> 2.3157595 | Z22: =R29*AO15/SQRT(4) -> 0.0048102959 | AA22: =S29*AP15/SQRT(4) -> -0.0039946736 | AB22: =T29*AQ15/SQRT(4) -> 0.0040400002 | AC22: =U29*AR15/SQRT(4) -> -0.00015127255 | AD22: =V29*AS15/SQRT(4) -> -0.00033808515 | AE22: =W29*AT15/SQRT(4) -> -0.0043662648
C23: =Data!C39 -> 0.1044318 | D23: =Data!D39 -> -0.97983506 | E23: =Data!E39 -> -0.66409302 | F23: =Data!F39 -> 0.09843062 | M23: -1.1766964 | N23: -1.4061935 | O23: -0.99136869 | P23: 3.1236637 | R23: =EXP(R16) -> 2.088504 | S23: =EXP(S16) -> 0.40297343 | T23: =EXP(T16) -> 2.0754861 | U23: =EXP(U16) -> 0.61945369 | V23: =EXP(V16) -> 2.0040481 | W23: =EXP(W16) -> 0.28518017 | Z23: =R30*AO16/SQRT(4) -> -0.041934738 | AA23: =S30*AP16/SQRT(4) -> 0.045683645 | AB23: =T30*AQ16/SQRT(4) -> -0.040101489 | AC23: =U30*AR16/SQRT(4) -> -0.059040997 | AD23: =V30*AS16/SQRT(4) -> -0.034352501 | AE23: =W30*AT16/SQRT(4) -> 0.12974608
C24: =Data!C40 -> 0.36923329 | D24: =Data!D40 -> 0.08568414 | E24: =Data!E40 -> -0.05782414 | F24: =Data!F40 -> -0.15055185 | R24: =EXP(R17) -> 1.0454691 | S24: =EXP(S17) -> 1.6226655 | T24: =EXP(T17) -> 1.0389174 | U24: =EXP(U17) -> 1.3812701 | V24: =EXP(V17) -> 1.0857059 | W24: =EXP(W17) -> 1.7323487 | Z24: =R31*AO17/SQRT(4) -> 0.0051713872 | AA24: =S31*AP17/SQRT(4) -> -0.0046922011 | AB24: =T31*AQ17/SQRT(4) -> 0.0044612043 | AC24: =U31*AR17/SQRT(4) -> 2.6939568e-05 | AD24: =V31*AS17/SQRT(4) -> 0.00033158018 | AE24: =W31*AT17/SQRT(4) -> -0.0052989101
C25: =Data!C41 -> -0.739261 | D25: =Data!D41 -> -0.3599221 | E25: =Data!E41 -> -0.23031939 | F25: =Data!F41 -> 0.52856111 | L25: Value | R25: =EXP(R18) -> 1.7949767 | S25: =EXP(S18) -> 0.37417559 | T25: =EXP(T18) -> 1.7927238 | U25: =EXP(U18) -> 0.58211683 | V25: =EXP(V18) -> 1.7451624 | W25: =EXP(W18) -> 0.25591902 | Z25: =R32*AO18/SQRT(4) -> -0.046780032 | AA25: =S32*AP18/SQRT(4) -> 0.050959005 | AB25: =T32*AQ18/SQRT(4) -> -0.044656705 | AC25: =U32*AR18/SQRT(4) -> -0.04368437 | AD25: =V32*AS18/SQRT(4) -> -0.03505093 | AE25: =W32*AT18/SQRT(4) -> 0.11921303
B26: W_V | C26: Matrix: | M26: 0 | N26: 1 | O26: 2 | P26: 3 | R26: =EXP(R19) -> 1.1581531 | S26: =EXP(S19) -> 3.1131124 | T26: =EXP(T19) -> 1.1249763 | U26: =EXP(U19) -> 2.158085 | V26: =EXP(V19) -> 1.2344257 | W26: =EXP(W19) -> 3.7131361 | Z26: =R33*AO19/SQRT(4) -> 0.0052014009 | AA26: =S33*AP19/SQRT(4) -> -0.0049137067 | AB26: =T33*AQ19/SQRT(4) -> 0.0045300848 | AC26: =U33*AR19/SQRT(4) -> 7.9228114e-05 | AD26: =V33*AS19/SQRT(4) -> 0.00047916163 | AE26: =W33*AT19/SQRT(4) -> -0.0053761689
C27: =Data!C46 -> 0.17180914 | D27: =Data!D46 -> -0.88152008 | E27: =Data!E46 -> 0.16204198 | F27: =Data!F46 -> -0.19254114 | M27: {=MMULT(C4:H9,C27:F32)} -> -1.1052556 | N27: -0.63684619 | O27: 0.74024123 | P27: 2.4396601 | Z27: =R34*AO20/SQRT(4) -> -0.042024335 | AA27: =S34*AP20/SQRT(4) -> 0.039707456 | AB27: =T34*AQ20/SQRT(4) -> -0.039544234 | AC27: =U34*AR20/SQRT(4) -> -0.060074291 | AD27: =V34*AS20/SQRT(4) -> -0.034885428 | AE27: =W34*AT20/SQRT(4) -> 0.13682083
C28: =Data!C47 -> -0.338461 | D28: =Data!D47 -> 0.30583814 | E28: =Data!E47 -> 0.51549976 | F28: =Data!F47 -> 0.46564006 | M28: -1.4580414 | N28: 0.74896116 | O28: 1.6576716 | P28: 1.8238637 | R28: Softmax Attention Probabilities:
C29: =Data!C48 -> -0.41960876 | D29: =Data!D48 -> -0.15460619 | E29: =Data!E48 -> 0.16563172 | F29: =Data!F48 -> 0.48777256 | M29: -1.0540256 | N29: -0.76748692 | O29: 0.8212789 | P29: 2.4689084 | R29: =R21/SUM($R21:$W21) -> 0.29151616 | S29: =S21/SUM($R21:$W21) -> 0.043508068 | T29: =T21/SUM($R21:$W21) -> 0.28866947 | U29: =U21/SUM($R21:$W21) -> 0.070038888 | V29: =V21/SUM($R21:$W21) -> 0.27616112 | W29: =W21/SUM($R21:$W21) -> 0.030106294 | Z29: Gradients dL/dK: | AG29: Gradients dL/dV:
C30: =Data!C49 -> -0.23958712 | D30: =Data!D49 -> -0.09282949 | E30: =Data!E49 -> -0.55316749 | F30: =Data!F49 -> -0.59810331 | M30: -1.1417211 | N30: 0.42451182 | O30: 1.0885698 | P30: 1.2963758 | R30: =R22/SUM($R22:$W22) -> 0.099367183 | S30: =S22/SUM($R22:$W22) -> 0.24324253 | T30: =T22/SUM($R22:$W22) -> 0.098309519 | U30: =U22/SUM($R22:$W22) -> 0.18627534 | V30: =V22/SUM($R22:$W22) -> 0.10661092 | W30: =W22/SUM($R22:$W22) -> 0.2661945 | Z30: {=MMULT(TRANSPOSE(Z22:AE27),M9:P14)} -> 0.068777248 | AA30: 0.03222002 | AB30: -0.26551912 | AC30: -0.13098986 | AG30: {=MMULT(TRANSPOSE(R29:W34),Z15:AC20)} -> 0.16059156 | AH30: 0.16059156 | AI30: 0.16059156 | AJ30: 0.16059156
C31: =Data!C50 -> 0.40626291 | D31: =Data!D50 -> 0.67812001 | E31: =Data!E50 -> -0.03600506 | F31: =Data!F50 -> 0.50176645 | M31: -1.0391573 | N31: -0.71156274 | O31: 0.86802201 | P31: 2.538906 | R31: =R23/SUM($R23:$W23) -> 0.2793744 | S31: =S23/SUM($R23:$W23) -> 0.053904834 | T31: =T23/SUM($R23:$W23) -> 0.27763304 | U31: =U23/SUM($R23:$W23) -> 0.082862904 | V31: =V23/SUM($R23:$W23) -> 0.26807693 | W31: =W23/SUM($R23:$W23) -> 0.038147899 | Z31: -0.071626429 | AA31: -0.032746998 | AB31: 0.27064069 | AC31: 0.13150699 | AG31: 0.61164924 | AH31: 0.61164924 | AI31: 0.61164924 | AJ31: 0.61164924
C32: =Data!C51 -> 0.18081801 | D32: =Data!D51 -> -0.32255988 | E32: =Data!E51 -> 0.1806978 | F32: =Data!F51 -> 0.76901828 | M32: -1.8453289 | N32: 1.0408975 | O32: 2.0616805 | P32: 2.1709018 | R32: =R24/SUM($R24:$W24) -> 0.13223112 | S32: =S24/SUM($R24:$W24) -> 0.20523503 | T32: =T24/SUM($R24:$W24) -> 0.13140247 | U32: =U24/SUM($R24:$W24) -> 0.1747033 | V32: =V24/SUM($R24:$W24) -> 0.13732029 | W32: =W24/SUM($R24:$W24) -> 0.21910779 | Z32: 0.065687486 | AA32: 0.030772869 | AB32: -0.2508995 | AC32: -0.12253059 | AG32: 0.15723093 | AH32: 0.15723093 | AI32: 0.15723093 | AJ32: 0.15723093
R33: =R25/SUM($R25:$W25) -> 0.27424848 | S33: =S25/SUM($R25:$W25) -> 0.057169036 | T33: =T25/SUM($R25:$W25) -> 0.27390427 | U33: =U25/SUM($R25:$W25) -> 0.088939682 | V33: =V25/SUM($R25:$W25) -> 0.26663753 | W33: =W25/SUM($R25:$W25) -> 0.03910101 | Z33: 0.093125566 | AA33: 0.046276302 | AB33: -0.33295603 | AC33: -0.14729197 | AG33: 0.44797965 | AH33: 0.44797965 | AI33: 0.44797965 | AJ33: 0.44797965
R34: =R26/SUM($R26:$W26) -> 0.092638252 | S34: =S26/SUM($R26:$W26) -> 0.24901137 | T34: =T26/SUM($R26:$W26) -> 0.08998451 | U34: =U26/SUM($R26:$W26) -> 0.17262072 | V34: =V26/SUM($R26:$W26) -> 0.098739136 | W34: =W26/SUM($R26:$W26) -> 0.29700601 | Z34: 0.05826214 | AA34: 0.028358191 | AB34: -0.20523836 | AC34: -0.090921123 | AG34: 0.18288369 | AH34: 0.18288369 | AI34: 0.18288369 | AJ34: 0.18288369
Z35: -0.21422601 | AA35: -0.10488038 | AB35: 0.78397231 | AC35: 0.36022654 | AG35: 0.69674258 | AH35: 0.69674258 | AI35: 0.69674258 | AJ35: 0.69674258
Z37: Gradients dL/dQ: | AF37: np.dot(X_train.T, dL_dV) | AK37: Updated W_V:
Z38: {=MMULT(Z22:AE27,M18:P23)} -> 0.0016785243 | AA38: -0.01411713 | AB38: 0.0022085469 | AC38: -0.024756995 | AF38: {=MMULT(TRANSPOSE(C4:H9),AG30:AJ35)} -> 0.47588613 | AG38: 0.47588613 | AH38: 0.47588613 | AI38: 0.47588613 | AK38: =C27-0.02*AF38 -> 0.16229142 | AL38: =D27-0.02*AG38 -> -0.8910378 | AM38: =E27-0.02*AH38 -> 0.15252426 | AN38: =F27-0.02*AI38 -> -0.20205886
Z39: -0.060112806 | AA39: 0.15985173 | AB39: -0.077496452 | AC39: 0.46085493 | AF39: 6.0185835 | AG39: 6.0185835 | AH39: 6.0185835 | AI39: 6.0185835 | AK39: =C28-0.02*AF39 -> -0.45883267 | AL39: =D28-0.02*AG39 -> 0.18546647 | AM39: =E28-0.02*AH39 -> 0.39512809 | AN39: =F28-0.02*AI39 -> 0.34526839
Z40: 0.0020581093 | AA40: -0.016332793 | AB40: 0.00277175 | AC40: -0.029349145 | AF40: 3.25849 | AG40: 3.25849 | AH40: 3.25849 | AI40: 3.25849 | AK40: =C29-0.02*AF40 -> -0.48477856 | AL40: =D29-0.02*AG40 -> -0.21977599 | AM40: =E29-0.02*AH40 -> 0.10046192 | AN40: =F29-0.02*AI40 -> 0.42260276
Z41: -0.053021407 | AA41: 0.1825148 | AB41: -0.069969397 | AC41: 0.46150839 | AF41: 0.80818999 | AG41: 0.80818999 | AH41: 0.80818999 | AI41: 0.80818999 | AK41: =C30-0.02*AF41 -> -0.25575092 | AL41: =D30-0.02*AG41 -> -0.10899329 | AM41: =E30-0.02*AH41 -> -0.56933129 | AN41: =F30-0.02*AI41 -> -0.61426711
Z42: 0.0021052513 | AA42: -0.016729011 | AB42: 0.0028399844 | AC42: -0.030072285 | AF42: 0.50070619 | AG42: 0.50070619 | AH42: 0.50070619 | AI42: 0.50070619 | AK42: =C31-0.02*AF42 -> 0.39624879 | AL42: =D31-0.02*AG42 -> 0.66810589 | AM42: =E31-0.02*AH42 -> -0.046019184 | AN42: =F31-0.02*AI42 -> 0.49175233
Z43: -0.062406537 | AA43: 0.15745572 | AB43: -0.080834954 | AC43: 0.46865503 | AF43: 0.50070619 | AG43: 0.50070619 | AH43: 0.50070619 | AI43: 0.50070619 | AK43: =C32-0.02*AF43 -> 0.17080389 | AL43: =D32-0.02*AG43 -> -0.332574 | AM43: =E32-0.02*AH43 -> 0.17068368 | AN43: =F32-0.02*AI43 -> 0.75900416
...

Sheet Second Iteration
B3: Input | C3: X_train: | J3: Y_train
C4: {=TRANSPOSE(Data!C14:H20)} -> 0.84127 | D4: 1 | E4: 3 | F4: 1 | G4: 1 | H4: 1 | I4: 1 | J4: 1 | AG4: dL/dZ
C5: 0.005291 | D5: 3 | E5: 1 | F5: 0.1 | G5: 0 | H5: 0 | I5: 0 | J5: 0 | Z5: Z Matrix (Output of Attention): | AE5: Y_Pred | AI5: Binary Cross-Entropy Loss | AM5: #2. Compute gradient of loss w.r.t attention_weights (dL/dP)
C6: 1 | D6: 1 | E6: 3 | F6: 0.9 | G6: 1 | H6: 1 | I6: 1 | J6: 1 | R6: {=MMULT(M9:P14,TRANSPOSE(M18:P23))} -> 1.8783288 | S6: -2.0739994 | T6: 1.8469427 | U6: -1.0529662 | V6: 1.7618005 | W6: -2.8785792 | Z6: {=MMULT(R29:W34,M27:P32)} -> -1.4731078 | AA6: -0.88472372 | AB6: 0.53272167 | AC6: 2.0013874 | AE6: =1/(1+EXP(-SUM(Z6:AC6))) -> 0.54395564 | AG6: =AE6-J4 -> -0.45604436 | AI6: =-J4*LN(AE6)-(1-J4)*LN(1-AE6) -> 0.60888758
C7: 0.015873 | D7: 2 | E7: 1 | F7: 0.2 | G7: 0 | H7: 0 | I7: 0 | J7: 0 | L7: Query | R7: 0.22154994 | S7: 0.63703289 | T7: 0.18496767 | U7: 0.50028467 | V7: 0.34392724 | W7: 0.43867024 | Z7: -1.6819385 | AA7: -0.33145796 | AB7: 0.83611711 | AC7: 1.7013493 | AE7: =1/(1+EXP(-SUM(Z7:AC7))) -> 0.62809896 | AG7: =AE7-J5 -> 0.62809896 | AI7: =-J5*LN(AE7)-(1-J5)*LN(1-AE7) -> 0.98912749 | AM7: {=MMULT(Z15:AC20,TRANSPOSE(M27:P32))} -> 0.0011496295 | AN7: -0.48370291 | AO7: -0.013123519 | AP7: -0.19634922 | AQ7: -0.10251419 | AR7: -0.55734479
C8: 0.94709 | D8: 1 | E8: 3 | F8: 0.8 | G8: 1 | H8: 1 | I8: 1 | J8: 1 | M8: 0 | N8: 1 | O8: 2 | P8: 3 | R8: 1.5129776 | S8: -1.9633438 | T8: 1.4889881 | U8: -1.0253075 | V8: 1.4220777 | W8: -2.7317666 | Z8: -1.4839359 | AA8: -0.8480539 | AB8: 0.55096736 | AC8: 1.9783304 | AE8: =1/(1+EXP(-SUM(Z8:AC8))) -> 0.5491676 | AG8: =AE8-J6 -> -0.4508324 | AI8: =-J6*LN(AE8)-(1-J6)*LN(1-AE8) -> 0.59935161 | AM8: -0.0015833572 | AN8: 0.66619242 | AO8: 0.018074708 | AP8: 0.27042707 | AQ8: 0.14119034 | AR8: 0.76761761
C9: 0 | D9: 4 | E9: 1 | F9: 0.3 | G9: 0 | H9: 0 | I9: 0 | J9: 0 | M9: {=MMULT(C4:H9,C13:F18)} -> -0.24458237 | N9: -0.32241863 | O9: -0.88936718 | P9: -1.5236856 | R9: 0.42005689 | S9: 0.40362919 | T9: 0.39656718 | U9: 0.34264102 | V9: 0.48298277 | W9: 0.28505193 | Z9: -1.6604483 | AA9: -0.39400999 | AB9: 0.80277667 | AC9: 1.7367873 | AE9: =1/(1+EXP(-SUM(Z9:AC9))) -> 0.61895277 | AG9: =AE9-J7 -> 0.61895277 | AI9: =-J7*LN(AE9)-(1-J7)*LN(1-AE9) -> 0.96483195 | AM9: 0.0011364908 | AN9: -0.47817485 | AO9: -0.012973535 | AP9: -0.19410522 | AQ9: -0.1013426 | AR9: -0.55097511
M10: -0.53752507 | N10: -0.26886543 | O10: 2.098029 | P10: 0.62527072 | R10: 1.2147331 | S10: -2.1179894 | T10: 1.200826 | U10: -1.1533319 | V10: 1.1500902 | W10: -2.9571403 | Z10: -1.485905 | AA10: -0.83657273 | AB10: 0.55596249 | AC10: 1.9697399 | AE10: =1/(1+EXP(-SUM(Z10:AC10))) -> 0.55063202 | AG10: =AE10-J8 -> -0.44936798 | AI10: =-J8*LN(AE10)-(1-J8)*LN(1-AE10) -> 0.59668853 | AM10: -0.0015603008 | AN10: 0.65649152 | AO10: 0.017811509 | AP10: 0.26648919 | AQ10: 0.13913437 | AR10: 0.75643979
M11: -0.21733268 | N11: -0.23748495 | O11: -0.75181393 | P11: -1.3740697 | R11: 0.96642897 | S11: 1.14203 | T11: 0.88845401 | U11: 0.92913131 | V11: 1.0699424 | W11: 0.99857451 | Z11: -1.6734607 | AA11: -0.3680349 | AB11: 0.81960578 | AC11: 1.7271656 | AE11: =1/(1+EXP(-SUM(Z11:AC11))) -> 0.62369836 | AG11: =AE11-J9 -> 0.62369836 | AI11: =-J9*LN(AE11)-(1-J9)*LN(1-AE11) -> 0.97736422 | AM11: 0.0011327992 | AN11: -0.47662161 | AO11: -0.012931394 | AP11: -0.19347471 | AQ11: -0.10101341 | AR11: -0.54918539
B12: Query | M12: -0.41626612 | N12: -0.21975446 | O12: 1.2119215 | P12: 0.30302488 | AI12: =AVERAGE(AI6:AI11) -> 0.78937523 | AM12: -0.0015722638 | AN12: 0.66152492 | AO12: 0.017948072 | AP12: 0.2685324 | AQ12: 0.14020113 | AR12: 0.76223951
C13: ='First Iteration'!AK48 -> 0.24827099 | D13: ='First Iteration'!AL48 -> -0.068325947 | E13: ='First Iteration'!AM48 -> 0.32372829 | F13: ='First Iteration'!AN48 -> 0.7628928 | M13: -0.24262705 | N13: -0.13809076 | O13: -0.68277454 | P13: -1.3859125 | R13: Attention Scores:
C14: ='First Iteration'!AK49 -> -0.10647338 | D14: ='First Iteration'!AL49 -> -0.14561305 | E14: ='First Iteration'!AM49 -> 0.80336536 | F14: ='First Iteration'!AN49 -> 0.3017969 | M14: -0.62099533 | N14: -0.60567509 | O14: 2.7273458 | P14: 0.86598738 | R14: =R6/SQRT(4) -> 0.93916438 | S14: =S6/SQRT(4) -> -1.0369997 | T14: =T6/SQRT(4) -> 0.92347135 | U14: =U6/SQRT(4) -> -0.52648311 | V14: =V6/SQRT(4) -> 0.88090025 | W14: =W6/SQRT(4) -> -1.4392896 | Z14: # 1. Compute gradient of loss w.r.t attention_output (dL/dZ)
C15: ='First Iteration'!AK50 -> -0.23157689 | D15: ='First Iteration'!AL50 -> 0.26411431 | E15: ='First Iteration'!AM50 -> -0.22761205 | F15: ='First Iteration'!AN50 -> -0.25563454 | R15: =R7/SQRT(4) -> 0.11077497 | S15: =S7/SQRT(4) -> 0.31851644 | T15: =T7/SQRT(4) -> 0.092483837 | U15: =U7/SQRT(4) -> 0.25014234 | V15: =V7/SQRT(4) -> 0.17196362 | W15: =W7/SQRT(4) -> 0.21933512 | Z15: =AG6 -> -0.45604436 | AA15: =Z15 -> -0.45604436 | AB15: =AA15 -> -0.45604436 | AC15: =AB15 -> -0.45604436 | AF15: =R29*AM7 -> 0.00033911853 | AG15: =S29*AN7 -> -0.01977585 | AH15: =T29*AO7 -> -0.0038109084 | AI15: =U29*AP7 -> -0.013375196 | AJ15: =V29*AQ7 -> -0.028528163 | AK15: =W29*AR7 -> -0.015239408 | AM15: =SUM(AF15:AK15) -> -0.080390407 | AO15: =AM7-$AM15 -> 0.081540037 | AP15: =AN7-$AM15 -> -0.4033125 | AQ15: =AO7-$AM15 -> 0.067266889 | AR15: =AP7-$AM15 -> -0.11595881 | AS15: =AQ7-$AM15 -> -0.022123784 | AT15: =AR7-$AM15 -> -0.47695438
C16: ='First Iteration'!AK51 -> 0.12158359 | D16: ='First Iteration'!AL51 -> -0.95779062 | E16: ='First Iteration'!AM51 -> -0.86167854 | F16: ='First Iteration'!AN51 -> -0.28521885 | L16: Key | R16: =R8/SQRT(4) -> 0.75648882 | S16: =S8/SQRT(4) -> -0.98167191 | T16: =T8/SQRT(4) -> 0.74449406 | U16: =U8/SQRT(4) -> -0.51265375 | V16: =V8/SQRT(4) -> 0.71103887 | W16: =W8/SQRT(4) -> -1.3658833 | Z16: =AG7 -> 0.62809896 | AA16: =Z16 -> 0.62809896 | AB16: =AA16 -> 0.62809896 | AC16: =AB16 -> 0.62809896 | AF16: =R30*AM8 -> -0.00024210029 | AG16: =S30*AN8 -> 0.12538255 | AH16: =T30*AO8 -> 0.0027135884 | AI16: =U30*AP8 -> 0.047532763 | AJ16: =V30*AQ8 -> 0.022950666 | AK16: =W30*AR8 -> 0.13083033 | AM16: =SUM(AF16:AK16) -> 0.32916779 | AO16: =AM8-$AM16 -> -0.33075115 | AP16: =AN8-$AM16 -> 0.33702463 | AQ16: =AO8-$AM16 -> -0.31109308 | AR16: =AP8-$AM16 -> -0.058740722 | AS16: =AQ8-$AM16 -> -0.18797745 | AT16: =AR8-$AM16 -> 0.43844982
C17: ='First Iteration'!AK52 -> -0.5065324 | D17: ='First Iteration'!AL52 -> 0.15806725 | E17: ='First Iteration'!AM52 -> -0.45416845 | F17: ='First Iteration'!AN52 -> -0.70446828 | M17: 0 | N17: 1 | O17: 2 | P17: 3 | R17: =R9/SQRT(4) -> 0.21002844 | S17: =S9/SQRT(4) -> 0.2018146 | T17: =T9/SQRT(4) -> 0.19828359 | U17: =U9/SQRT(4) -> 0.17132051 | V17: =V9/SQRT(4) -> 0.24149139 | W17: =W9/SQRT(4) -> 0.14252597 | Z17: =AG8 -> -0.4508324 | AA17: =Z17 -> -0.4508324 | AB17: =AA17 -> -0.4508324 | AC17: =AB17 -> -0.4508324 | AF17: =R31*AM9 -> 0.00032283851 | AG17: =S31*AN9 -> -0.023885399 | AH17: =T31*AO9 -> -0.0036414006 | AI17: =U31*AP9 -> -0.015497976 | AJ17: =V31*AQ9 -> -0.02750887 | AK17: =W31*AR9 -> -0.01874204 | AM17: =SUM(AF17:AK17) -> -0.088952847 | AO17: =AM9-$AM17 -> 0.090089338 | AP17: =AN9-$AM17 -> -0.38922201 | AQ17: =AO9-$AM17 -> 0.075979312 | AR17: =AP9-$AM17 -> -0.10515237 | AS17: =AQ9-$AM17 -> -0.012389749 | AT17: =AR9-$AM17 -> -0.46202226
C18: ='First Iteration'!AK53 -> 0.73270754 | D18: ='First Iteration'!AL53 -> -0.11194457 | E18: ='First Iteration'!AM53 -> 0.033607694 | F18: ='First Iteration'!AN53 -> -0.71069052 | M18: {=MMULT(C4:H9,C20:F25)} -> -0.83758736 | N18: -2.9503449 | O18: -0.41864813 | P18: -0.22963503 | R18: =R10/SQRT(4) -> 0.60736653 | S18: =S10/SQRT(4) -> -1.0589947 | T18: =T10/SQRT(4) -> 0.60041301 | U18: =U10/SQRT(4) -> -0.57666596 | V18: =V10/SQRT(4) -> 0.5750451 | W18: =W10/SQRT(4) -> -1.4785701 | Z18: =AG9 -> 0.61895277 | AA18: =Z18 -> 0.61895277 | AB18: =AA18 -> 0.61895277 | AC18: =AB18 -> 0.61895277 | AF18: =R32*AM10 -> -0.00026406105 | AG18: =S32*AN10 -> 0.11019399 | AH18: =T32*AO10 -> 0.002979175 | AI18: =U32*AP10 -> 0.043387535 | AJ18: =V32*AQ10 -> 0.024299348 | AK18: =W32*AR10 -> 0.1196615 | AM18: =SUM(AF18:AK18) -> 0.30025748 | AO18: =AM10-$AM18 -> -0.30181779 | AP18: =AN10-$AM18 -> 0.35623404 | AQ18: =AO10-$AM18 -> -0.28244598 | AR18: =AP10-$AM18 -> -0.033768294 | AS18: =AQ10-$AM18 -> -0.16112312 | AT18: =AR10-$AM18 -> 0.45618231
B19: W_K | C19: Matrix: | M19: -0.8651068 | N19: -1.0478319 | O19: -0.68449911 | P19: 2.1213044 | R19: =R11/SQRT(4) -> 0.48321448 | S19: =S11/SQRT(4) -> 0.571015 | T19: =T11/SQRT(4) -> 0.444227 | U19: =U11/SQRT(4) -> 0.46456566 | V19: =V11/SQRT(4) -> 0.53497119 | W19: =W11/SQRT(4) -> 0.49928726 | Z19: =AG10 -> -0.44936798 | AA19: =Z19 -> -0.44936798 | AB19: =AA19 -> -0.44936798 | AC19: =AB19 -> -0.44936798 | AF19: =R33*AM11 -> 0.00031638617 | AG19: =S33*AN11 -> -0.02515051 | AH19: =T33*AO11 -> -0.0035866584 | AI19: =U33*AP11 -> -0.016537505 | AJ19: =V33*AQ11 -> -0.027315337 | AK19: =W33*AR11 -> -0.019049025 | AM19: =SUM(AF19:AK19) -> -0.091322649 | AO19: =AM11-$AM19 -> 0.092455448 | AP19: =AN11-$AM19 -> -0.38529896 | AQ19: =AO11-$AM19 -> 0.078391255 | AR19: =AP11-$AM19 -> -0.10215206 | AS19: =AQ11-$AM19 -> -0.0096907587 | AT19: =AR11-$AM19 -> -0.45786274
C20: ='First Iteration'!AK56 -> -0.27578789 | D20: ='First Iteration'!AL56 -> 0.053755337 | E20: ='First Iteration'!AM56 -> -0.56204669 | F20: ='First Iteration'!AN56 -> 0.19425863 | M20: -0.89156295 | N20: -2.8437146 | O20: -0.44237221 | P20: -0.20908791 | Z20: =AG11 -> 0.62369836 | AA20: =Z20 -> 0.62369836 | AB20: =AA20 -> 0.62369836 | AC20: =AB20 -> 0.62369836 | AF20: =R34*AM12 -> -0.00025756326 | AG20: =S34*AN12 -> 0.11831396 | AH20: =T34*AO12 -> 0.0028277712 | AI20: =U34*AP12 -> 0.043177362 | AJ20: =V34*AQ12 -> 0.024187314 | AK20: =W34*AR12 -> 0.12689084 | AM20: =SUM(AF20:AK20) -> 0.31513968 | AO20: =AM12-$AM20 -> -0.31671195 | AP20: =AN12-$AM20 -> 0.34638524 | AQ20: =AO12-$AM20 -> -0.29719161 | AR20: =AP12-$AM20 -> -0.046607287 | AS20: =AQ12-$AM20 -> -0.17493856 | AT20: =AR12-$AM20 -> 0.44709983
C21: ='First Iteration'!AK57 -> -0.28646323 | D21: ='First Iteration'!AL57 -> -0.13916969 | E21: ='First Iteration'!AM57 -> -0.35205816 | F21: ='First Iteration'!AN57 -> 0.90221106 | M21: -0.57136217 | N21: -1.0061911 | O21: -0.40387812 | P21: 1.2314365 | R21: =EXP(R14) -> 2.5578431 | S21: =EXP(S14) -> 0.35451674 | T21: =EXP(T14) -> 2.5180161 | U21: =EXP(U14) -> 0.59067867 | V21: =EXP(V14) -> 2.4130711 | W21: =EXP(W14) -> 0.23709613 | Z21: # 3. Compute gradient of loss w.r.t attention scores (dL/dA) with softmax derivative
C22: ='First Iteration'!AK58 -> -0.014457685 | D22: ='First Iteration'!AL58 -> -0.5325095 | E22: ='First Iteration'!AM58 -> 0.44013874 | F22: ='First Iteration'!AN58 -> -0.59664416 | M22: -0.88717079 | N22: -2.748461 | O22: -0.34714473 | P22: -0.22965368 | R22: =EXP(R15) -> 1.1171435 | S22: =EXP(S15) -> 1.3750862 | T22: =EXP(T15) -> 1.0968954 | U22: =EXP(U15) -> 1.2842082 | V22: =EXP(V15) -> 1.1876346 | W22: =EXP(W15) -> 1.2452485 | Z22: =R29*AO15/SQRT(4) -> 0.012026369 | AA22: =S29*AP15/SQRT(4) -> -0.0082445725 | AB22: =T29*AQ15/SQRT(4) -> 0.0097667383 | AC22: =U29*AR15/SQRT(4) -> -0.0039495239 | AD22: =V29*AS15/SQRT(4) -> -0.0030783588 | AE22: =W29*AT15/SQRT(4) -> -0.0065206518
C23: ='First Iteration'!AK59 -> 0.10199779 | D23: ='First Iteration'!AL59 -> -0.98097743 | E23: ='First Iteration'!AM59 -> -0.65489592 | F23: ='First Iteration'!AN59 -> 0.1028755 | M23: -1.1297113 | N23: -1.3834815 | O23: -1.1645627 | P23: 3.0430627 | R23: =EXP(R16) -> 2.1307815 | S23: =EXP(S16) -> 0.37468414 | T23: =EXP(T16) -> 2.105376 | U23: =EXP(U16) -> 0.59890413 | V23: =EXP(V16) -> 2.0361054 | W23: =EXP(W16) -> 0.2551552 | Z23: =R30*AO16/SQRT(4) -> -0.025286446 | AA23: =S30*AP16/SQRT(4) -> 0.031715316 | AB23: =T30*AQ16/SQRT(4) -> -0.023352482 | AC23: =U30*AR16/SQRT(4) -> -0.0051624063 | AD23: =V30*AS16/SQRT(4) -> -0.015277985 | AE23: =W30*AT16/SQRT(4) -> 0.037364003
C24: ='First Iteration'!AK60 -> 0.36537875 | D24: ='First Iteration'!AL60 -> 0.083857118 | E24: ='First Iteration'!AM60 -> -0.043391 | F24: ='First Iteration'!AN60 -> -0.14366302 | R24: =EXP(R17) -> 1.2337132 | S24: =EXP(S17) -> 1.2236211 | T24: =EXP(T17) -> 1.2193081 | U24: =EXP(U17) -> 1.1868711 | V24: =EXP(V17) -> 1.2731465 | W24: =EXP(W17) -> 1.153183 | Z24: =R31*AO17/SQRT(4) -> 0.012795663 | AA24: =S31*AP17/SQRT(4) -> -0.0097210497 | AB24: =T31*AQ17/SQRT(4) -> 0.010662904 | AC24: =U31*AR17/SQRT(4) -> -0.0041978493 | AD24: =V31*AS17/SQRT(4) -> -0.0016815633 | AE24: =W31*AT17/SQRT(4) -> -0.0078581042
C25: ='First Iteration'!AK61 -> -0.74311554 | D25: ='First Iteration'!AL61 -> -0.36174912 | E25: ='First Iteration'!AM61 -> -0.21588625 | F25: ='First Iteration'!AN61 -> 0.53544994 | L25: Value | R25: =EXP(R18) -> 1.8355911 | S25: =EXP(S18) -> 0.34680428 | T25: =EXP(T18) -> 1.8228715 | U25: =EXP(U18) -> 0.56176821 | V25: =EXP(V18) -> 1.7772107 | W25: =EXP(W18) -> 0.22796341 | Z25: =R32*AO18/SQRT(4) -> -0.025539409 | AA25: =S32*AP18/SQRT(4) -> 0.029897454 | AB25: =T32*AQ18/SQRT(4) -> -0.023621131 | AC25: =U32*AR18/SQRT(4) -> -0.0027489352 | AD25: =V32*AS18/SQRT(4) -> -0.014069805 | AE25: =W32*AT18/SQRT(4) -> 0.036081826
B26: W_V | C26: Matrix: | M26: 0 | N26: 1 | O26: 2 | P26: 3 | R26: =EXP(R19) -> 1.6212776 | S26: =EXP(S19) -> 1.7700628 | T26: =EXP(T19) -> 1.5592844 | U26: =EXP(U19) -> 1.5913229 | V26: =EXP(V19) -> 1.707399 | W26: =EXP(W19) -> 1.6475466 | Z26: =R33*AO19/SQRT(4) -> 0.012911214 | AA26: =S33*AP19/SQRT(4) -> -0.010165785 | AB26: =T33*AQ19/SQRT(4) -> 0.010871321 | AC26: =U33*AR19/SQRT(4) -> -0.0043657908 | AD26: =V33*AS19/SQRT(4) -> -0.0013102535 | AE26: =W33*AT19/SQRT(4) -> -0.0079407053
C27: ='First Iteration'!AK38 -> 0.16229142 | D27: ='First Iteration'!AL38 -> -0.8910378 | E27: ='First Iteration'!AM38 -> 0.15252426 | F27: ='First Iteration'!AN38 -> -0.20205886 | M27: {=MMULT(C4:H9,C27:F32)} -> -1.4653357 | N27: -0.99692628 | O27: 0.38016113 | P27: 2.07958 | Z27: =R34*AO20/SQRT(4) -> -0.025941372 | AA27: =S34*AP20/SQRT(4) -> 0.03097556 | AB27: =T34*AQ20/SQRT(4) -> -0.023411703 | AC27: =U34*AR20/SQRT(4) -> -0.0037469962 | AD27: =V34*AS20/SQRT(4) -> -0.015090085 | AE27: =W34*AT20/SQRT(4) -> 0.037214597
C28: ='First Iteration'!AK39 -> -0.45883267 | D28: ='First Iteration'!AL39 -> 0.18546647 | E28: ='First Iteration'!AM39 -> 0.39512809 | F28: ='First Iteration'!AN39 -> 0.34526839 | M28: -1.885993 | N28: 0.32100961 | O28: 1.2297201 | P28: 1.3959121 | R28: Softmax Attention Probabilities:
C29: ='First Iteration'!AK40 -> -0.48477856 | D29: ='First Iteration'!AL40 -> -0.21977599 | E29: ='First Iteration'!AM40 -> 0.10046192 | F29: ='First Iteration'!AN40 -> 0.42260276 | M29: -1.4140001 | N29: -1.1274614 | O29: 0.46130444 | P29: 2.1089339 | R29: =R21/SUM($R21:$W21) -> 0.2949807 | S29: =S21/SUM($R21:$W21) -> 0.040884289 | T29: =T21/SUM($R21:$W21) -> 0.29038769 | U29: =U21/SUM($R21:$W21) -> 0.068119428 | V29: =V21/SUM($R21:$W21) -> 0.27828501 | W29: =W21/SUM($R21:$W21) -> 0.027342874 | Z29: Gradients dL/dK: | AG29: Gradients dL/dV:
C30: ='First Iteration'!AK41 -> -0.25575092 | D30: ='First Iteration'!AL41 -> -0.10899329 | E30: ='First Iteration'!AM41 -> -0.56933129 | F30: ='First Iteration'!AN41 -> -0.61426711 | M30: -1.451018 | N30: 0.11521485 | O30: 0.77927286 | P30: 0.98707884 | R30: =R22/SUM($R22:$W22) -> 0.15290315 | S30: =S22/SUM($R22:$W22) -> 0.18820771 | T30: =T22/SUM($R22:$W22) -> 0.1501318 | U30: =U22/SUM($R22:$W22) -> 0.17576925 | V30: =V22/SUM($R22:$W22) -> 0.16255125 | W30: =W22/SUM($R22:$W22) -> 0.17043685 | Z30: {=MMULT(TRANSPOSE(Z22:AE27),M9:P14)} -> 0.031477797 | AA30: 0.019423871 | AB30: -0.18388581 | AC30: -0.099815201 | AG30: {=MMULT(TRANSPOSE(R29:W34),Z15:AC20)} -> -0.085136645 | AH30: -0.085136645 | AI30: -0.085136645 | AJ30: -0.085136645
C31: ='First Iteration'!AK42 -> 0.39624879 | D31: ='First Iteration'!AL42 -> 0.66810589 | E31: ='First Iteration'!AM42 -> -0.046019184 | F31: ='First Iteration'!AN42 -> 0.49175233 | M31: -1.3970118 | N31: -1.0694172 | O31: 0.51016751 | P31: 2.1810515 | R31: =R23/SUM($R23:$W23) -> 0.28406609 | S31: =S23/SUM($R23:$W23) -> 0.049951182 | T31: =T23/SUM($R23:$W23) -> 0.28067913 | U31: =U23/SUM($R23:$W23) -> 0.07984317 | V31: =V23/SUM($R23:$W23) -> 0.2714443 | W31: =W23/SUM($R23:$W23) -> 0.034016128 | Z31: -0.042133079 | AA31: -0.027487768 | AB31: 0.2088359 | AC31: 0.095723198 | AG31: 0.26877769 | AH31: 0.26877769 | AI31: 0.26877769 | AJ31: 0.26877769
C32: ='First Iteration'!AK43 -> 0.17080389 | D32: ='First Iteration'!AL43 -> -0.332574 | E32: ='First Iteration'!AM43 -> 0.17068368 | F32: ='First Iteration'!AN43 -> 0.75900416 | M32: -2.3968345 | N32: 0.4893919 | O32: 1.5101749 | P32: 1.6193962 | R32: =R24/SUM($R24:$W24) -> 0.16923727 | S32: =S24/SUM($R24:$W24) -> 0.16785288 | T32: =T24/SUM($R24:$W24) -> 0.16726123 | U32: =U24/SUM($R24:$W24) -> 0.16281161 | V32: =V24/SUM($R24:$W24) -> 0.17464663 | W32: =W24/SUM($R24:$W24) -> 0.15819038 | Z32: 0.029579933 | AA32: 0.018466923 | AB32: -0.16559835 | AC32: -0.086633363 | AG32: -0.087515941 | AH32: -0.087515941 | AI32: -0.087515941 | AJ32: -0.087515941
R33: =R25/SUM($R25:$W25) -> 0.2792959 | S33: =S25/SUM($R25:$W25) -> 0.052768296 | T33: =T25/SUM($R25:$W25) -> 0.27736055 | U33: =U25/SUM($R25:$W25) -> 0.085476313 | V33: =V25/SUM($R25:$W25) -> 0.27041298 | W33: =W25/SUM($R25:$W25) -> 0.034685964 | Z33: 0.0091836512 | AA33: 0.0071347471 | AB33: -0.014732297 | AC33: 0.010530825 | AG33: 0.20598604 | AH33: 0.20598604 | AI33: 0.20598604 | AJ33: 0.20598604
R34: =R26/SUM($R26:$W26) -> 0.16381682 | S34: =S26/SUM($R26:$W26) -> 0.17885034 | T34: =T26/SUM($R26:$W26) -> 0.15755292 | U34: =U26/SUM($R26:$W26) -> 0.16079014 | V34: =V26/SUM($R26:$W26) -> 0.17251869 | W34: =W26/SUM($R26:$W26) -> 0.16647109 | Z34: 0.024876229 | AA34: 0.017912113 | AB34: -0.085364414 | AC34: -0.018067268 | AG34: -0.053005223 | AH34: -0.053005223 | AI34: -0.053005223 | AJ34: -0.053005223
Z35: -0.052984532 | AA35: -0.035449886 | AB35: 0.24074498 | AC35: 0.098261808 | AG35: 0.26539943 | AH35: 0.26539943 | AI35: 0.26539943 | AJ35: 0.26539943
Z37: Gradients dL/dQ: | AF37: np.dot(X_train.T, dL_dV) | AK37: Updated W_V:
Z38: {=MMULT(Z22:AE27,M18:P23)} -> 0.00070573183 | AA38: -0.033160899 | AB38: 0.0065455221 | AC38: -0.046292414 | AF38: {=MMULT(TRANSPOSE(C4:H9),AG30:AJ35)} -> -0.20464784 | AG38: -0.20464784 | AH38: -0.20464784 | AI38: -0.20464784 | AK38: =C27-0.02*AF38 -> 0.16638437 | AL38: =D27-0.02*AG38 -> -0.88694485 | AM38: =E27-0.02*AH38 -> 0.15661721 | AN38: =F27-0.02*AI38 -> -0.19796591
Z39: -0.011144071 | AA39: 0.10327211 | AB39: -0.036916561 | AC39: 0.18881969 | AF39: 2.0542451 | AG39: 2.0542451 | AH39: 2.0542451 | AI39: 2.0542451 | AK39: =C28-0.02*AF39 -> -0.49991757 | AL39: =D28-0.02*AG39 -> 0.14438157 | AM39: =E28-0.02*AH39 -> 0.35404319 | AN39: =F28-0.02*AI39 -> 0.30418349
Z40: 0.00095332607 | AA40: -0.038170755 | AB40: 0.0080106174 | AC40: -0.054485034 | AF40: 0.063189733 | AG40: 0.063189733 | AH40: 0.063189733 | AI40: 0.063189733 | AK40: =C29-0.02*AF40 -> -0.48604236 | AL40: =D29-0.02*AG40 -> -0.22103979 | AM40: =E29-0.02*AH40 -> 0.099198124 | AN40: =F29-0.02*AI40 -> 0.42133896
Z41: -0.010122368 | AA41: 0.10271204 | AB41: -0.035348477 | AC41: 0.18387054 | AF41: -0.058610365 | AG41: -0.058610365 | AH41: -0.058610365 | AI41: -0.058610365 | AK41: =C30-0.02*AF41 -> -0.25457871 | AL41: =D30-0.02*AG41 -> -0.10782108 | AM41: =E30-0.02*AH41 -> -0.56815908 | AN41: =F30-0.02*AI41 -> -0.6130949
Z42: 0.00091532416 | AA42: -0.039375613 | AB42: 0.0082095889 | AC42: -0.056042007 | AF42: -0.22565781 | AG42: -0.22565781 | AH42: -0.22565781 | AI42: -0.22565781 | AK42: =C31-0.02*AF42 -> 0.40076194 | AL42: =D31-0.02*AG42 -> 0.67261904 | AM42: =E31-0.02*AH42 -> -0.041506028 | AN42: =F31-0.02*AI42 -> 0.49626548
Z43: -0.01070937 | AA43: 0.10441401 | AB43: -0.036572706 | AC43: 0.1886584 | AF43: -0.22565781 | AG43: -0.22565781 | AH43: -0.22565781 | AI43: -0.22565781 | AK43: =C32-0.02*AF43 -> 0.17531704 | AL43: =D32-0.02*AG43 -> -0.32806085 | AM43: =E32-0.02*AH43 -> 0.17519683 | AN43: =F32-0.02*AI43 -> 0.76351731
...

Sheet Third Iteration
B3: Input | C3: X_train: | J3: Y_train
C4: {=TRANSPOSE(Data!C14:H20)} -> 0.84127 | D4: 1 | E4: 3 | F4: 1 | G4: 1 | H4: 1 | I4: 1 | J4: 1 | AG4: dL/dZ
C5: 0.005291 | D5: 3 | E5: 1 | F5: 0.1 | G5: 0 | H5: 0 | I5: 0 | J5: 0 | Z5: Z Matrix (Output of Attention): | AE5: Y_Pred | AI5: Binary Cross-Entropy Loss | AM5: #2. Compute gradient of loss w.r.t attention_weights (dL/dP)
C6: 1 | D6: 1 | E6: 3 | F6: 0.9 | G6: 1 | H6: 1 | I6: 1 | J6: 1 | R6: {=MMULT(M9:P14,TRANSPOSE(M18:P23))} -> 1.8105334 | S6: -2.0583201 | T6: 1.7763998 | U6: -1.0449113 | V6: 1.6933371 | W6: -2.8580143 | Z6: {=MMULT(R29:W34,M27:P32)} -> -1.5173712 | AA6: -0.92065196 | AB6: 0.4933675 | AC6: 1.9547121 | AE6: =1/(1+EXP(-SUM(Z6:AC6))) -> 0.50251409 | AG6: =AE6-J4 -> -0.49748591 | AI6: =-J4*LN(AE6)-(1-J4)*LN(1-AE6) -> 0.6881316
C7: 0.015873 | D7: 2 | E7: 1 | F7: 0.2 | G7: 0 | H7: 0 | I7: 0 | J7: 0 | L7: Query | R7: 0.52496242 | S7: 0.34730642 | T7: 0.48209313 | U7: 0.35721063 | V7: 0.63754647 | W7: 0.014826117 | Z7: -1.7103563 | AA7: -0.50749241 | AB7: 0.70330291 | AC7: 1.6787585 | AE7: =1/(1+EXP(-SUM(Z7:AC7))) -> 0.54096119 | AG7: =AE7-J5 -> 0.54096119 | AI7: =-J5*LN(AE7)-(1-J5)*LN(1-AE7) -> 0.77862051 | AM7: {=MMULT(Z15:AC20,TRANSPOSE(M27:P32))} -> 0.06340896 | AN7: -0.2801494 | AO7: 0.046779232 | AP7: -0.048759466 | AQ7: -0.050070326 | AR7: -0.27915004
C8: 0.94709 | D8: 1 | E8: 3 | F8: 0.8 | G8: 1 | H8: 1 | I8: 1 | J8: 1 | M8: 0 | N8: 1 | O8: 2 | P8: 3 | R8: 1.4560451 | S8: -1.9561409 | T8: 1.429467 | U8: -1.021764 | V8: 1.3644429 | W8: -2.7233189 | Z8: -1.5303202 | AA8: -0.88693605 | AB8: 0.50898666 | AC8: 1.9297457 | AE8: =1/(1+EXP(-SUM(Z8:AC8))) -> 0.50536882 | AG8: =AE8-J6 -> -0.49463118 | AI8: =-J6*LN(AE8)-(1-J6)*LN(1-AE8) -> 0.68246678 | AM8: -0.068950267 | AN8: 0.30463165 | AO8: -0.050867267 | AP8: 0.053020554 | AQ8: 0.05444597 | AR8: 0.30354496
C9: 0 | D9: 4 | E9: 1 | F9: 0.3 | G9: 0 | H9: 0 | I9: 0 | J9: 0 | M9: {=MMULT(C4:H9,C13:F18)} -> -0.24130719 | N9: -0.33069183 | O9: -0.88206326 | P9: -1.5505492 | R9: 0.60786443 | S9: 0.21958551 | T9: 0.58004299 | U9: 0.25184673 | V9: 0.66441833 | W9: 0.015540947 | Z9: -1.7042358 | AA9: -0.53007905 | AB9: 0.69376998 | AC9: 1.6967396 | AE9: =1/(1+EXP(-SUM(Z9:AC9))) -> 0.5389695 | AG9: =AE9-J7 -> 0.5389695 | AI9: =-J7*LN(AE9)-(1-J7)*LN(1-AE9) -> 0.77429109 | AM9: 0.0630451 | AN9: -0.27854182 | AO9: 0.046510798 | AP9: -0.048479669 | AQ9: -0.049783007 | AR9: -0.27754819
M10: -0.53139573 | N10: -0.31767796 | O10: 2.1171388 | P10: 0.53160297 | R10: 1.1617257 | S10: -2.1137788 | T10: 1.1452423 | U10: -1.1513144 | V10: 1.0963234 | W10: -2.953002 | Z10: -1.5327498 | AA10: -0.87646535 | AB10: 0.51314204 | AC10: 1.9207396 | AE10: =1/(1+EXP(-SUM(Z10:AC10))) -> 0.50616631 | AG10: =AE10-J8 -> -0.49383369 | AI10: =-J8*LN(AE10)-(1-J8)*LN(1-AE10) -> 0.68089 | AM10: -0.06869641 | AN10: 0.30351007 | AO10: -0.050679987 | AP10: 0.052825346 | AQ10: 0.054245514 | AR10: 0.30242738
M11: -0.21407257 | N11: -0.24551057 | O11: -0.74457803 | P11: -1.4005365 | R11: 1.3686411 | S11: 0.75957358 | T11: 1.2822806 | U11: 0.74051992 | V11: 1.4590949 | W11: 0.43898615 | Z11: -1.6837005 | AA11: -0.57187353 | AB11: 0.67276586 | AC11: 1.7253897 | AE11: =1/(1+EXP(-SUM(Z11:AC11))) -> 0.53558513 | AG11: =AE11-J9 -> 0.53558513 | AI11: =-J9*LN(AE11)-(1-J9)*LN(1-AE11) -> 0.76697702 | AM11: 0.062943453 | AN11: -0.27809273 | AO11: 0.04643581 | AP11: -0.048401506 | AQ11: -0.049702742 | AR11: -0.27710071
B12: Query | M12: -0.41200794 | N12: -0.25202815 | O12: 1.2249303 | P12: 0.2400834 | AI12: =AVERAGE(AI6:AI11) -> 0.72856283 | AM12: -0.068265042 | AN12: 0.30160423 | AO12: -0.05036175 | AP12: 0.052493638 | AQ12: 0.053904888 | AR12: 0.30052834
C13: ='Second Iteration'!AK48 -> 0.24822711 | D13: ='Second Iteration'!AL48 -> -0.066302277 | E13: ='Second Iteration'!AM48 -> 0.32331757 | F13: ='Second Iteration'!AN48 -> 0.76574458 | M13: -0.23937274 | N13: -0.1462971 | O13: -0.67551973 | P13: -1.412586 | R13: Attention Scores:
C14: ='Second Iteration'!AK49 -> -0.10459458 | D14: ='Second Iteration'!AL49 -> -0.16205684 | E14: ='Second Iteration'!AM49 -> 0.8094648 | F14: ='Second Iteration'!AN49 -> 0.27115661 | M14: -0.61297074 | N14: -0.67079483 | O14: 2.7525629 | P14: 0.74177589 | R14: =R6/SQRT(4) -> 0.90526668 | S14: =S6/SQRT(4) -> -1.02916 | T14: =T6/SQRT(4) -> 0.88819992 | U14: =U6/SQRT(4) -> -0.52245567 | V14: =V6/SQRT(4) -> 0.84666856 | W14: =W6/SQRT(4) -> -1.4290071 | Z14: # 1. Compute gradient of loss w.r.t attention_output (dL/dZ)
C15: ='Second Iteration'!AK50 -> -0.23109183 | D15: ='Second Iteration'!AL50 -> 0.26454878 | E15: ='Second Iteration'!AM50 -> -0.22680124 | F15: ='Second Iteration'!AN50 -> -0.25745235 | R15: =R7/SQRT(4) -> 0.26248121 | S15: =S7/SQRT(4) -> 0.17365321 | T15: =T7/SQRT(4) -> 0.24104657 | U15: =U7/SQRT(4) -> 0.17860531 | V15: =V7/SQRT(4) -> 0.31877324 | W15: =W7/SQRT(4) -> 0.0074130585 | Z15: =AG6 -> -0.49748591 | AA15: =Z15 -> -0.49748591 | AB15: =AA15 -> -0.49748591 | AC15: =AB15 -> -0.49748591 | AF15: =R29*AM7 -> 0.018609158 | AG15: =S29*AN7 -> -0.011881053 | AH15: =T29*AO7 -> 0.013496376 | AI15: =U29*AP7 -> -0.003432283 | AJ15: =V29*AQ7 -> -0.013858227 | AK15: =W29*AR7 -> -0.0079369117 | AM15: =SUM(AF15:AK15) -> -0.0050029407 | AO15: =AM7-$AM15 -> 0.068411901 | AP15: =AN7-$AM15 -> -0.27514646 | AQ15: =AO7-$AM15 -> 0.051782173 | AR15: =AP7-$AM15 -> -0.043756525 | AS15: =AQ7-$AM15 -> -0.045067385 | AT15: =AR7-$AM15 -> -0.2741471
C16: ='Second Iteration'!AK51 -> 0.1216647 | D16: ='Second Iteration'!AL51 -> -0.95705419 | E16: ='Second Iteration'!AM51 -> -0.86165033 | F16: ='Second Iteration'!AN51 -> -0.28466067 | L16: Key | R16: =R8/SQRT(4) -> 0.72802256 | S16: =S8/SQRT(4) -> -0.97807045 | T16: =T8/SQRT(4) -> 0.71473348 | U16: =U8/SQRT(4) -> -0.51088199 | V16: =V8/SQRT(4) -> 0.68222144 | W16: =W8/SQRT(4) -> -1.3616594 | Z16: =AG7 -> 0.54096119 | AA16: =Z16 -> 0.54096119 | AB16: =AA16 -> 0.54096119 | AC16: =AB16 -> 0.54096119 | AF16: =R30*AM8 -> -0.012211991 | AG16: =S30*AN8 -> 0.049368283 | AH16: =T30*AO8 -> -0.0088182005 | AI16: =U30*AP8 -> 0.0086351112 | AJ16: =V30*AQ8 -> 0.010201489 | AK16: =W30*AR8 -> 0.041658041 | AM16: =SUM(AF16:AK16) -> 0.088832732 | AO16: =AM8-$AM16 -> -0.157783 | AP16: =AN8-$AM16 -> 0.21579892 | AQ16: =AO8-$AM16 -> -0.1397 | AR16: =AP8-$AM16 -> -0.035812178 | AS16: =AQ8-$AM16 -> -0.034386762 | AT16: =AR8-$AM16 -> 0.21471222
C17: ='Second Iteration'!AK52 -> -0.50658389 | D17: ='Second Iteration'!AL52 -> 0.16028139 | E17: ='Second Iteration'!AM52 -> -0.45462376 | F17: ='Second Iteration'!AN52 -> -0.70133189 | M17: 0 | N17: 1 | O17: 2 | P17: 3 | R17: =R9/SQRT(4) -> 0.30393221 | S17: =S9/SQRT(4) -> 0.10979276 | T17: =T9/SQRT(4) -> 0.29002149 | U17: =U9/SQRT(4) -> 0.12592336 | V17: =V9/SQRT(4) -> 0.33220916 | W17: =W9/SQRT(4) -> 0.0077704733 | Z17: =AG8 -> -0.49463118 | AA17: =Z17 -> -0.49463118 | AB17: =AA17 -> -0.49463118 | AC17: =AB17 -> -0.49463118 | AF17: =R31*AM9 -> 0.017824292 | AG17: =S31*AN9 -> -0.014298964 | AH17: =T31*AO9 -> 0.012976076 | AI17: =U31*AP9 -> -0.0039707377 | AJ17: =V31*AQ9 -> -0.013444694 | AK17: =W31*AR9 -> -0.0097087206 | AM17: =SUM(AF17:AK17) -> -0.010622748 | AO17: =AM9-$AM17 -> 0.073667848 | AP17: =AN9-$AM17 -> -0.26791907 | AQ17: =AO9-$AM17 -> 0.057133546 | AR17: =AP9-$AM17 -> -0.037856921 | AS17: =AQ9-$AM17 -> -0.039160259 | AT17: =AR9-$AM17 -> -0.26692544
C18: ='Second Iteration'!AK53 -> 0.73265605 | D18: ='Second Iteration'!AL53 -> -0.10973043 | E18: ='Second Iteration'!AM53 -> 0.03315238 | F18: ='Second Iteration'!AN53 -> -0.70755413 | M18: {=MMULT(C4:H9,C20:F25)} -> -0.84918901 | N18: -2.9578284 | O18: -0.35862 | P18: -0.20067905 | R18: =R10/SQRT(4) -> 0.58086285 | S18: =S10/SQRT(4) -> -1.0568894 | T18: =T10/SQRT(4) -> 0.57262117 | U18: =U10/SQRT(4) -> -0.57565721 | V18: =V10/SQRT(4) -> 0.54816168 | W18: =W10/SQRT(4) -> -1.476501 | Z18: =AG9 -> 0.5389695 | AA18: =Z18 -> 0.5389695 | AB18: =AA18 -> 0.5389695 | AC18: =AB18 -> 0.5389695 | AF18: =R32*AM10 -> -0.012676927 | AG18: =S32*AN10 -> 0.046125316 | AH18: =T32*AO10 -> -0.0092230611 | AI18: =U32*AP10 -> 0.0081585697 | AJ18: =V32*AQ10 -> 0.010297322 | AK18: =W32*AR10 -> 0.041503014 | AM18: =SUM(AF18:AK18) -> 0.084184234 | AO18: =AM10-$AM18 -> -0.15288064 | AP18: =AN10-$AM18 -> 0.21932584 | AQ18: =AO10-$AM18 -> -0.13486422 | AR18: =AP10-$AM18 -> -0.031358888 | AS18: =AQ10-$AM18 -> -0.02993872 | AT18: =AR10-$AM18 -> 0.21824315
B19: W_K | C19: Matrix: | M19: -0.85462987 | N19: -1.0408949 | O19: -0.73395117 | P19: 2.1000012 | R19: =R11/SQRT(4) -> 0.68432054 | S19: =S11/SQRT(4) -> 0.37978679 | T19: =T11/SQRT(4) -> 0.64114031 | U19: =U11/SQRT(4) -> 0.37025996 | V19: =V11/SQRT(4) -> 0.72954743 | W19: =W11/SQRT(4) -> 0.21949308 | Z19: =AG10 -> -0.49383369 | AA19: =Z19 -> -0.49383369 | AB19: =AA19 -> -0.49383369 | AC19: =AB19 -> -0.49383369 | AF19: =R33*AM11 -> 0.017501766 | AG19: =S33*AN11 -> -0.015033295 | AH19: =T33*AO11 -> 0.01280575 | AI19: =U33*AP11 -> -0.0042336982 | AJ19: =V33*AQ11 -> -0.01337549 | AK19: =W33*AR11 -> -0.0098461665 | AM19: =SUM(AF19:AK19) -> -0.012181135 | AO19: =AM11-$AM19 -> 0.075124588 | AP19: =AN11-$AM19 -> -0.2659116 | AQ19: =AO11-$AM19 -> 0.058616944 | AR19: =AP11-$AM19 -> -0.036220371 | AS19: =AQ11-$AM19 -> -0.037521608 | AT19: =AR11-$AM19 -> -0.26491957
C20: ='Second Iteration'!AK56 -> -0.27737877 | D20: ='Second Iteration'!AL56 -> 0.05272054 | E20: ='Second Iteration'!AM56 -> -0.55404124 | F20: ='Second Iteration'!AN56 -> 0.19799948 | M20: -0.90329766 | N20: -2.8512855 | O20: -0.38169548 | P20: -0.1798403 | Z20: =AG11 -> 0.53558513 | AA20: =Z20 -> 0.53558513 | AB20: =AA20 -> 0.53558513 | AC20: =AB20 -> 0.53558513 | AF20: =R34*AM12 -> -0.013384805 | AG20: =S34*AN12 -> 0.043610774 | AH20: =T34*AO12 -> -0.0094571783 | AI20: =U34*AP12 -> 0.0075184028 | AJ20: =V34*AQ12 -> 0.011058179 | AK20: =W34*AR12 -> 0.037019208 | AM20: =SUM(AF20:AK20) -> 0.076364581 | AO20: =AM12-$AM20 -> -0.14462962 | AP20: =AN12-$AM20 -> 0.22523965 | AQ20: =AO12-$AM20 -> -0.12672633 | AR20: =AP12-$AM20 -> -0.023870943 | AS20: =AQ12-$AM20 -> -0.022459693 | AT20: =AR12-$AM20 -> 0.22416375
C21: ='Second Iteration'!AK57 -> -0.28178251 | D21: ='Second Iteration'!AL57 -> -0.13608588 | E21: ='Second Iteration'!AM57 -> -0.37456164 | F21: ='Second Iteration'!AN57 -> 0.8922758 | M21: -0.56570226 | N21: -1.0024257 | O21: -0.43011987 | P21: 1.2204104 | R21: =EXP(R14) -> 2.4725912 | S21: =EXP(S14) -> 0.35730696 | T21: =EXP(T14) -> 2.4307502 | U21: =EXP(U14) -> 0.59306239 | V21: =EXP(V14) -> 2.3318654 | W21: =EXP(W14) -> 0.23954664 | Z21: # 3. Compute gradient of loss w.r.t attention scores (dL/dA) with softmax derivative
C22: ='Second Iteration'!AK58 -> -0.017895043 | D22: ='Second Iteration'!AL58 -> -0.53474162 | E22: ='Second Iteration'!AM58 -> 0.45753268 | F22: ='Second Iteration'!AN58 -> -0.58846352 | M22: -0.89870187 | N22: -2.7559004 | O22: -0.28751368 | P22: -0.20090617 | R22: =EXP(R15) -> 1.300152 | S22: =EXP(S15) -> 1.1896429 | T22: =EXP(T15) -> 1.2725803 | U22: =EXP(U15) -> 1.1955488 | V22: =EXP(V15) -> 1.3754394 | W22: =EXP(W15) -> 1.0074406 | Z22: =R29*AO15/SQRT(4) -> 0.010038706 | AA22: =S29*AP15/SQRT(4) -> -0.00583444 | AB22: =T29*AQ15/SQRT(4) -> 0.0074698926 | AC22: =U29*AR15/SQRT(4) -> -0.0015400576 | AD22: =V29*AS15/SQRT(4) -> -0.0062367683 | AE22: =W29*AT15/SQRT(4) -> -0.003897333
C23: ='Second Iteration'!AK59 -> 0.10080322 | D23: ='Second Iteration'!AL59 -> -0.98174577 | E23: ='Second Iteration'!AM59 -> -0.64867482 | F23: ='Second Iteration'!AN59 -> 0.10589714 | M23: -1.1147841 | N23: -1.3736089 | O23: -1.2353163 | P23: 3.0124088 | R23: =EXP(R16) -> 2.0709813 | S23: =EXP(S16) -> 0.37603598 | T23: =EXP(T16) -> 2.0436419 | U23: =EXP(U16) -> 0.59996618 | V23: =EXP(V16) -> 1.9782675 | W23: =EXP(W16) -> 0.25623522 | Z23: =R30*AO16/SQRT(4) -> -0.013972713 | AA23: =S30*AP16/SQRT(4) -> 0.017486072 | AB23: =T30*AQ16/SQRT(4) -> -0.012108991 | AC23: =U30*AR16/SQRT(4) -> -0.0029162477 | AD23: =V30*AS16/SQRT(4) -> -0.0032215073 | AE23: =W30*AT16/SQRT(4) -> 0.014733387
C24: ='Second Iteration'!AK60 -> 0.36366007 | D24: ='Second Iteration'!AL60 -> 0.08274106 | E24: ='Second Iteration'!AM60 -> -0.034694029 | F24: ='Second Iteration'!AN60 -> -0.1395727 | R24: =EXP(R17) -> 1.3551772 | S24: =EXP(S17) -> 1.1160468 | T24: =EXP(T17) -> 1.3364562 | U24: =EXP(U17) -> 1.1341952 | V24: =EXP(V17) -> 1.3940444 | W24: =EXP(W17) -> 1.0078007 | Z24: =R31*AO17/SQRT(4) -> 0.010413793 | AA24: =S31*AP17/SQRT(4) -> -0.0068768224 | AB24: =T31*AQ17/SQRT(4) -> 0.0079698614 | AC24: =U31*AR17/SQRT(4) -> -0.0015503396 | AD24: =V31*AS17/SQRT(4) -> -0.0052879257 | AE24: =W31*AT17/SQRT(4) -> -0.0046685668
